<?xml version="1.0" encoding="utf-8"?>
<!-- This URDF was automatically created by SolidWorks to URDF Exporter! Originally created by Stephen Brawner (brawner@gmail.com) 
     Commit Version: 1.6.0-4-g7f85cfe  Build Version: 1.6.7995.38578
     For more information, please see http://wiki.ros.org/sw_urdf_exporter -->
<robot
  name="Roly_with_arm X12 version">
  <link
    name="base_link">
    <inertial>
      <origin
        xyz="-2.0969330273087E-05 -4.03632971993773E-13 -0.0187178691238857"
        rpy="0 0 0" />
      <mass
        value="4.35454338307743" />
      <inertia
        ixx="0.0197722203546471"
        ixy="1.18998862197138E-07"
        ixz="6.7770411068282E-06"
        iyy="0.00413553225471283"
        iyz="-7.81213800173199E-15"
        izz="0.021630011357051" />
    </inertial>
    <visual>
      <origin
        xyz="0 0 0"
        rpy="0 0 0" />
      <geometry>
        <mesh
          filename="package://Roly_with_arm X12 version/meshes/base_link.STL" />
      </geometry>
      <material
        name="">
        <color
          rgba="0.752941176470588 0.752941176470588 0.752941176470588 1" />
      </material>
    </visual>
    <collision>
      <origin
        xyz="0 0 0"
        rpy="0 0 0" />
      <geometry>
        <mesh
          filename="package://Roly_with_arm X12 version/meshes/base_link.STL" />
      </geometry>
    </collision>
  </link>
  <joint
    name="trunk"
    type="continuous">
    <origin
      xyz="0 0 0.024"
      rpy="0 0 0" />
    <parent
      link="base_link" />
    <child
      link="trunk" />
    <axis
      xyz="0 0 1" />
  </joint>
  <link
    name="R_hip_yaw">
    <inertial>
      <origin
        xyz="-0.0376961379513844 2.56625665293053E-06 -0.0690573024444017"
        rpy="0 0 0" />
      <mass
        value="0.733343615600181" />
      <inertia
        ixx="0.00119900118613847"
        ixy="6.01653813839693E-08"
        ixz="9.24155578825333E-07"
        iyy="0.000924833085839684"
        iyz="-7.69796625722206E-10"
        izz="0.00124906806994162" />
    </inertial>
    <visual>
      <origin
        xyz="0 0 0"
        rpy="0 0 0" />
      <geometry>
        <mesh
          filename="package://Roly_with_arm X12 version/meshes/R_hip_yaw.STL" />
      </geometry>
      <material
        name="">
        <color
          rgba="0.752941176470588 0.752941176470588 0.752941176470588 1" />
      </material>
    </visual>
    <collision>
      <origin
        xyz="0 0 0"
        rpy="0 0 0" />
      <geometry>
        <mesh
          filename="package://Roly_with_arm X12 version/meshes/R_hip_yaw.STL" />
      </geometry>
    </collision>
  </link>
  <joint
    name="R_hip_yaw"
    type="continuous">
    <origin
      xyz="0 -0.13 -0.024"
      rpy="0 0 0" />
    <parent
      link="base_link" />
    <child
      link="R_hip_yaw" />
    <axis
      xyz="0 0 1" />
  </joint>
  <link
    name="R_hip_roll">
    <inertial>
      <origin
        xyz="0.00146093919704993 4.44632851370752E-09 -0.000423486625366122"
        rpy="0 0 0" />
      <mass
        value="1.33291706220482" />
      <inertia
        ixx="0.000591897359084709"
        ixy="-1.60236031948606E-11"
        ixz="-4.8451746760555E-13"
        iyy="0.00200428114901879"
        iyz="-6.76808998220696E-17"
        izz="0.00190740917285887" />
    </inertial>
    <visual>
      <origin
        xyz="0 0 0"
        rpy="0 0 0" />
      <geometry>
        <mesh
          filename="package://Roly_with_arm X12 version/meshes/R_hip_roll.STL" />
      </geometry>
      <material
        name="">
        <color
          rgba="0.752941176470588 0.752941176470588 0.752941176470588 1" />
      </material>
    </visual>
    <collision>
      <origin
        xyz="0 0 0"
        rpy="0 0 0" />
      <geometry>
        <mesh
          filename="package://Roly_with_arm X12 version/meshes/R_hip_roll.STL" />
      </geometry>
    </collision>
  </link>
  <joint
    name="R_hip_roll"
    type="continuous">
    <origin
      xyz="0 0 -0.1165"
      rpy="1.5707963267949 0 1.5707963267949" />
    <parent
      link="R_hip_yaw" />
    <child
      link="R_hip_roll" />
    <axis
      xyz="0 0 1" />
  </joint>
  <link
    name="R_hip_pitch">
    <inertial>
      <origin
        xyz="-0.127210532308635 0.000292504184818075 0.00107219503644987"
        rpy="0 0 0" />
      <mass
        value="2.89882038414392" />
      <inertia
        ixx="0.00467343751010157"
        ixy="2.13719906053841E-05"
        ixz="-5.65184797764741E-10"
        iyy="0.00483644807960927"
        iyz="-2.0500002737255E-06"
        izz="0.00547575849667531" />
    </inertial>
    <visual>
      <origin
        xyz="0 0 0"
        rpy="0 0 0" />
      <geometry>
        <mesh
          filename="package://Roly_with_arm X12 version/meshes/R_hip_pitch.STL" />
      </geometry>
      <material
        name="">
        <color
          rgba="0.752941176470588 0.752941176470588 0.752941176470588 1" />
      </material>
    </visual>
    <collision>
      <origin
        xyz="0 0 0"
        rpy="0 0 0" />
      <geometry>
        <mesh
          filename="package://Roly_with_arm X12 version/meshes/R_hip_pitch.STL" />
      </geometry>
    </collision>
  </link>
  <joint
    name="R_hip_pitch"
    type="continuous">
    <origin
      xyz="0 0 0"
      rpy="1.5708 0 1.5708" />
    <parent
      link="R_hip_roll" />
    <child
      link="R_hip_pitch" />
    <axis
      xyz="0 0 1" />
  </joint>
  <link
    name="R_calf">
    <inertial>
      <origin
        xyz="-0.115064212556169 -0.000572949014918702 -0.0104599967609761"
        rpy="0 0 0" />
      <mass
        value="1.80952664426131" />
      <inertia
        ixx="0.00120585904578178"
        ixy="1.76830897841789E-05"
        ixz="-1.72650824574503E-06"
        iyy="0.00439268233185776"
        iyz="4.64248765005868E-08"
        izz="0.00514146636651206" />
    </inertial>
    <visual>
      <origin
        xyz="0 0 0"
        rpy="0 0 0" />
      <geometry>
        <mesh
          filename="package://Roly_with_arm X12 version/meshes/R_calf.STL" />
      </geometry>
      <material
        name="">
        <color
          rgba="0.752941176470588 0.752941176470588 0.752941176470588 1" />
      </material>
    </visual>
    <collision>
      <origin
        xyz="0 0 0"
        rpy="0 0 0" />
      <geometry>
        <mesh
          filename="package://Roly_with_arm X12 version/meshes/R_calf.STL" />
      </geometry>
    </collision>
  </link>
  <joint
    name="R_calf"
    type="continuous">
    <origin
      xyz="-0.27 0 0"
      rpy="0 0 0" />
    <parent
      link="R_hip_pitch" />
    <child
      link="R_calf" />
    <axis
      xyz="0 0 -1" />
  </joint>
  <link
    name="R_ankle_pitch">
    <inertial>
      <origin
        xyz="-0.0459607705929198 0.0196304584001554 -4.06788864644458E-05"
        rpy="0 0 0" />
      <mass
        value="0.990577841443612" />
      <inertia
        ixx="0.00101039477916099"
        ixy="1.54818542623502E-05"
        ixz="-8.03481621715949E-13"
        iyy="0.000487572584281687"
        iyz="-4.50082270266902E-13"
        izz="0.00115084495203271" />
    </inertial>
    <visual>
      <origin
        xyz="0 0 0"
        rpy="0 0 0" />
      <geometry>
        <mesh
          filename="package://Roly_with_arm X12 version/meshes/R_ankle_pitch.STL" />
      </geometry>
      <material
        name="">
        <color
          rgba="0.752941176470588 0.752941176470588 0.752941176470588 1" />
      </material>
    </visual>
    <collision>
      <origin
        xyz="0 0 0"
        rpy="0 0 0" />
      <geometry>
        <mesh
          filename="package://Roly_with_arm X12 version/meshes/R_ankle_pitch.STL" />
      </geometry>
    </collision>
  </link>
  <joint
    name="R_ankle_pitch"
    type="continuous">
    <origin
      xyz="-0.26 0 0"
      rpy="0 0 -2.6978E-05" />
    <parent
      link="R_calf" />
    <child
      link="R_ankle_pitch" />
    <axis
      xyz="0 0 -1" />
  </joint>
  <link
    name="R_ankle_roll">
    <inertial>
      <origin
        xyz="-0.06859980493504 2.20840845610581E-11 0.0199999999883363"
        rpy="0 0 0" />
      <mass
        value="1.80750858879406" />
      <inertia
        ixx="0.00356060489977588"
        ixy="5.03488600897087E-14"
        ixz="8.78953740422329E-14"
        iyy="0.00313608673879828"
        iyz="-3.22423801350962E-13"
        izz="0.00058266456747892" />
    </inertial>
    <visual>
      <origin
        xyz="0 0 0"
        rpy="0 0 0" />
      <geometry>
        <mesh
          filename="package://Roly_with_arm X12 version/meshes/R_ankle_roll.STL" />
      </geometry>
      <material
        name="">
        <color
          rgba="0.752941176470588 0.752941176470588 0.752941176470588 1" />
      </material>
    </visual>
    <collision>
      <origin
        xyz="0 0 0"
        rpy="0 0 0" />
      <geometry>
        <mesh
          filename="package://Roly_with_arm X12 version/meshes/R_ankle_roll.STL" />
      </geometry>
    </collision>
  </link>
  <joint
    name="R_ankle_roll"
    type="continuous">
    <origin
      xyz="-0.05 0 0"
      rpy="-1.5708 0 2.6978E-05" />
    <parent
      link="R_ankle_pitch" />
    <child
      link="R_ankle_roll" />
    <axis
      xyz="0 0 -1" />
  </joint>
  <link
    name="R_knee_rocker">
    <inertial>
      <origin
        xyz="-0.00719496594488911 -0.00261875342616329 -0.0218740723753148"
        rpy="0 0 0" />
      <mass
        value="0.147234181769684" />
      <inertia
        ixx="3.23048235529037E-05"
        ixy="-1.4298916093054E-05"
        ixz="-6.07779307989089E-06"
        iyy="6.63863926532267E-05"
        iyz="-2.21213576191369E-06"
        izz="8.94281354141202E-05" />
    </inertial>
    <visual>
      <origin
        xyz="0 0 0"
        rpy="0 0 0" />
      <geometry>
        <mesh
          filename="package://Roly_with_arm X12 version/meshes/R_knee_rocker.STL" />
      </geometry>
      <material
        name="">
        <color
          rgba="0.752941176470588 0.752941176470588 0.752941176470588 1" />
      </material>
    </visual>
    <collision>
      <origin
        xyz="0 0 0"
        rpy="0 0 0" />
      <geometry>
        <mesh
          filename="package://Roly_with_arm X12 version/meshes/R_knee_rocker.STL" />
      </geometry>
    </collision>
  </link>
  <joint
    name="R_knee_rocker"
    type="continuous">
    <origin
      xyz="-0.15 0 -0.0295000000000031"
      rpy="0 0 0" />
    <parent
      link="R_hip_pitch" />
    <child
      link="R_knee_rocker" />
    <axis
      xyz="0 0 1" />
  </joint>
  <link
    name="R_knee_linkage">
    <inertial>
      <origin
        xyz="-0.0590948291193004 0.0215084963352754 -5.56693580122669E-13"
        rpy="0 0 0" />
      <mass
        value="0.110281845782562" />
      <inertia
        ixx="1.16107281445784E-05"
        ixy="2.38947586613589E-05"
        ixz="2.06937329969362E-13"
        iyy="6.8564057108433E-05"
        iyz="5.72483289283379E-13"
        izz="7.74131693353278E-05" />
    </inertial>
    <visual>
      <origin
        xyz="0 0 0"
        rpy="0 0 0" />
      <geometry>
        <mesh
          filename="package://Roly_with_arm X12 version/meshes/R_knee_linkage.STL" />
      </geometry>
      <material
        name="">
        <color
          rgba="0.752941176470588 0.752941176470588 0.752941176470588 1" />
      </material>
    </visual>
    <collision>
      <origin
        xyz="0 0 0"
        rpy="0 0 0" />
      <geometry>
        <mesh
          filename="package://Roly_with_arm X12 version/meshes/R_knee_linkage.STL" />
      </geometry>
    </collision>
  </link>
  <joint
    name="R_knee_linkage"
    type="continuous">
    <origin
      xyz="-0.0563815572467992 -0.0205212086005204 -0.0264999999999999"
      rpy="0 0 0.349065850416189" />
    <parent
      link="R_knee_rocker" />
    <child
      link="R_knee_linkage" />
    <axis
      xyz="0 0 1" />
  </joint>
  <link
    name="L_hip_yaw">
    <inertial>
      <origin
        xyz="-0.0376961379513853 2.56625664149523E-06 -0.0690573024444016"
        rpy="0 0 0" />
      <mass
        value="0.733343615600181" />
      <inertia
        ixx="0.00119900118613847"
        ixy="6.01653813846152E-08"
        ixz="9.24155578825376E-07"
        iyy="0.000924833085839683"
        iyz="-7.69796626111075E-10"
        izz="0.00124906806994162" />
    </inertial>
    <visual>
      <origin
        xyz="0 0 0"
        rpy="0 0 0" />
      <geometry>
        <mesh
          filename="package://Roly_with_arm X12 version/meshes/L_hip_yaw.STL" />
      </geometry>
      <material
        name="">
        <color
          rgba="0.752941176470588 0.752941176470588 0.752941176470588 1" />
      </material>
    </visual>
    <collision>
      <origin
        xyz="0 0 0"
        rpy="0 0 0" />
      <geometry>
        <mesh
          filename="package://Roly_with_arm X12 version/meshes/L_hip_yaw.STL" />
      </geometry>
    </collision>
  </link>
  <joint
    name="L_hip_yaw"
    type="continuous">
    <origin
      xyz="0 0.13 -0.024"
      rpy="0 0 0" />
    <parent
      link="base_link" />
    <child
      link="L_hip_yaw" />
    <axis
      xyz="0 0 1" />
  </joint>
  <link
    name="L_hip_roll">
    <inertial>
      <origin
        xyz="-0.00146134805967929 -4.44757360107406E-09 -0.000413805692940466"
        rpy="0 0 0" />
      <mass
        value="1.33254396984757" />
      <inertia
        ixx="0.000591888195356316"
        ixy="-1.60440311849567E-11"
        ixz="3.46676912191186E-13"
        iyy="0.0020042800162885"
        iyz="-2.16517741557815E-16"
        izz="0.00190740000129135" />
    </inertial>
    <visual>
      <origin
        xyz="0 0 0"
        rpy="0 0 0" />
      <geometry>
        <mesh
          filename="package://Roly_with_arm X12 version/meshes/L_hip_roll.STL" />
      </geometry>
      <material
        name="">
        <color
          rgba="0.752941176470588 0.752941176470588 0.752941176470588 1" />
      </material>
    </visual>
    <collision>
      <origin
        xyz="0 0 0"
        rpy="0 0 0" />
      <geometry>
        <mesh
          filename="package://Roly_with_arm X12 version/meshes/L_hip_roll.STL" />
      </geometry>
    </collision>
  </link>
  <joint
    name="L_hip_roll"
    type="continuous">
    <origin
      xyz="0 0 -0.1165"
      rpy="1.5707963267949 0 1.5707963267949" />
    <parent
      link="L_hip_yaw" />
    <child
      link="L_hip_roll" />
    <axis
      xyz="0 0 1" />
  </joint>
  <link
    name="L_hip_pitch">
    <inertial>
      <origin
        xyz="-0.127210532308636 0.000292504184817722 -0.00112657093857071"
        rpy="0 0 0" />
      <mass
        value="2.89882038414392" />
      <inertia
        ixx="0.00467343751010157"
        ixy="2.13719906053828E-05"
        ixz="-5.65184797689356E-10"
        iyy="0.00483644807960927"
        iyz="2.05001926409375E-06"
        izz="0.0054757584966753" />
    </inertial>
    <visual>
      <origin
        xyz="0 0 0"
        rpy="0 0 0" />
      <geometry>
        <mesh
          filename="package://Roly_with_arm X12 version/meshes/L_hip_pitch.STL" />
      </geometry>
      <material
        name="">
        <color
          rgba="0.752941176470588 0.752941176470588 0.752941176470588 1" />
      </material>
    </visual>
    <collision>
      <origin
        xyz="0 0 0"
        rpy="0 0 0" />
      <geometry>
        <mesh
          filename="package://Roly_with_arm X12 version/meshes/L_hip_pitch.STL" />
      </geometry>
    </collision>
  </link>
  <joint
    name="L_hip_pitch"
    type="continuous">
    <origin
      xyz="0 0 0"
      rpy="1.5708 0 1.5708" />
    <parent
      link="L_hip_roll" />
    <child
      link="L_hip_pitch" />
    <axis
      xyz="0 0 1" />
  </joint>
  <link
    name="L_calf">
    <inertial>
      <origin
        xyz="-0.11504693138273 -0.000697382529229964 0.0108054494606971"
        rpy="0 0 0" />
      <mass
        value="1.81934397391708" />
      <inertia
        ixx="0.00120849467573946"
        ixy="1.7589861816723E-05"
        ixz="1.72520219163424E-06"
        iyy="0.00439549186433966"
        iyz="-4.6370327248491E-08"
        izz="0.0051406660037251" />
    </inertial>
    <visual>
      <origin
        xyz="0 0 0"
        rpy="0 0 0" />
      <geometry>
        <mesh
          filename="package://Roly_with_arm X12 version/meshes/L_calf.STL" />
      </geometry>
      <material
        name="">
        <color
          rgba="0.752941176470588 0.752941176470588 0.752941176470588 1" />
      </material>
    </visual>
    <collision>
      <origin
        xyz="0 0 0"
        rpy="0 0 0" />
      <geometry>
        <mesh
          filename="package://Roly_with_arm X12 version/meshes/L_calf.STL" />
      </geometry>
    </collision>
  </link>
  <joint
    name="L_calf"
    type="continuous">
    <origin
      xyz="-0.27 0 0"
      rpy="0 0 0" />
    <parent
      link="L_hip_pitch" />
    <child
      link="L_calf" />
    <axis
      xyz="0 0 -1" />
  </joint>
  <link
    name="L_ankle_pitch">
    <inertial>
      <origin
        xyz="-0.0459602037497333 0.0196317254812573 5.49195569358452E-05"
        rpy="0 0 0" />
      <mass
        value="0.990577843355175" />
      <inertia
        ixx="0.00101039570334688"
        ixy="1.54676262047357E-05"
        ixz="-1.9586757110239E-12"
        iyy="0.000487571655959726"
        iyz="-1.71302288969826E-15"
        izz="0.00115084495573058" />
    </inertial>
    <visual>
      <origin
        xyz="0 0 0"
        rpy="0 0 0" />
      <geometry>
        <mesh
          filename="package://Roly_with_arm X12 version/meshes/L_ankle_pitch.STL" />
      </geometry>
      <material
        name="">
        <color
          rgba="0.752941176470588 0.752941176470588 0.752941176470588 1" />
      </material>
    </visual>
    <collision>
      <origin
        xyz="0 0 0"
        rpy="0 0 0" />
      <geometry>
        <mesh
          filename="package://Roly_with_arm X12 version/meshes/L_ankle_pitch.STL" />
      </geometry>
    </collision>
  </link>
  <joint
    name="L_ankle_pitch"
    type="continuous">
    <origin
      xyz="-0.26 0 0"
      rpy="0 0 0" />
    <parent
      link="L_calf" />
    <child
      link="L_ankle_pitch" />
    <axis
      xyz="0 0 -1" />
  </joint>
  <link
    name="L_ankle_roll">
    <inertial>
      <origin
        xyz="-0.0685998049350405 2.13515594094105E-11 0.019999999988339"
        rpy="0 0 0" />
      <mass
        value="1.80750858879406" />
      <inertia
        ixx="0.00356060489977588"
        ixy="5.45548170745626E-14"
        ixz="7.01378451330357E-14"
        iyy="0.00313608673879828"
        iyz="-3.22423719747347E-13"
        izz="0.000582664567478919" />
    </inertial>
    <visual>
      <origin
        xyz="0 0 0"
        rpy="0 0 0" />
      <geometry>
        <mesh
          filename="package://Roly_with_arm X12 version/meshes/L_ankle_roll.STL" />
      </geometry>
      <material
        name="">
        <color
          rgba="0.752941176470588 0.752941176470588 0.752941176470588 1" />
      </material>
    </visual>
    <collision>
      <origin
        xyz="0 0 0"
        rpy="0 0 0" />
      <geometry>
        <mesh
          filename="package://Roly_with_arm X12 version/meshes/L_ankle_roll.STL" />
      </geometry>
    </collision>
  </link>
  <joint
    name="L_ankle_roll"
    type="continuous">
    <origin
      xyz="-0.05 0 0"
      rpy="-1.5708 0 0" />
    <parent
      link="L_ankle_pitch" />
    <child
      link="L_ankle_roll" />
    <axis
      xyz="0 0 -1" />
  </joint>
  <link
    name="L_knee_rocker">
    <inertial>
      <origin
        xyz="-0.00719496593563257 -0.00261875345159788 0.0168740723753051"
        rpy="0 0 0" />
      <mass
        value="0.147234181769685" />
      <inertia
        ixx="3.23048234922348E-05"
        ixy="-1.42989160207515E-05"
        ixz="6.07779307394664E-06"
        iyy="6.63863927138957E-05"
        iyz="2.21213577824525E-06"
        izz="8.94281354141202E-05" />
    </inertial>
    <visual>
      <origin
        xyz="0 0 0"
        rpy="0 0 0" />
      <geometry>
        <mesh
          filename="package://Roly_with_arm X12 version/meshes/L_knee_rocker.STL" />
      </geometry>
      <material
        name="">
        <color
          rgba="0.752941176470588 0.752941176470588 0.752941176470588 1" />
      </material>
    </visual>
    <collision>
      <origin
        xyz="0 0 0"
        rpy="0 0 0" />
      <geometry>
        <mesh
          filename="package://Roly_with_arm X12 version/meshes/L_knee_rocker.STL" />
      </geometry>
    </collision>
  </link>
  <joint
    name="L_knee_rocker"
    type="continuous">
    <origin
      xyz="-0.150000000000001 0 0.0345000000000142"
      rpy="0 0 0" />
    <parent
      link="L_hip_pitch" />
    <child
      link="L_knee_rocker" />
    <axis
      xyz="0 0 1" />
  </joint>
  <link
    name="L_knee_linkage">
    <inertial>
      <origin
        xyz="-0.0590948291197253 0.0215084963341083 -5.66963143100452E-13"
        rpy="0 0 0" />
      <mass
        value="0.110281845782562" />
      <inertia
        ixx="1.16107281436419E-05"
        ixy="2.38947586602429E-05"
        ixz="2.0693738733528E-13"
        iyy="6.85640571093693E-05"
        iyz="5.7248326909744E-13"
        izz="7.74131693353276E-05" />
    </inertial>
    <visual>
      <origin
        xyz="0 0 0"
        rpy="0 0 0" />
      <geometry>
        <mesh
          filename="package://Roly_with_arm X12 version/meshes/L_knee_linkage.STL" />
      </geometry>
      <material
        name="">
        <color
          rgba="0.752941176470588 0.752941176470588 0.752941176470588 1" />
      </material>
    </visual>
    <collision>
      <origin
        xyz="0 0 0"
        rpy="0 0 0" />
      <geometry>
        <mesh
          filename="package://Roly_with_arm X12 version/meshes/L_knee_linkage.STL" />
      </geometry>
    </collision>
  </link>
  <joint
    name="L_knee_linkage"
    type="continuous">
    <origin
      xyz="-0.0563815572472011 -0.0205212085994101 0.0215000000000007"
      rpy="0 0 0.349065850396594" />
    <parent
      link="L_knee_rocker" />
    <child
      link="L_knee_linkage" />
    <axis
      xyz="0 0 1" />
  </joint>
  <link
    name="trunk_link">
    <inertial>
      <origin
        xyz="-0.000201091103482572 -0.0017185025937486 0.342933302682403"
        rpy="0 0 0" />
      <mass
        value="3.71736761608289" />
      <inertia
        ixx="0.0423654714360518"
        ixy="6.10031795665189E-05"
        ixz="-3.51532548621827E-05"
        iyy="0.0296803741935269"
        iyz="6.70641597388618E-05"
        izz="0.0132646084404227" />
    </inertial>
    <visual>
      <origin
        xyz="0 0 0"
        rpy="0 0 0" />
      <geometry>
        <mesh
          filename="package://Roly_with_arm X12 version/meshes/trunk_link.STL" />
      </geometry>
      <material
        name="">
        <color
          rgba="0.752941176470588 0.752941176470588 0.752941176470588 1" />
      </material>
    </visual>
    <collision>
      <origin
        xyz="0 0 0"
        rpy="0 0 0" />
      <geometry>
        <mesh
          filename="package://Roly_with_arm X12 version/meshes/trunk_link.STL" />
      </geometry>
    </collision>
  </link>
  <joint
    name="trunk"
    type="continuous">
    <origin
      xyz="0 0 0"
      rpy="0 0 0" />
    <parent
      link="base_link" />
    <child
      link="trunk_link" />
    <axis
      xyz="0 0 1" />
  </joint>
  <link
    name="neck">
    <inertial>
      <origin
        xyz="-0.0115401971148564 -0.00305819315450984 2.74217546394349E-05"
        rpy="0 0 0" />
      <mass
        value="0.0915993237937378" />
      <inertia
        ixx="1.52019609168068E-05"
        ixy="1.43206387590055E-09"
        ixz="3.2834138654383E-07"
        iyy="2.61388223158171E-05"
        iyz="1.37470597830405E-09"
        izz="2.11960891861307E-05" />
    </inertial>
    <visual>
      <origin
        xyz="0 0 0"
        rpy="0 0 0" />
      <geometry>
        <mesh
          filename="package://Roly_with_arm X12 version/meshes/neck.STL" />
      </geometry>
      <material
        name="">
        <color
          rgba="0.752941176470588 0.752941176470588 0.752941176470588 1" />
      </material>
    </visual>
    <collision>
      <origin
        xyz="0 0 0"
        rpy="0 0 0" />
      <geometry>
        <mesh
          filename="package://Roly_with_arm X12 version/meshes/neck.STL" />
      </geometry>
    </collision>
  </link>
  <joint
    name="neck"
    type="continuous">
    <origin
      xyz="0.0236 0 0.6049"
      rpy="1.5708 0 0" />
    <parent
      link="trunk_link" />
    <child
      link="neck" />
    <axis
      xyz="0 1 0" />
  </joint>
  <link
    name="camera">
    <inertial>
      <origin
        xyz="0.00773068278361726 0.0510544535429485 -0.00119353011540578"
        rpy="0 0 0" />
      <mass
        value="0.074287263423426" />
      <inertia
        ixx="4.43870779407165E-05"
        ixy="9.06935673607456E-08"
        ixz="4.47251575648331E-07"
        iyy="3.98543909637004E-05"
        iyz="2.19915553005896E-08"
        izz="1.5340417371391E-05" />
    </inertial>
    <visual>
      <origin
        xyz="0 0 0"
        rpy="0 0 0" />
      <geometry>
        <mesh
          filename="package://Roly_with_arm X12 version/meshes/camera.STL" />
      </geometry>
      <material
        name="">
        <color
          rgba="0.752941176470588 0.752941176470588 0.752941176470588 1" />
      </material>
    </visual>
    <collision>
      <origin
        xyz="0 0 0"
        rpy="0 0 0" />
      <geometry>
        <mesh
          filename="package://Roly_with_arm X12 version/meshes/camera.STL" />
      </geometry>
    </collision>
  </link>
  <joint
    name="camera"
    type="continuous">
    <origin
      xyz="0 0 0"
      rpy="0 0 0" />
    <parent
      link="neck" />
    <child
      link="camera" />
    <axis
      xyz="0 0 1" />
  </joint>
  <link
    name="R_shoulder">
    <inertial>
      <origin
        xyz="-4.78828931242402E-05 0.015653951807032 0.248211898616547"
        rpy="0 0 0" />
      <mass
        value="0.159233792908747" />
      <inertia
        ixx="5.90635379080722E-05"
        ixy="6.76340148769935E-07"
        ixz="3.93669860266057E-09"
        iyy="4.06885503332512E-05"
        iyz="-6.05489800766356E-09"
        izz="7.3658214817E-05" />
    </inertial>
    <visual>
      <origin
        xyz="0 0 0"
        rpy="0 0 0" />
      <geometry>
        <mesh
          filename="package://Roly_with_arm X12 version/meshes/R_shoulder.STL" />
      </geometry>
      <material
        name="">
        <color
          rgba="0.752941176470588 0.752941176470588 0.752941176470588 1" />
      </material>
    </visual>
    <collision>
      <origin
        xyz="0 0 0"
        rpy="0 0 0" />
      <geometry>
        <mesh
          filename="package://Roly_with_arm X12 version/meshes/R_shoulder.STL" />
      </geometry>
    </collision>
  </link>
  <joint
    name="R_shoulder"
    type="continuous">
    <origin
      xyz="0 0 0.495"
      rpy="1.5707963267949 0 0" />
    <parent
      link="trunk_link" />
    <child
      link="R_shoulder" />
    <axis
      xyz="0 0 1" />
  </joint>
  <link
    name="R_arm1">
    <inertial>
      <origin
        xyz="-0.133478677161678 1.93810793080451E-05 -7.69201038018115E-06"
        rpy="0 0 0" />
      <mass
        value="0.18902791419566" />
      <inertia
        ixx="5.50086142018852E-05"
        ixy="1.24338572181684E-08"
        ixz="6.76337657030858E-07"
        iyy="9.02607737600278E-05"
        iyz="3.9387760784785E-09"
        izz="6.73964220260777E-05" />
    </inertial>
    <visual>
      <origin
        xyz="0 0 0"
        rpy="0 0 0" />
      <geometry>
        <mesh
          filename="package://Roly_with_arm X12 version/meshes/R_arm1.STL" />
      </geometry>
      <material
        name="">
        <color
          rgba="0.752941176470588 0.752941176470588 0.752941176470588 1" />
      </material>
    </visual>
    <collision>
      <origin
        xyz="0 0 0"
        rpy="0 0 0" />
      <geometry>
        <mesh
          filename="package://Roly_with_arm X12 version/meshes/R_arm1.STL" />
      </geometry>
    </collision>
  </link>
  <joint
    name="R_arm1"
    type="continuous">
    <origin
      xyz="0 0 0.2488"
      rpy="1.57079632679491 0 1.5707963267949" />
    <parent
      link="R_shoulder" />
    <child
      link="R_arm1" />
    <axis
      xyz="0 0 1" />
  </joint>
  <link
    name="R_arm2">
    <inertial>
      <origin
        xyz="-0.0928720824914254 1.67416240065554E-07 -0.00651967320173651"
        rpy="0 0 0" />
      <mass
        value="0.075919568245842" />
      <inertia
        ixx="2.47922147508112E-05"
        ixy="2.31836798285092E-11"
        ixz="1.78932145416598E-07"
        iyy="2.92268550020728E-05"
        iyz="2.41655414270796E-11"
        izz="1.61014820233827E-05" />
    </inertial>
    <visual>
      <origin
        xyz="0 0 0"
        rpy="0 0 0" />
      <geometry>
        <mesh
          filename="package://Roly_with_arm X12 version/meshes/R_arm2.STL" />
      </geometry>
      <material
        name="">
        <color
          rgba="0.752941176470588 0.752941176470588 0.752941176470588 1" />
      </material>
    </visual>
    <collision>
      <origin
        xyz="0 0 0"
        rpy="0 0 0" />
      <geometry>
        <mesh
          filename="package://Roly_with_arm X12 version/meshes/R_arm2.STL" />
      </geometry>
    </collision>
  </link>
  <joint
    name="R_arm2"
    type="continuous">
    <origin
      xyz="-0.170499999999998 0 0"
      rpy="0 0 0" />
    <parent
      link="R_arm1" />
    <child
      link="R_arm2" />
    <axis
      xyz="0 0 1" />
  </joint>
  <link
    name="R_arm3">
    <inertial>
      <origin
        xyz="-3.229776360128E-05 -1.49737468538847E-05 -0.187350702194845"
        rpy="0 0 0" />
      <mass
        value="0.0455132201726527" />
      <inertia
        ixx="1.04441289107308E-05"
        ixy="-1.2160922485046E-12"
        ixz="1.81663840661964E-07"
        iyy="1.24358375510277E-05"
        iyz="-2.28574770322622E-09"
        izz="7.82054953991461E-06" />
    </inertial>
    <visual>
      <origin
        xyz="0 0 0"
        rpy="0 0 0" />
      <geometry>
        <mesh
          filename="package://Roly_with_arm X12 version/meshes/R_arm3.STL" />
      </geometry>
      <material
        name="">
        <color
          rgba="0.752941176470588 0.752941176470588 0.752941176470588 1" />
      </material>
    </visual>
    <collision>
      <origin
        xyz="0 0 0"
        rpy="0 0 0" />
      <geometry>
        <mesh
          filename="package://Roly_with_arm X12 version/meshes/R_arm3.STL" />
      </geometry>
    </collision>
  </link>
  <joint
    name="R_arm3"
    type="continuous">
    <origin
      xyz="0 0 0"
      rpy="1.5707963267949 0 1.57079632679489" />
    <parent
      link="R_arm2" />
    <child
      link="R_arm3" />
    <axis
      xyz="0 0 1" />
  </joint>
  <link
    name="R_arm4">
    <inertial>
      <origin
        xyz="-0.0101576588872287 -0.0474946152588764 9.27931642478175E-05"
        rpy="0 0 0" />
      <mass
        value="0.0493363034804284" />
      <inertia
        ixx="9.03991587155392E-06"
        ixy="1.78932574784442E-07"
        ixz="2.4160338756813E-11"
        iyy="1.18657637430999E-05"
        iyz="-1.47190672634888E-11"
        izz="1.28686059122131E-05" />
    </inertial>
    <visual>
      <origin
        xyz="0 0 0"
        rpy="0 0 0" />
      <geometry>
        <mesh
          filename="package://Roly_with_arm X12 version/meshes/R_arm4.STL" />
      </geometry>
      <material
        name="">
        <color
          rgba="0.752941176470588 0.752941176470588 0.752941176470588 1" />
      </material>
    </visual>
    <collision>
      <origin
        xyz="0 0 0"
        rpy="0 0 0" />
      <geometry>
        <mesh
          filename="package://Roly_with_arm X12 version/meshes/R_arm4.STL" />
      </geometry>
    </collision>
  </link>
  <joint
    name="R_arm4"
    type="continuous">
    <origin
      xyz="0 0 -0.2003"
      rpy="1.5707963267949 0 1.57079632679489" />
    <parent
      link="R_arm3" />
    <child
      link="R_arm4" />
    <axis
      xyz="0 0 1" />
  </joint>
  <link
    name="R_palm">
    <inertial>
      <origin
        xyz="-0.011393804720238 0.0235201597117776 0.122398990601324"
        rpy="0 0 0" />
      <mass
        value="0.11370086762227" />
      <inertia
        ixx="1.37805698844369E-05"
        ixy="-2.42636927691283E-07"
        ixz="1.94877931641431E-07"
        iyy="4.21613319822172E-05"
        iyz="-2.4136054404023E-07"
        izz="4.19256804358657E-05" />
    </inertial>
    <visual>
      <origin
        xyz="0 0 0"
        rpy="0 0 0" />
      <geometry>
        <mesh
          filename="package://Roly_with_arm X12 version/meshes/R_palm.STL" />
      </geometry>
      <material
        name="">
        <color
          rgba="0.752941176470588 0.752941176470588 0.752941176470588 1" />
      </material>
    </visual>
    <collision>
      <origin
        xyz="0 0 0"
        rpy="0 0 0" />
      <geometry>
        <mesh
          filename="package://Roly_with_arm X12 version/meshes/R_palm.STL" />
      </geometry>
    </collision>
  </link>
  <joint
    name="R_palm"
    type="continuous">
    <origin
      xyz="0 0 0"
      rpy="1.5707963267949 0 0" />
    <parent
      link="R_arm4" />
    <child
      link="R_palm" />
    <axis
      xyz="0 0 1" />
  </joint>
  <link
    name="R finger1-1">
    <inertial>
      <origin
        xyz="-2.13717932240343E-15 -0.0114999999999992 4.71844785465692E-16"
        rpy="0 0 0" />
      <mass
        value="0.00127787614034051" />
      <inertia
        ixx="1.18414458975181E-07"
        ixy="-7.85331679126806E-24"
        ixz="-9.95032540747013E-24"
        iyy="2.02553394151494E-08"
        iyz="-4.72204409332132E-23"
        izz="1.35262128682756E-07" />
    </inertial>
    <visual>
      <origin
        xyz="0 0 0"
        rpy="0 0 0" />
      <geometry>
        <mesh
          filename="package://Roly_with_arm X12 version/meshes/R finger1-1.STL" />
      </geometry>
      <material
        name="">
        <color
          rgba="0.752941176470588 0.752941176470588 0.752941176470588 1" />
      </material>
    </visual>
    <collision>
      <origin
        xyz="0 0 0"
        rpy="0 0 0" />
      <geometry>
        <mesh
          filename="package://Roly_with_arm X12 version/meshes/R finger1-1.STL" />
      </geometry>
    </collision>
  </link>
  <joint
    name="R finger1-1"
    type="continuous">
    <origin
      xyz="-0.0350000000000064 0 0.14"
      rpy="-1.5707963267949 0 3.14159265358978" />
    <parent
      link="R_palm" />
    <child
      link="R finger1-1" />
    <axis
      xyz="0 0 1" />
  </joint>
  <link
    name="R finger1-2">
    <inertial>
      <origin
        xyz="-0.00382076453403931 -0.0297910509462691 1.94734034453248E-10"
        rpy="0 0 0" />
      <mass
        value="0.00707739738871867" />
      <inertia
        ixx="1.51715754069772E-06"
        ixy="2.43507202052062E-07"
        ixz="1.59954747626768E-13"
        iyy="3.21509711618996E-07"
        iyz="-4.4103912464431E-13"
        izz="1.72391332503902E-06" />
    </inertial>
    <visual>
      <origin
        xyz="0 0 0"
        rpy="0 0 0" />
      <geometry>
        <mesh
          filename="package://Roly_with_arm X12 version/meshes/R finger1-2.STL" />
      </geometry>
      <material
        name="">
        <color
          rgba="0.752941176470588 0.752941176470588 0.752941176470588 1" />
      </material>
    </visual>
    <collision>
      <origin
        xyz="0 0 0"
        rpy="0 0 0" />
      <geometry>
        <mesh
          filename="package://Roly_with_arm X12 version/meshes/R finger1-2.STL" />
      </geometry>
    </collision>
  </link>
  <joint
    name="R finger1-2"
    type="continuous">
    <origin
      xyz="0 -0.023 0"
      rpy="0 0 0" />
    <parent
      link="R finger1-1" />
    <child
      link="R finger1-2" />
    <axis
      xyz="0 0 1" />
  </joint>
  <link
    name="R finger2-1">
    <inertial>
      <origin
        xyz="-1.58206781009085E-15 -0.0114999999999992 2.77555756156289E-17"
        rpy="0 0 0" />
      <mass
        value="0.0012778761403405" />
      <inertia
        ixx="1.18414458975181E-07"
        ixy="2.72795675863621E-23"
        ixz="-1.65436122510606E-23"
        iyy="2.02553394151493E-08"
        iyz="1.58570877470788E-23"
        izz="1.35262128682756E-07" />
    </inertial>
    <visual>
      <origin
        xyz="0 0 0"
        rpy="0 0 0" />
      <geometry>
        <mesh
          filename="package://Roly_with_arm X12 version/meshes/R finger2-1.STL" />
      </geometry>
      <material
        name="">
        <color
          rgba="0.752941176470588 0.752941176470588 0.752941176470588 1" />
      </material>
    </visual>
    <collision>
      <origin
        xyz="0 0 0"
        rpy="0 0 0" />
      <geometry>
        <mesh
          filename="package://Roly_with_arm X12 version/meshes/R finger2-1.STL" />
      </geometry>
    </collision>
  </link>
  <joint
    name="R finger2-1"
    type="continuous">
    <origin
      xyz="0.0303108891324509 0.0174999999999965 0.14"
      rpy="-1.5707963267949 0 -2.61799387799151" />
    <parent
      link="R_palm" />
    <child
      link="R finger2-1" />
    <axis
      xyz="0 0 1" />
    <mimic
      joint=""
      multiplier="1"
      offset="0" />
  </joint>
  <link
    name="R finger2-2">
    <inertial>
      <origin
        xyz="0.00382076453403551 -0.0297910509462691 -1.94733673630765E-10"
        rpy="0 0 0" />
      <mass
        value="0.00707739738871865" />
      <inertia
        ixx="1.51715754069772E-06"
        ixy="-2.43507202052063E-07"
        ixz="1.59954747898131E-13"
        iyy="3.21509711618996E-07"
        iyz="4.41039125506766E-13"
        izz="1.72391332503902E-06" />
    </inertial>
    <visual>
      <origin
        xyz="0 0 0"
        rpy="0 0 0" />
      <geometry>
        <mesh
          filename="package://Roly_with_arm X12 version/meshes/R finger2-2.STL" />
      </geometry>
      <material
        name="">
        <color
          rgba="0.752941176470588 0.752941176470588 0.752941176470588 1" />
      </material>
    </visual>
    <collision>
      <origin
        xyz="0 0 0"
        rpy="0 0 0" />
      <geometry>
        <mesh
          filename="package://Roly_with_arm X12 version/meshes/R finger2-2.STL" />
      </geometry>
    </collision>
  </link>
  <joint
    name="R finger2-2"
    type="continuous">
    <origin
      xyz="0 -0.023 0"
      rpy="0 0 0" />
    <parent
      link="R finger2-1" />
    <child
      link="R finger2-2" />
    <axis
      xyz="0 0 1" />
    <mimic
      joint=""
      multiplier="1"
      offset="0" />
  </joint>
  <link
    name="R finger3-1">
    <inertial>
      <origin
        xyz="-2.06779038336435E-15 -0.0114999999999991 -7.21644966006352E-16"
        rpy="0 0 0" />
      <mass
        value="0.00127787614034051" />
      <inertia
        ixx="1.18414458975182E-07"
        ixy="-3.25063862816992E-23"
        ixz="9.92616735063633E-24"
        iyy="2.02553394151494E-08"
        iyz="-2.01107497623748E-23"
        izz="1.35262128682756E-07" />
    </inertial>
    <visual>
      <origin
        xyz="0 0 0"
        rpy="0 0 0" />
      <geometry>
        <mesh
          filename="package://Roly_with_arm X12 version/meshes/R finger3-1.STL" />
      </geometry>
      <material
        name="">
        <color
          rgba="0.752941176470588 0.752941176470588 0.752941176470588 1" />
      </material>
    </visual>
    <collision>
      <origin
        xyz="0 0 0"
        rpy="0 0 0" />
      <geometry>
        <mesh
          filename="package://Roly_with_arm X12 version/meshes/R finger3-1.STL" />
      </geometry>
    </collision>
  </link>
  <joint
    name="R finger3-1"
    type="continuous">
    <origin
      xyz="0.0303108891324489 -0.0175000000000004 0.14"
      rpy="-1.5707963267949 0 2.61799387799149" />
    <parent
      link="R_palm" />
    <child
      link="R finger3-1" />
    <axis
      xyz="0 0 1" />
    <mimic
      joint=""
      multiplier="1"
      offset="0" />
  </joint>
  <link
    name="R finger3-2">
    <inertial>
      <origin
        xyz="0.00382076453403511 -0.0297910509462691 -1.9473433976458E-10"
        rpy="0 0 0" />
      <mass
        value="0.00707739738871867" />
      <inertia
        ixx="1.51715754069773E-06"
        ixy="-2.43507202052062E-07"
        ixz="1.5995474805695E-13"
        iyy="3.21509711618996E-07"
        iyz="4.41039125929004E-13"
        izz="1.72391332503902E-06" />
    </inertial>
    <visual>
      <origin
        xyz="0 0 0"
        rpy="0 0 0" />
      <geometry>
        <mesh
          filename="package://Roly_with_arm X12 version/meshes/R finger3-2.STL" />
      </geometry>
      <material
        name="">
        <color
          rgba="0.752941176470588 0.752941176470588 0.752941176470588 1" />
      </material>
    </visual>
    <collision>
      <origin
        xyz="0 0 0"
        rpy="0 0 0" />
      <geometry>
        <mesh
          filename="package://Roly_with_arm X12 version/meshes/R finger3-2.STL" />
      </geometry>
    </collision>
  </link>
  <joint
    name="R finger3-2"
    type="continuous">
    <origin
      xyz="0 -0.023 0"
      rpy="0 0 0" />
    <parent
      link="R finger3-1" />
    <child
      link="R finger3-2" />
    <axis
      xyz="0 0 1" />
    <mimic
      joint=""
      multiplier="1"
      offset="0" />
  </joint>
  <link
    name="R gripper">
    <inertial>
      <origin
        xyz="5.27355936696949E-16 0.00156504693314396 -1.38777878078145E-17"
        rpy="0 0 0" />
      <mass
        value="0.00609127056774437" />
      <inertia
        ixx="8.38284437689385E-07"
        ixy="-3.65507433083676E-21"
        ixz="1.57900664607769E-22"
        iyy="3.77175708246467E-07"
        iyz="3.1489536491342E-22"
        izz="9.34655494343132E-07" />
    </inertial>
    <visual>
      <origin
        xyz="0 0 0"
        rpy="0 0 0" />
      <geometry>
        <mesh
          filename="package://Roly_with_arm X12 version/meshes/R gripper.STL" />
      </geometry>
      <material
        name="">
        <color
          rgba="0.792156862745098 0.819607843137255 0.933333333333333 1" />
      </material>
    </visual>
    <collision>
      <origin
        xyz="0 0 0"
        rpy="0 0 0" />
      <geometry>
        <mesh
          filename="package://Roly_with_arm X12 version/meshes/R gripper.STL" />
      </geometry>
    </collision>
  </link>
  <joint
    name="R gripper"
    type="prismatic">
    <origin
      xyz="0 0 0.0430000000002747"
      rpy="0 0 -1.5707963267949" />
    <parent
      link="R_palm" />
    <child
      link="R gripper" />
    <axis
      xyz="0 0 1" />
    <limit
      lower="0"
      upper="0.03"
      effort="0"
      velocity="0" />
  </joint>
  <link
    name="L_shoulder">
    <inertial>
      <origin
        xyz="-4.78827689023352E-05 0.0156539518070297 -0.248204682969382"
        rpy="0 0 0" />
      <mass
        value="0.159233792908747" />
      <inertia
        ixx="5.90635379080722E-05"
        ixy="6.76336036224615E-07"
        ixz="3.93669860263999E-09"
        iyy="4.06885503332512E-05"
        iyz="1.24343094958913E-08"
        izz="7.36582148170001E-05" />
    </inertial>
    <visual>
      <origin
        xyz="0 0 0"
        rpy="0 0 0" />
      <geometry>
        <mesh
          filename="package://Roly_with_arm X12 version/meshes/L_shoulder.STL" />
      </geometry>
      <material
        name="">
        <color
          rgba="0.752941176470588 0.752941176470588 0.752941176470588 1" />
      </material>
    </visual>
    <collision>
      <origin
        xyz="0 0 0"
        rpy="0 0 0" />
      <geometry>
        <mesh
          filename="package://Roly_with_arm X12 version/meshes/L_shoulder.STL" />
      </geometry>
    </collision>
  </link>
  <joint
    name="L_shoulder"
    type="continuous">
    <origin
      xyz="0 0 0.495"
      rpy="1.5707963267949 0 0" />
    <parent
      link="trunk_link" />
    <child
      link="L_shoulder" />
    <axis
      xyz="0 0 1" />
  </joint>
  <link
    name="L_arm1">
    <inertial>
      <origin
        xyz="-0.133478677155532 -1.33027489930548E-05 -7.69190748466966E-06"
        rpy="0 0 0" />
      <mass
        value="0.189027914267191" />
      <inertia
        ixx="5.50086142024179E-05"
        ixy="-6.05444469004796E-09"
        ixz="6.7633762077662E-07"
        iyy="9.02607737592395E-05"
        iyz="3.93877325849219E-09"
        izz="6.73964220277782E-05" />
    </inertial>
    <visual>
      <origin
        xyz="0 0 0"
        rpy="0 0 0" />
      <geometry>
        <mesh
          filename="package://Roly_with_arm X12 version/meshes/L_arm1.STL" />
      </geometry>
      <material
        name="">
        <color
          rgba="0.752941176470588 0.752941176470588 0.752941176470588 1" />
      </material>
    </visual>
    <collision>
      <origin
        xyz="0 0 0"
        rpy="0 0 0" />
      <geometry>
        <mesh
          filename="package://Roly_with_arm X12 version/meshes/L_arm1.STL" />
      </geometry>
    </collision>
  </link>
  <joint
    name="L_arm1"
    type="continuous">
    <origin
      xyz="0 0 -0.248800000000003"
      rpy="1.57079632679491 0 1.5707963267949" />
    <parent
      link="L_shoulder" />
    <child
      link="L_arm1" />
    <axis
      xyz="0 0 1" />
  </joint>
  <link
    name="L_arm2">
    <inertial>
      <origin
        xyz="-0.0928720824550845 1.67413663793026E-07 -0.0065196731730373"
        rpy="0 0 0" />
      <mass
        value="0.0759195681603366" />
      <inertia
        ixx="2.47922147148806E-05"
        ixy="2.31861399240551E-11"
        ixz="1.7893212345905E-07"
        iyy="2.9226854952603E-05"
        iyz="2.41603171468977E-11"
        izz="1.61014820114889E-05" />
    </inertial>
    <visual>
      <origin
        xyz="0 0 0"
        rpy="0 0 0" />
      <geometry>
        <mesh
          filename="package://Roly_with_arm X12 version/meshes/L_arm2.STL" />
      </geometry>
      <material
        name="">
        <color
          rgba="0.752941176470588 0.752941176470588 0.752941176470588 1" />
      </material>
    </visual>
    <collision>
      <origin
        xyz="0 0 0"
        rpy="0 0 0" />
      <geometry>
        <mesh
          filename="package://Roly_with_arm X12 version/meshes/L_arm2.STL" />
      </geometry>
    </collision>
  </link>
  <joint
    name="L_arm2"
    type="continuous">
    <origin
      xyz="-0.170499999999999 0 0"
      rpy="0 0 0" />
    <parent
      link="L_arm1" />
    <child
      link="L_arm2" />
    <axis
      xyz="0 0 1" />
  </joint>
  <link
    name="L_arm3">
    <inertial>
      <origin
        xyz="3.22976181230394E-05 -1.49723623597797E-05 -0.187350702159037"
        rpy="0 0 0" />
      <mass
        value="0.0455132202581581" />
      <inertia
        ixx="1.04441289466614E-05"
        ixy="-1.2136321683183E-12"
        ixz="-1.81663846805559E-07"
        iyy="1.24358376004975E-05"
        iyz="-2.28507494410208E-09"
        izz="7.82054955180841E-06" />
    </inertial>
    <visual>
      <origin
        xyz="0 0 0"
        rpy="0 0 0" />
      <geometry>
        <mesh
          filename="package://Roly_with_arm X12 version/meshes/L_arm3.STL" />
      </geometry>
      <material
        name="">
        <color
          rgba="0.752941176470588 0.752941176470588 0.752941176470588 1" />
      </material>
    </visual>
    <collision>
      <origin
        xyz="0 0 0"
        rpy="0 0 0" />
      <geometry>
        <mesh
          filename="package://Roly_with_arm X12 version/meshes/L_arm3.STL" />
      </geometry>
    </collision>
  </link>
  <joint
    name="L_arm3"
    type="continuous">
    <origin
      xyz="0 0 0"
      rpy="1.5707963267949 0 1.5707963267949" />
    <parent
      link="L_arm2" />
    <child
      link="L_arm3" />
    <axis
      xyz="0 0 1" />
  </joint>
  <link
    name="L_arm4">
    <inertial>
      <origin
        xyz="-0.0101576588877213 -0.047494615258864 -9.22779261514073E-05"
        rpy="0 0 0" />
      <mass
        value="0.0493363034804284" />
      <inertia
        ixx="9.03991587155392E-06"
        ixy="1.78932578789148E-07"
        ixz="2.41603387321551E-11"
        iyy="1.18657637430999E-05"
        iyz="6.10913668989936E-11"
        izz="1.28686059122131E-05" />
    </inertial>
    <visual>
      <origin
        xyz="0 0 0"
        rpy="0 0 0" />
      <geometry>
        <mesh
          filename="package://Roly_with_arm X12 version/meshes/L_arm4.STL" />
      </geometry>
      <material
        name="">
        <color
          rgba="0.752941176470588 0.752941176470588 0.752941176470588 1" />
      </material>
    </visual>
    <collision>
      <origin
        xyz="0 0 0"
        rpy="0 0 0" />
      <geometry>
        <mesh
          filename="package://Roly_with_arm X12 version/meshes/L_arm4.STL" />
      </geometry>
    </collision>
  </link>
  <joint
    name="L_arm4"
    type="continuous">
    <origin
      xyz="0 0 -0.200300000000001"
      rpy="1.5707963267949 0 1.5707963267949" />
    <parent
      link="L_arm3" />
    <child
      link="L_arm4" />
    <axis
      xyz="0 0 1" />
  </joint>
  <link
    name="L_palm">
    <inertial>
      <origin
        xyz="-0.0113941026685173 -0.0235199290031709 0.122398988054478"
        rpy="0 0 0" />
      <mass
        value="0.113700877525943" />
      <inertia
        ixx="1.3780572871713E-05"
        ixy="-2.42636911354403E-07"
        ixz="-5.57775675048596E-07"
        iyy="4.21613337338275E-05"
        iyz="2.41305400461025E-07"
        izz="4.19256816055249E-05" />
    </inertial>
    <visual>
      <origin
        xyz="0 0 0"
        rpy="0 0 0" />
      <geometry>
        <mesh
          filename="package://Roly_with_arm X12 version/meshes/L_palm.STL" />
      </geometry>
      <material
        name="">
        <color
          rgba="0.752941176470588 0.752941176470588 0.752941176470588 1" />
      </material>
    </visual>
    <collision>
      <origin
        xyz="0 0 0"
        rpy="0 0 0" />
      <geometry>
        <mesh
          filename="package://Roly_with_arm X12 version/meshes/L_palm.STL" />
      </geometry>
    </collision>
  </link>
  <joint
    name="L_palm"
    type="continuous">
    <origin
      xyz="0 0 0"
      rpy="1.5707963267949 0 0" />
    <parent
      link="L_arm4" />
    <child
      link="L_palm" />
    <axis
      xyz="0 0 1" />
  </joint>
  <link
    name="L finger1-1">
    <inertial>
      <origin
        xyz="-6.03683769639929E-16 -0.0114999999999965 -2.4980018054066E-16"
        rpy="0 0 0" />
      <mass
        value="0.0012778761403405" />
      <inertia
        ixx="1.1841445897518E-07"
        ixy="-1.05950121737481E-23"
        ixz="6.14119701119139E-25"
        iyy="2.02553394151493E-08"
        iyz="-1.78196975440135E-24"
        izz="1.35262128682755E-07" />
    </inertial>
    <visual>
      <origin
        xyz="0 0 0"
        rpy="0 0 0" />
      <geometry>
        <mesh
          filename="package://Roly_with_arm X12 version/meshes/L finger1-1.STL" />
      </geometry>
      <material
        name="">
        <color
          rgba="0.752941176470588 0.752941176470588 0.752941176470588 1" />
      </material>
    </visual>
    <collision>
      <origin
        xyz="0 0 0"
        rpy="0 0 0" />
      <geometry>
        <mesh
          filename="package://Roly_with_arm X12 version/meshes/L finger1-1.STL" />
      </geometry>
    </collision>
  </link>
  <joint
    name="L finger1-1"
    type="continuous">
    <origin
      xyz="-0.0350000000000003 0 0.14"
      rpy="-1.5707963267949 0 3.14159265358978" />
    <parent
      link="L_palm" />
    <child
      link="L finger1-1" />
    <axis
      xyz="0 0 1" />
  </joint>
  <link
    name="L finger1-2">
    <inertial>
      <origin
        xyz="-0.00382076453404034 -0.0297910509462667 1.94733673630765E-10"
        rpy="0 0 0" />
      <mass
        value="0.00707739738871865" />
      <inertia
        ixx="1.51715754069772E-06"
        ixy="2.43507202052061E-07"
        ixz="1.59954748015483E-13"
        iyy="3.21509711618994E-07"
        iyz="-4.41039125502671E-13"
        izz="1.72391332503901E-06" />
    </inertial>
    <visual>
      <origin
        xyz="0 0 0"
        rpy="0 0 0" />
      <geometry>
        <mesh
          filename="package://Roly_with_arm X12 version/meshes/L finger1-2.STL" />
      </geometry>
      <material
        name="">
        <color
          rgba="0.752941176470588 0.752941176470588 0.752941176470588 1" />
      </material>
    </visual>
    <collision>
      <origin
        xyz="0 0 0"
        rpy="0 0 0" />
      <geometry>
        <mesh
          filename="package://Roly_with_arm X12 version/meshes/L finger1-2.STL" />
      </geometry>
    </collision>
  </link>
  <joint
    name="L finger1-2"
    type="continuous">
    <origin
      xyz="0 -0.023 0"
      rpy="0 0 0" />
    <parent
      link="L finger1-1" />
    <child
      link="L finger1-2" />
    <axis
      xyz="0 0 1" />
  </joint>
  <link
    name="L finger2-1">
    <inertial>
      <origin
        xyz="-2.77555756156289E-17 -0.0114999999999964 3.60822483003176E-16"
        rpy="0 0 0" />
      <mass
        value="0.00127787614034051" />
      <inertia
        ixx="1.18414458975181E-07"
        ixy="1.14268233933351E-22"
        ixz="1.32348898008484E-23"
        iyy="2.02553394151493E-08"
        iyz="-3.45744791431346E-23"
        izz="1.35262128682756E-07" />
    </inertial>
    <visual>
      <origin
        xyz="0 0 0"
        rpy="0 0 0" />
      <geometry>
        <mesh
          filename="package://Roly_with_arm X12 version/meshes/L finger2-1.STL" />
      </geometry>
      <material
        name="">
        <color
          rgba="0.752941176470588 0.752941176470588 0.752941176470588 1" />
      </material>
    </visual>
    <collision>
      <origin
        xyz="0 0 0"
        rpy="0 0 0" />
      <geometry>
        <mesh
          filename="package://Roly_with_arm X12 version/meshes/L finger2-1.STL" />
      </geometry>
    </collision>
  </link>
  <joint
    name="L finger2-1"
    type="continuous">
    <origin
      xyz="0.0303108891324555 -0.0174999999999996 0.139999999999999"
      rpy="-1.5707963267949 0 2.61799387799149" />
    <parent
      link="L_palm" />
    <child
      link="L finger2-1" />
    <axis
      xyz="0 0 1" />
  </joint>
  <link
    name="L finger2-2">
    <inertial>
      <origin
        xyz="0.00382076453403721 -0.0297910509462663 -1.94732951985799E-10"
        rpy="0 0 0" />
      <mass
        value="0.00707739738871867" />
      <inertia
        ixx="1.51715754069773E-06"
        ixy="-2.43507202052062E-07"
        ixz="1.59954747792252E-13"
        iyy="3.21509711618997E-07"
        iyz="4.41039126079084E-13"
        izz="1.72391332503902E-06" />
    </inertial>
    <visual>
      <origin
        xyz="0 0 0"
        rpy="0 0 0" />
      <geometry>
        <mesh
          filename="package://Roly_with_arm X12 version/meshes/L finger2-2.STL" />
      </geometry>
      <material
        name="">
        <color
          rgba="0.752941176470588 0.752941176470588 0.752941176470588 1" />
      </material>
    </visual>
    <collision>
      <origin
        xyz="0 0 0"
        rpy="0 0 0" />
      <geometry>
        <mesh
          filename="package://Roly_with_arm X12 version/meshes/L finger2-2.STL" />
      </geometry>
    </collision>
  </link>
  <joint
    name="L finger2-2"
    type="continuous">
    <origin
      xyz="0 -0.023 0"
      rpy="0 0 0" />
    <parent
      link="L finger2-1" />
    <child
      link="L finger2-2" />
    <axis
      xyz="0 0 1" />
  </joint>
  <link
    name="L finger3-1">
    <inertial>
      <origin
        xyz="4.16333634234434E-16 -0.0114999999999966 -2.77555756156289E-16"
        rpy="0 0 0" />
      <mass
        value="0.00127787614034051" />
      <inertia
        ixx="1.18414458975181E-07"
        ixy="3.39189818845324E-23"
        ixz="0"
        iyy="2.02553394151494E-08"
        iyz="6.06279011789309E-23"
        izz="1.35262128682756E-07" />
    </inertial>
    <visual>
      <origin
        xyz="0 0 0"
        rpy="0 0 0" />
      <geometry>
        <mesh
          filename="package://Roly_with_arm X12 version/meshes/L finger3-1.STL" />
      </geometry>
      <material
        name="">
        <color
          rgba="0.752941176470588 0.752941176470588 0.752941176470588 1" />
      </material>
    </visual>
    <collision>
      <origin
        xyz="0 0 0"
        rpy="0 0 0" />
      <geometry>
        <mesh
          filename="package://Roly_with_arm X12 version/meshes/L finger3-1.STL" />
      </geometry>
    </collision>
  </link>
  <joint
    name="L finger3-1"
    type="continuous">
    <origin
      xyz="0.0303108891324564 0.0174999999999999 0.139999999999999"
      rpy="-1.5707963267949 0 -2.61799387799151" />
    <parent
      link="L_palm" />
    <child
      link="L finger3-1" />
    <axis
      xyz="0 0 1" />
  </joint>
  <link
    name="L finger3-2">
    <inertial>
      <origin
        xyz="0.00382076453403753 -0.0297910509462666 -1.94733867919794E-10"
        rpy="0 0 0" />
      <mass
        value="0.00707739738871864" />
      <inertia
        ixx="1.51715754069772E-06"
        ixy="-2.43507202052061E-07"
        ixz="1.5995474805695E-13"
        iyy="3.21509711618995E-07"
        iyz="4.4103912542856E-13"
        izz="1.72391332503901E-06" />
    </inertial>
    <visual>
      <origin
        xyz="0 0 0"
        rpy="0 0 0" />
      <geometry>
        <mesh
          filename="package://Roly_with_arm X12 version/meshes/L finger3-2.STL" />
      </geometry>
      <material
        name="">
        <color
          rgba="0.752941176470588 0.752941176470588 0.752941176470588 1" />
      </material>
    </visual>
    <collision>
      <origin
        xyz="0 0 0"
        rpy="0 0 0" />
      <geometry>
        <mesh
          filename="package://Roly_with_arm X12 version/meshes/L finger3-2.STL" />
      </geometry>
    </collision>
  </link>
  <joint
    name="L finger3-2"
    type="continuous">
    <origin
      xyz="0 -0.023 0"
      rpy="0 0 0" />
    <parent
      link="L finger3-1" />
    <child
      link="L finger3-2" />
    <axis
      xyz="0 0 1" />
  </joint>
  <link
    name="L gripper">
    <inertial>
      <origin
        xyz="0 0.00156504693314186 2.74252842658029E-13"
        rpy="0 0 0" />
      <mass
        value="0.00609127056774437" />
      <inertia
        ixx="8.38284437689384E-07"
        ixy="2.01923264715392E-22"
        ixz="1.00958464778017E-22"
        iyy="3.77175708246467E-07"
        iyz="-9.19705800213186E-23"
        izz="9.34655494343132E-07" />
    </inertial>
    <visual>
      <origin
        xyz="0 0 0"
        rpy="0 0 0" />
      <geometry>
        <mesh
          filename="package://Roly_with_arm X12 version/meshes/L gripper.STL" />
      </geometry>
      <material
        name="">
        <color
          rgba="0.792156862745098 0.819607843137255 0.933333333333333 1" />
      </material>
    </visual>
    <collision>
      <origin
        xyz="0 0 0"
        rpy="0 0 0" />
      <geometry>
        <mesh
          filename="package://Roly_with_arm X12 version/meshes/L gripper.STL" />
      </geometry>
    </collision>
  </link>
  <joint
    name="L gripper"
    type="prismatic">
    <origin
      xyz="0 0 0.0430000000029319"
      rpy="0 0 -1.5707963267949" />
    <parent
      link="L_palm" />
    <child
      link="L gripper" />
    <axis
      xyz="0 0 1" />
    <limit
      lower="0"
      upper="0.03"
      effort="0"
      velocity="0" />
  </joint>
</robot>