<?xml version="1.0" encoding="utf-8"?>
<!-- This URDF was automatically created by SolidWorks to URDF Exporter! Originally created by Stephen Brawner (brawner@gmail.com) 
     Commit Version: 1.6.0-4-g7f85cfe  Build Version: 1.6.7995.38578
     For more information, please see http://wiki.ros.org/sw_urdf_exporter -->
<robot
  name="Roly_with_arm9">
  <mujoco>
    <compiler meshdir="../meshes" balanceinertia="true" discardvisual="false"/>
  </mujoco>
  <link
    name="base_link">
    <inertial>
      <origin
        xyz="-2.09693302730873E-05 -4.03623384600333E-13 0.00528213087611431"
        rpy="0 0 0" />
      <mass
        value="4.35454338307742" />
      <inertia
        ixx="0.0197722203546471"
        ixy="1.18998862197292E-07"
        ixz="6.7770411068282E-06"
        iyy="0.00413553225471282"
        iyz="-7.81020639127251E-15"
        izz="0.021630011357051" />
    </inertial>
    <visual>
      <origin
        xyz="0 0 0"
        rpy="0 0 0" />
      <geometry>
        <mesh
          filename="package://Roly_with_arm9/meshes/base_link.STL" />
      </geometry>
      <material
        name="">
        <color
          rgba="0.752941176470588 0.752941176470588 0.752941176470588 1" />
      </material>
    </visual>
    <collision>
      <origin
        xyz="0 0 0"
        rpy="0 0 0" />
      <geometry>
        <mesh
          filename="package://Roly_with_arm9/meshes/base_link.STL" />
      </geometry>
    </collision>
  </link>
  <link
    name="R_hip_yaw">
    <inertial>
      <origin
        xyz="-0.0551157453462434 -6.37588778601428E-05 -0.0843448458503073"
        rpy="0 0 0" />
      <mass
        value="1.43214345091561" />
      <inertia
        ixx="0.00166279676292496"
        ixy="-2.25901370225581E-06"
        ixz="8.23440880245642E-07"
        iyy="0.00137829761902421"
        iyz="-5.71796483936079E-13"
        izz="0.00159533562608115" />
    </inertial>
    <visual>
      <origin
        xyz="0 0 0"
        rpy="0 0 0" />
      <geometry>
        <mesh
          filename="package://Roly_with_arm9/meshes/R_hip_yaw.STL" />
      </geometry>
      <material
        name="">
        <color
          rgba="0.752941176470588 0.752941176470588 0.752941176470588 1" />
      </material>
    </visual>
    <collision>
      <origin
        xyz="0 0 0"
        rpy="0 0 0" />
      <geometry>
        <mesh
          filename="package://Roly_with_arm9/meshes/R_hip_yaw.STL" />
      </geometry>
    </collision>
  </link>
  <joint
    name="R_hip_yaw"
    type="continuous">
    <origin
      xyz="0 -0.13 0"
      rpy="0 0 0" />
    <parent
      link="base_link" />
    <child
      link="R_hip_yaw" />
    <axis
      xyz="0 0 1" />
  </joint>
  <link
    name="R_hip_roll">
    <inertial>
      <origin
        xyz="0.00148012987693896 4.39768767235282E-09 9.44097992160297E-05"
        rpy="0 0 0" />
      <mass
        value="1.31563499532916" />
      <inertia
        ixx="0.000586960069643613"
        ixy="-1.61482924035937E-11"
        ixz="-4.23254347232259E-13"
        iyy="0.00199706384380774"
        iyz="9.90320587269463E-13"
        izz="0.00189601334783963" />
    </inertial>
    <visual>
      <origin
        xyz="0 0 0"
        rpy="0 0 0" />
      <geometry>
        <mesh
          filename="package://Roly_with_arm9/meshes/R_hip_roll.STL" />
      </geometry>
      <material
        name="">
        <color
          rgba="0.752941176470588 0.752941176470588 0.752941176470588 1" />
      </material>
    </visual>
    <collision>
      <origin
        xyz="0 0 0"
        rpy="0 0 0" />
      <geometry>
        <mesh
          filename="package://Roly_with_arm9/meshes/R_hip_roll.STL" />
      </geometry>
    </collision>
  </link>
  <joint
    name="R_hip_roll"
    type="continuous">
    <origin
      xyz="0 0 -0.100499999999984"
      rpy="1.5707963267949 0 1.5707963267949" />
    <parent
      link="R_hip_yaw" />
    <child
      link="R_hip_roll" />
    <axis
      xyz="0 0 1" />
  </joint>
  <link
    name="R_hip_pitch">
    <inertial>
      <origin
        xyz="-0.149911356974161 0.00102058562119425 0.0013820449571266"
        rpy="0 0 0" />
      <mass
        value="2.59034581862293" />
      <inertia
        ixx="0.00368152189538091"
        ixy="2.60027571776194E-05"
        ixz="-2.32790309814718E-08"
        iyy="0.00509733345831479"
        iyz="-2.00560044278426E-06"
        izz="0.00565081393341751" />
    </inertial>
    <visual>
      <origin
        xyz="0 0 0"
        rpy="0 0 0" />
      <geometry>
        <mesh
          filename="package://Roly_with_arm9/meshes/R_hip_pitch.STL" />
      </geometry>
      <material
        name="">
        <color
          rgba="0.752941176470588 0.752941176470588 0.752941176470588 1" />
      </material>
    </visual>
    <collision>
      <origin
        xyz="0 0 0"
        rpy="0 0 0" />
      <geometry>
        <mesh
          filename="package://Roly_with_arm9/meshes/R_hip_pitch.STL" />
      </geometry>
    </collision>
  </link>
  <joint
    name="R_hip_pitch"
    type="continuous">
    <origin
      xyz="0 0 0"
      rpy="1.5707963267949 0 1.5707963267949" />
    <parent
      link="R_hip_roll" />
    <child
      link="R_hip_pitch" />
    <axis
      xyz="0 0 1" />
  </joint>
  <link
    name="R_calf">
    <inertial>
      <origin
        xyz="-0.115445160832685 -0.000559768363222833 -0.0101642953168719"
        rpy="0 0 0" />
      <mass
        value="1.86216970756978" />
      <inertia
        ixx="0.00121693708160006"
        ixy="1.75971149586229E-05"
        ixz="-1.72650949756646E-06"
        iyy="0.00442117021095285"
        iyz="4.63776535906202E-08"
        izz="0.00516207706040075" />
    </inertial>
    <visual>
      <origin
        xyz="0 0 0"
        rpy="0 0 0" />
      <geometry>
        <mesh
          filename="package://Roly_with_arm9/meshes/R_calf.STL" />
      </geometry>
      <material
        name="">
        <color
          rgba="0.752941176470588 0.752941176470588 0.752941176470588 1" />
      </material>
    </visual>
    <collision>
      <origin
        xyz="0 0 0"
        rpy="0 0 0" />
      <geometry>
        <mesh
          filename="package://Roly_with_arm9/meshes/R_calf.STL" />
      </geometry>
    </collision>
  </link>
  <joint
    name="R_calf"
    type="continuous">
    <origin
      xyz="-0.31 0 0"
      rpy="0 0 0" />
    <parent
      link="R_hip_pitch" />
    <child
      link="R_calf" />
    <axis
      xyz="0 0 1" />
  </joint>
  <link
    name="R_ankle_pitch">
    <inertial>
      <origin
        xyz="-0.0459602409816353 0.0196316983322056 -4.06788864645846E-05"
        rpy="0 0 0" />
      <mass
        value="0.990577841443613" />
      <inertia
        ixx="0.00101039561412582"
        ixy="1.54677494342956E-05"
        ixz="-8.03493865707325E-13"
        iyy="0.000487571749316865"
        iyz="-4.5006050049064E-13"
        izz="0.00115084495203271" />
    </inertial>
    <visual>
      <origin
        xyz="0 0 0"
        rpy="0 0 0" />
      <geometry>
        <mesh
          filename="package://Roly_with_arm9/meshes/R_ankle_pitch.STL" />
      </geometry>
      <material
        name="">
        <color
          rgba="0.752941176470588 0.752941176470588 0.752941176470588 1" />
      </material>
    </visual>
    <collision>
      <origin
        xyz="0 0 0"
        rpy="0 0 0" />
      <geometry>
        <mesh
          filename="package://Roly_with_arm9/meshes/R_ankle_pitch.STL" />
      </geometry>
    </collision>
  </link>
  <joint
    name="R_ankle_pitch"
    type="continuous">
    <origin
      xyz="-0.26 0 0"
      rpy="0 0 0" />
    <parent
      link="R_calf" />
    <child
      link="R_ankle_pitch" />
    <axis
      xyz="0 0 1" />
  </joint>
  <link
    name="R_ankle_roll">
    <inertial>
      <origin
        xyz="-0.0685998049350528 2.1956714224558E-11 0.019999999988339"
        rpy="0 0 0" />
      <mass
        value="1.80750858879406" />
      <inertia
        ixx="0.00356060489977588"
        ixy="5.08107152413919E-14"
        ixz="7.01373883488739E-14"
        iyy="0.00313608673879828"
        iyz="-3.22423635393295E-13"
        izz="0.000582664567478919" />
    </inertial>
    <visual>
      <origin
        xyz="0 0 0"
        rpy="0 0 0" />
      <geometry>
        <mesh
          filename="package://Roly_with_arm9/meshes/R_ankle_roll.STL" />
      </geometry>
      <material
        name="">
        <color
          rgba="0.752941176470588 0.752941176470588 0.752941176470588 1" />
      </material>
    </visual>
    <collision>
      <origin
        xyz="0 0 0"
        rpy="0 0 0" />
      <geometry>
        <mesh
          filename="package://Roly_with_arm9/meshes/R_ankle_roll.STL" />
      </geometry>
    </collision>
  </link>
  <joint
    name="R_ankle_roll"
    type="continuous">
    <origin
      xyz="-0.05 0 0"
      rpy="-1.57079632679489 0 0" />
    <parent
      link="R_ankle_pitch" />
    <child
      link="R_ankle_roll" />
    <axis
      xyz="0 0 1" />
  </joint>
  <link
    name="R_knee_rocker">
    <inertial>
      <origin
        xyz="-0.00719496594494928 -0.00261875342603682 -0.0168740723753153"
        rpy="0 0 0" />
      <mass
        value="0.147234181769685" />
      <inertia
        ixx="3.23048235524151E-05"
        ixy="-1.42989160924717E-05"
        ixz="-6.07779307992846E-06"
        iyy="6.63863926537153E-05"
        iyz="-2.21213576180986E-06"
        izz="8.94281354141202E-05" />
    </inertial>
    <visual>
      <origin
        xyz="0 0 0"
        rpy="0 0 0" />
      <geometry>
        <mesh
          filename="package://Roly_with_arm9/meshes/R_knee_rocker.STL" />
      </geometry>
      <material
        name="">
        <color
          rgba="0.752941176470588 0.752941176470588 0.752941176470588 1" />
      </material>
    </visual>
    <collision>
      <origin
        xyz="0 0 0"
        rpy="0 0 0" />
      <geometry>
        <mesh
          filename="package://Roly_with_arm9/meshes/R_knee_rocker.STL" />
      </geometry>
    </collision>
  </link>
  <joint
    name="R_knee_rocker"
    type="continuous">
    <origin
      xyz="-0.16 0 -0.0345000000000003"
      rpy="0 0 0" />
    <parent
      link="R_hip_pitch" />
    <child
      link="R_knee_rocker" />
    <axis
      xyz="0 0 1" />
  </joint>
  <link
    name="R_knee_linkage">
    <inertial>
      <origin
        xyz="-0.073190218431471 0.0266387984841576 -5.56249490912819E-13"
        rpy="0 0 0" />
      <mass
        value="0.110281845782562" />
      <inertia
        ixx="1.16107281437619E-05"
        ixy="2.38947586603858E-05"
        ixz="2.06937518275148E-13"
        iyy="6.85640571092493E-05"
        iyz="5.72483218249403E-13"
        izz="7.74131693353276E-05" />
    </inertial>
    <visual>
      <origin
        xyz="0 0 0"
        rpy="0 0 0" />
      <geometry>
        <mesh
          filename="package://Roly_with_arm9/meshes/R_knee_linkage.STL" />
      </geometry>
      <material
        name="">
        <color
          rgba="0.752941176470588 0.752941176470588 0.752941176470588 1" />
      </material>
    </visual>
    <collision>
      <origin
        xyz="0 0 0"
        rpy="0 0 0" />
      <geometry>
        <mesh
          filename="package://Roly_with_arm9/meshes/R_knee_linkage.STL" />
      </geometry>
    </collision>
  </link>
  <joint
    name="R_knee_linkage"
    type="continuous">
    <origin
      xyz="-0.056382 -0.020521 -0.0215"
      rpy="0 0 0.34907" />
    <parent
      link="R_knee_rocker" />
    <child
      link="R_knee_linkage" />
    <axis
      xyz="0 0 1" />
  </joint>
  <link
    name="L_hip_yaw">
    <inertial>
      <origin
        xyz="-0.0551157453462434 -6.37588778603371E-05 -0.0843448458503074"
        rpy="0 0 0" />
      <mass
        value="1.43214345091561" />
      <inertia
        ixx="0.00166279676292496"
        ixy="-2.25901370225579E-06"
        ixz="8.2344088024564E-07"
        iyy="0.00137829761902421"
        iyz="-5.71796469378348E-13"
        izz="0.00159533562608115" />
    </inertial>
    <visual>
      <origin
        xyz="0 0 0"
        rpy="0 0 0" />
      <geometry>
        <mesh
          filename="package://Roly_with_arm9/meshes/L_hip_yaw.STL" />
      </geometry>
      <material
        name="">
        <color
          rgba="0.752941176470588 0.752941176470588 0.752941176470588 1" />
      </material>
    </visual>
    <collision>
      <origin
        xyz="0 0 0"
        rpy="0 0 0" />
      <geometry>
        <mesh
          filename="package://Roly_with_arm9/meshes/L_hip_yaw.STL" />
      </geometry>
    </collision>
  </link>
  <joint
    name="L_hip_yaw"
    type="continuous">
    <origin
      xyz="0 0.13 0"
      rpy="0 0 0" />
    <parent
      link="base_link" />
    <child
      link="L_hip_yaw" />
    <axis
      xyz="0 0 1" />
  </joint>
  <link
    name="L_hip_roll">
    <inertial>
      <origin
        xyz="-0.0014560680427817 -4.43152022022719E-09 -0.000573641853623311"
        rpy="0 0 0" />
      <mass
        value="1.33737606179077" />
      <inertia
        ixx="0.000590105330412749"
        ixy="-1.60440311084914E-11"
        ixz="3.4667693990553E-13"
        iyy="0.00200020910826934"
        iyz="-2.16495656956366E-16"
        izz="0.00190217341882605" />
    </inertial>
    <visual>
      <origin
        xyz="0 0 0"
        rpy="0 0 0" />
      <geometry>
        <mesh
          filename="package://Roly_with_arm9/meshes/L_hip_roll.STL" />
      </geometry>
      <material
        name="">
        <color
          rgba="0.752941176470588 0.752941176470588 0.752941176470588 1" />
      </material>
    </visual>
    <collision>
      <origin
        xyz="0 0 0"
        rpy="0 0 0" />
      <geometry>
        <mesh
          filename="package://Roly_with_arm9/meshes/L_hip_roll.STL" />
      </geometry>
    </collision>
  </link>
  <joint
    name="L_hip_roll"
    type="continuous">
    <origin
      xyz="0 0 -0.100499999999984"
      rpy="1.5707963267949 0 1.5707963267949" />
    <parent
      link="L_hip_yaw" />
    <child
      link="L_hip_roll" />
    <axis
      xyz="0 0 1" />
  </joint>
  <link
    name="L_hip_pitch">
    <inertial>
      <origin
        xyz="-0.14991135697416 0.00102058562119372 -0.00137091856747854"
        rpy="0 0 0" />
      <mass
        value="2.59034581862293" />
      <inertia
        ixx="0.0036815218953809"
        ixy="2.60027571776146E-05"
        ixz="2.3282057392949E-08"
        iyy="0.00509733345831479"
        iyz="2.00559932947276E-06"
        izz="0.00565081393341751" />
    </inertial>
    <visual>
      <origin
        xyz="0 0 0"
        rpy="0 0 0" />
      <geometry>
        <mesh
          filename="package://Roly_with_arm9/meshes/L_hip_pitch.STL" />
      </geometry>
      <material
        name="">
        <color
          rgba="0.752941176470588 0.752941176470588 0.752941176470588 1" />
      </material>
    </visual>
    <collision>
      <origin
        xyz="0 0 0"
        rpy="0 0 0" />
      <geometry>
        <mesh
          filename="package://Roly_with_arm9/meshes/L_hip_pitch.STL" />
      </geometry>
    </collision>
  </link>
  <joint
    name="L_hip_pitch"
    type="continuous">
    <origin
      xyz="0 0 0"
      rpy="1.5707963267949 0 1.5707963267949" />
    <parent
      link="L_hip_roll" />
    <child
      link="L_hip_pitch" />
    <axis
      xyz="0 0 1" />
  </joint>
  <link
    name="L_calf">
    <inertial>
      <origin
        xyz="-0.115426382792599 -0.000677771088297709 0.0105015841300469"
        rpy="0 0 0" />
      <mass
        value="1.87198703722554" />
      <inertia
        ixx="0.00121957366335642"
        ixy="1.75898619777057E-05"
        ixz="1.72520219163734E-06"
        iyy="0.00442397879163605"
        iyz="-4.63709721302372E-08"
        izz="0.00516127669761379" />
    </inertial>
    <visual>
      <origin
        xyz="0 0 0"
        rpy="0 0 0" />
      <geometry>
        <mesh
          filename="package://Roly_with_arm9/meshes/L_calf.STL" />
      </geometry>
      <material
        name="">
        <color
          rgba="0.752941176470588 0.752941176470588 0.752941176470588 1" />
      </material>
    </visual>
    <collision>
      <origin
        xyz="0 0 0"
        rpy="0 0 0" />
      <geometry>
        <mesh
          filename="package://Roly_with_arm9/meshes/L_calf.STL" />
      </geometry>
    </collision>
  </link>
  <joint
    name="L_calf"
    type="continuous">
    <origin
      xyz="-0.31 0 0"
      rpy="0 0 0" />
    <parent
      link="L_hip_pitch" />
    <child
      link="L_calf" />
    <axis
      xyz="0 0 1" />
  </joint>
  <link
    name="L_ankle_pitch">
    <inertial>
      <origin
        xyz="-0.0459602036001867 0.0196317255822612 5.49194716694401E-05"
        rpy="0 0 0" />
      <mass
        value="0.990577841443613" />
      <inertia
        ixx="0.00101039570726068"
        ixy="1.54676260903529E-05"
        ixz="-9.68287419015026E-13"
        iyy="0.000487571656182"
        iyz="5.95500778085383E-14"
        izz="0.00115084495203271" />
    </inertial>
    <visual>
      <origin
        xyz="0 0 0"
        rpy="0 0 0" />
      <geometry>
        <mesh
          filename="package://Roly_with_arm9/meshes/L_ankle_pitch.STL" />
      </geometry>
      <material
        name="">
        <color
          rgba="0.752941176470588 0.752941176470588 0.752941176470588 1" />
      </material>
    </visual>
    <collision>
      <origin
        xyz="0 0 0"
        rpy="0 0 0" />
      <geometry>
        <mesh
          filename="package://Roly_with_arm9/meshes/L_ankle_pitch.STL" />
      </geometry>
    </collision>
  </link>
  <joint
    name="L_ankle_pitch"
    type="continuous">
    <origin
      xyz="-0.26 0 0"
      rpy="0 0 0" />
    <parent
      link="L_calf" />
    <child
      link="L_ankle_pitch" />
    <axis
      xyz="0 0 1" />
  </joint>
  <link
    name="L_ankle_roll">
    <inertial>
      <origin
        xyz="-0.0685998049350528 2.19569085135873E-11 0.019999999988339"
        rpy="0 0 0" />
      <mass
        value="1.80750858879406" />
      <inertia
        ixx="0.00356060489977588"
        ixy="5.08107038639974E-14"
        ixz="7.01373890416774E-14"
        iyy="0.00313608673879828"
        iyz="-3.22423606020187E-13"
        izz="0.000582664567478918" />
    </inertial>
    <visual>
      <origin
        xyz="0 0 0"
        rpy="0 0 0" />
      <geometry>
        <mesh
          filename="package://Roly_with_arm9/meshes/L_ankle_roll.STL" />
      </geometry>
      <material
        name="">
        <color
          rgba="0.752941176470588 0.752941176470588 0.752941176470588 1" />
      </material>
    </visual>
    <collision>
      <origin
        xyz="0 0 0"
        rpy="0 0 0" />
      <geometry>
        <mesh
          filename="package://Roly_with_arm9/meshes/L_ankle_roll.STL" />
      </geometry>
    </collision>
  </link>
  <joint
    name="L_ankle_roll"
    type="continuous">
    <origin
      xyz="-0.05 0 0"
      rpy="-1.5707963267949 0 0" />
    <parent
      link="L_ankle_pitch" />
    <child
      link="L_ankle_roll" />
    <axis
      xyz="0 0 1" />
  </joint>
  <link
    name="L_knee_rocker">
    <inertial>
      <origin
        xyz="-0.00719496593564212 -0.00261875345160752 0.0168740723753153"
        rpy="0 0 0" />
      <mass
        value="0.147234181769685" />
      <inertia
        ixx="3.23048234923004E-05"
        ixy="-1.42989160208298E-05"
        ixz="6.0777930739413E-06"
        iyy="6.63863927138299E-05"
        iyz="2.21213577825894E-06"
        izz="8.94281354141203E-05" />
    </inertial>
    <visual>
      <origin
        xyz="0 0 0"
        rpy="0 0 0" />
      <geometry>
        <mesh
          filename="package://Roly_with_arm9/meshes/L_knee_rocker.STL" />
      </geometry>
      <material
        name="">
        <color
          rgba="0.752941176470588 0.752941176470588 0.752941176470588 1" />
      </material>
    </visual>
    <collision>
      <origin
        xyz="0 0 0"
        rpy="0 0 0" />
      <geometry>
        <mesh
          filename="package://Roly_with_arm9/meshes/L_knee_rocker.STL" />
      </geometry>
    </collision>
  </link>
  <joint
    name="L_knee_rocker"
    type="continuous">
    <origin
      xyz="-0.16 0 0.0344999999999996"
      rpy="0 0 0" />
    <parent
      link="L_hip_pitch" />
    <child
      link="L_knee_rocker" />
    <axis
      xyz="0 0 1" />
  </joint>
  <link
    name="L_knee_linkage">
    <inertial>
      <origin
        xyz="-0.0731902184314766 0.0266387984841421 -5.56277246488435E-13"
        rpy="0 0 0" />
      <mass
        value="0.110281845782561" />
      <inertia
        ixx="1.16107281437516E-05"
        ixy="2.38947586603736E-05"
        ixz="2.06937495737682E-13"
        iyy="6.85640571092591E-05"
        iyz="5.72483231869122E-13"
        izz="7.74131693353272E-05" />
    </inertial>
    <visual>
      <origin
        xyz="0 0 0"
        rpy="0 0 0" />
      <geometry>
        <mesh
          filename="package://Roly_with_arm9/meshes/L_knee_linkage.STL" />
      </geometry>
      <material
        name="">
        <color
          rgba="0.752941176470588 0.752941176470588 0.752941176470588 1" />
      </material>
    </visual>
    <collision>
      <origin
        xyz="0 0 0"
        rpy="0 0 0" />
      <geometry>
        <mesh
          filename="package://Roly_with_arm9/meshes/L_knee_linkage.STL" />
      </geometry>
    </collision>
  </link>
  <joint
    name="L_knee_linkage"
    type="continuous">
    <origin
      xyz="-0.056381557247154 -0.0205212085995416 0.0215"
      rpy="0 0 0.349065850398892" />
    <parent
      link="L_knee_rocker" />
    <child
      link="L_knee_linkage" />
    <axis
      xyz="0 0 1" />
  </joint>
  <link
    name="trunk">
    <inertial>
      <origin
        xyz="-0.000201063217514159 -0.00171826428333875 0.342961658831092"
        rpy="0 0 0" />
      <mass
        value="3.71788318727001" />
      <inertia
        ixx="0.0423654539437729"
        ixy="6.10031795665218E-05"
        ixz="-3.51593926867052E-05"
        iyy="0.029680328833866"
        iyz="6.70641597387363E-05"
        izz="0.0132646479265729" />
    </inertial>
    <visual>
      <origin
        xyz="0 0 0"
        rpy="0 0 0" />
      <geometry>
        <mesh
          filename="package://Roly_with_arm9/meshes/trunk.STL" />
      </geometry>
      <material
        name="">
        <color
          rgba="0.752941176470588 0.752941176470588 0.752941176470588 1" />
      </material>
    </visual>
    <collision>
      <origin
        xyz="0 0 0"
        rpy="0 0 0" />
      <geometry>
        <mesh
          filename="package://Roly_with_arm9/meshes/trunk.STL" />
      </geometry>
    </collision>
  </link>
  <joint
    name="trunk"
    type="continuous">
    <origin
      xyz="0 0 0.024"
      rpy="0 0 0" />
    <parent
      link="base_link" />
    <child
      link="trunk" />
    <axis
      xyz="0 0 1" />
  </joint>
  <link
    name="neck">
    <inertial>
      <origin
        xyz="-0.0115357599839019 -2.74625618214149E-05 0.0768671640428236"
        rpy="0 0 0" />
      <mass
        value="0.0914632144860051" />
      <inertia
        ixx="1.51395450687921E-05"
        ixy="-3.28341386543845E-07"
        ixz="1.8649735304314E-09"
        iyy="2.11664309108574E-05"
        iyz="-1.37470597831684E-09"
        izz="2.60473648306636E-05" />
    </inertial>
    <visual>
      <origin
        xyz="0 0 0"
        rpy="0 0 0" />
      <geometry>
        <mesh
          filename="package://Roly_with_arm9/meshes/neck.STL" />
      </geometry>
      <material
        name="">
        <color
          rgba="0.752941176470588 0.752941176470588 0.752941176470588 1" />
      </material>
    </visual>
    <collision>
      <origin
        xyz="0 0 0"
        rpy="0 0 0" />
      <geometry>
        <mesh
          filename="package://Roly_with_arm9/meshes/neck.STL" />
      </geometry>
    </collision>
  </link>
  <joint
    name="neck"
    type="continuous">
    <origin
      xyz="0.0235999999999944 0 0.525000000000011"
      rpy="0 0 0" />
    <parent
      link="trunk" />
    <child
      link="neck" />
    <axis
      xyz="0 0 1" />
  </joint>
  <link
    name="camera">
    <inertial>
      <origin
        xyz="0.00772982904240837 0.0510549004810608 -0.00119370076781037"
        rpy="0 0 0" />
      <mass
        value="0.0742659104108594" />
      <inertia
        ixx="4.43809962693199E-05"
        ixy="9.45230465593593E-08"
        ixz="4.47251572731327E-07"
        iyy="3.98516350286536E-05"
        iyz="2.19915507872119E-08"
        izz="1.53318606905173E-05" />
    </inertial>
    <visual>
      <origin
        xyz="0 0 0"
        rpy="0 0 0" />
      <geometry>
        <mesh
          filename="package://Roly_with_arm9/meshes/camera.STL" />
      </geometry>
      <material
        name="">
        <color
          rgba="0.752941176470588 0.752941176470588 0.752941176470588 1" />
      </material>
    </visual>
    <collision>
      <origin
        xyz="0 0 0"
        rpy="0 0 0" />
      <geometry>
        <mesh
          filename="package://Roly_with_arm9/meshes/camera.STL" />
      </geometry>
    </collision>
  </link>
  <joint
    name="camera"
    type="continuous">
    <origin
      xyz="0 0 0.0799000000000032"
      rpy="1.5707963267949 0 0" />
    <parent
      link="neck" />
    <child
      link="camera" />
    <axis
      xyz="0 0 1" />
  </joint>
  <link
    name="R_shoulder">
    <inertial>
      <origin
        xyz="-4.78828931241279E-05 0.0156539518070288 0.248211898616546"
        rpy="0 0 0" />
      <mass
        value="0.159233792908747" />
      <inertia
        ixx="5.90635379080723E-05"
        ixy="6.76340148769902E-07"
        ixz="3.93669860263498E-09"
        iyy="4.06885503332513E-05"
        iyz="-6.05489800766165E-09"
        izz="7.36582148170002E-05" />
    </inertial>
    <visual>
      <origin
        xyz="0 0 0"
        rpy="0 0 0" />
      <geometry>
        <mesh
          filename="package://Roly_with_arm9/meshes/R_shoulder.STL" />
      </geometry>
      <material
        name="">
        <color
          rgba="0.752941176470588 0.752941176470588 0.752941176470588 1" />
      </material>
    </visual>
    <collision>
      <origin
        xyz="0 0 0"
        rpy="0 0 0" />
      <geometry>
        <mesh
          filename="package://Roly_with_arm9/meshes/R_shoulder.STL" />
      </geometry>
    </collision>
  </link>
  <joint
    name="R_shoulder"
    type="continuous">
    <origin
      xyz="0 0 0.495000000000016"
      rpy="1.5707963267949 0 0" />
    <parent
      link="trunk" />
    <child
      link="R_shoulder" />
    <axis
      xyz="0 0 1" />
  </joint>
  <link
    name="R_arm1">
    <inertial>
      <origin
        xyz="-0.0833488305230862 1.97169402734731E-05 -7.82530764841632E-06"
        rpy="0 0 0" />
      <mass
        value="0.185807988030177" />
      <inertia
        ixx="5.49966092882242E-05"
        ixy="1.24338572306125E-08"
        ixz="6.76337657036315E-07"
        iyy="8.8000822987359E-05"
        iyz="3.93877607820437E-09"
        izz="6.51364712534081E-05" />
    </inertial>
    <visual>
      <origin
        xyz="0 0 0"
        rpy="0 0 0" />
      <geometry>
        <mesh
          filename="package://Roly_with_arm9/meshes/R_arm1.STL" />
      </geometry>
      <material
        name="">
        <color
          rgba="0.752941176470588 0.752941176470588 0.752941176470588 1" />
      </material>
    </visual>
    <collision>
      <origin
        xyz="0 0 0"
        rpy="0 0 0" />
      <geometry>
        <mesh
          filename="package://Roly_with_arm9/meshes/R_arm1.STL" />
      </geometry>
    </collision>
  </link>
  <joint
    name="R_arm1"
    type="continuous">
    <origin
      xyz="0 0 0.248799999999999"
      rpy="1.57079632679491 0 1.57079632679437" />
    <parent
      link="R_shoulder" />
    <child
      link="R_arm1" />
    <axis
      xyz="0 0 1" />
  </joint>
  <link
    name="R_arm2">
    <inertial>
      <origin
        xyz="-0.0563000259065848 1.74831241261941E-07 -0.00680843482052774"
        rpy="0 0 0" />
      <mass
        value="0.0726996420803591" />
      <inertia
        ixx="2.47802098371494E-05"
        ixy="2.31836798433191E-11"
        ixz="1.7893214541659E-07"
        iyy="2.6966904229404E-05"
        iyz="2.41655414356696E-11"
        izz="1.38415312507139E-05" />
    </inertial>
    <visual>
      <origin
        xyz="0 0 0"
        rpy="0 0 0" />
      <geometry>
        <mesh
          filename="package://Roly_with_arm9/meshes/R_arm2.STL" />
      </geometry>
      <material
        name="">
        <color
          rgba="0.752941176470588 0.752941176470588 0.752941176470588 1" />
      </material>
    </visual>
    <collision>
      <origin
        xyz="0 0 0"
        rpy="0 0 0" />
      <geometry>
        <mesh
          filename="package://Roly_with_arm9/meshes/R_arm2.STL" />
      </geometry>
    </collision>
  </link>
  <joint
    name="R_arm2"
    type="continuous">
    <origin
      xyz="-0.110500000000012 0 0"
      rpy="0 0 0" />
    <parent
      link="R_arm1" />
    <child
      link="R_arm2" />
    <axis
      xyz="0 0 1" />
  </joint>
  <link
    name="R_arm3">
    <inertial>
      <origin
        xyz="-3.22977636016963E-05 -0.0109601967295957 -0.118522042268513"
        rpy="0 0 0" />
      <mass
        value="0.0455132201726528" />
      <inertia
        ixx="1.04441289107308E-05"
        ixy="-1.81664610902479E-07"
        ixz="-4.30037887951275E-13"
        iyy="7.72819086244754E-06"
        iyz="-2.28508016822014E-09"
        izz="1.25281962284949E-05" />
    </inertial>
    <visual>
      <origin
        xyz="0 0 0"
        rpy="0 0 0" />
      <geometry>
        <mesh
          filename="package://Roly_with_arm9/meshes/R_arm3.STL" />
      </geometry>
      <material
        name="">
        <color
          rgba="0.752941176470588 0.752941176470588 0.752941176470588 1" />
      </material>
    </visual>
    <collision>
      <origin
        xyz="0 0 0"
        rpy="0 0 0" />
      <geometry>
        <mesh
          filename="package://Roly_with_arm9/meshes/R_arm3.STL" />
      </geometry>
    </collision>
  </link>
  <joint
    name="R_arm3"
    type="continuous">
    <origin
      xyz="0 0 0"
      rpy="1.5707963267949 0 1.57079632679489" />
    <parent
      link="R_arm2" />
    <child
      link="R_arm3" />
    <axis
      xyz="0 0 1" />
  </joint>
  <link
    name="R_arm4">
    <inertial>
      <origin
        xyz="-0.0101576588872286 -0.0474946152588541 9.2793164247984E-05"
        rpy="0 0 0" />
      <mass
        value="0.0493363034804284" />
      <inertia
        ixx="9.03991587155392E-06"
        ixy="1.78932574784435E-07"
        ixz="2.41603387565879E-11"
        iyy="1.18657637430999E-05"
        iyz="-1.47190672719737E-11"
        izz="1.28686059122131E-05" />
    </inertial>
    <visual>
      <origin
        xyz="0 0 0"
        rpy="0 0 0" />
      <geometry>
        <mesh
          filename="package://Roly_with_arm9/meshes/R_arm4.STL" />
      </geometry>
      <material
        name="">
        <color
          rgba="0.752941176470588 0.752941176470588 0.752941176470588 1" />
      </material>
    </visual>
    <collision>
      <origin
        xyz="0 0 0"
        rpy="0 0 0" />
      <geometry>
        <mesh
          filename="package://Roly_with_arm9/meshes/R_arm4.STL" />
      </geometry>
    </collision>
  </link>
  <joint
    name="R_arm4"
    type="continuous">
    <origin
      xyz="0 0 -0.119500000000016"
      rpy="1.5707963267949 0 1.57079632679489" />
    <parent
      link="R_arm3" />
    <child
      link="R_arm4" />
    <axis
      xyz="0 0 1" />
  </joint>
  <link
    name="R_palm">
    <inertial>
      <origin
        xyz="-0.0114428183839519 0.0235779900939111 0.122371139811163"
        rpy="0 0 0" />
      <mass
        value="0.113421990500795" />
      <inertia
        ixx="1.37703657304056E-05"
        ixy="-2.42636885993604E-07"
        ixz="1.94932161501945E-07"
        iyy="4.21508439476097E-05"
        iyz="-2.41360510431156E-07"
        izz="4.19221725069787E-05" />
    </inertial>
    <visual>
      <origin
        xyz="0 0 0"
        rpy="0 0 0" />
      <geometry>
        <mesh
          filename="package://Roly_with_arm9/meshes/R_palm.STL" />
      </geometry>
      <material
        name="">
        <color
          rgba="0.752941176470588 0.752941176470588 0.752941176470588 1" />
      </material>
    </visual>
    <collision>
      <origin
        xyz="0 0 0"
        rpy="0 0 0" />
      <geometry>
        <mesh
          filename="package://Roly_with_arm9/meshes/R_palm.STL" />
      </geometry>
    </collision>
  </link>
  <joint
    name="R_palm"
    type="continuous">
    <origin
      xyz="0 0 0"
      rpy="1.5707963267949 0 0" />
    <parent
      link="R_arm4" />
    <child
      link="R_palm" />
    <axis
      xyz="0 0 1" />
  </joint>
  <link
    name="R finger1-1">
    <inertial>
      <origin
        xyz="2.56739074444567E-15 -0.00649999999997194 -1.41553435639707E-15"
        rpy="0 0 0" />
      <mass
        value="0.00079787614034051" />
      <inertia
        ixx="4.49656063445361E-08"
        ixy="3.12984464274752E-22"
        ixz="-7.77308893676082E-22"
        iyy="1.38553394151494E-08"
        iyz="-2.90161055913503E-21"
        izz="5.66932760521109E-08" />
    </inertial>
    <visual>
      <origin
        xyz="0 0 0"
        rpy="0 0 0" />
      <geometry>
        <mesh
          filename="package://Roly_with_arm9/meshes/R finger1-1.STL" />
      </geometry>
      <material
        name="">
        <color
          rgba="0.752941176470588 0.752941176470588 0.752941176470588 1" />
      </material>
    </visual>
    <collision>
      <origin
        xyz="0 0 0"
        rpy="0 0 0" />
      <geometry>
        <mesh
          filename="package://Roly_with_arm9/meshes/R finger1-1.STL" />
      </geometry>
    </collision>
  </link>
  <joint
    name="R finger1-1"
    type="continuous">
    <origin
      xyz="-0.0349999999999997 0 0.140000000000012"
      rpy="-1.57079632679497 0.041179896289441 3.14159265358972" />
    <parent
      link="R_palm" />
    <child
      link="R finger1-1" />
    <axis
      xyz="0 0 1" />
  </joint>
  <link
    name="R finger1-2">
    <inertial>
      <origin
        xyz="0.00521420691933251 0.0205031747921958 -5.55111512312578E-16"
        rpy="0 0 0" />
      <mass
        value="0.0043788782820395" />
      <inertia
        ixx="5.71767324048311E-07"
        ixy="1.15303368140794E-07"
        ixz="-1.34889717002517E-23"
        iyy="2.7709601634118E-07"
        iyz="1.81126761638131E-23"
        izz="7.69938222163977E-07" />
    </inertial>
    <visual>
      <origin
        xyz="0 0 0"
        rpy="0 0 0" />
      <geometry>
        <mesh
          filename="package://Roly_with_arm9/meshes/R finger1-2.STL" />
      </geometry>
      <material
        name="">
        <color
          rgba="0.752941176470588 0.752941176470588 0.752941176470588 1" />
      </material>
    </visual>
    <collision>
      <origin
        xyz="0 0 0"
        rpy="0 0 0" />
      <geometry>
        <mesh
          filename="package://Roly_with_arm9/meshes/R finger1-2.STL" />
      </geometry>
    </collision>
  </link>
  <joint
    name="R finger1-2"
    type="continuous">
    <origin
      xyz="-0.000535187361472816 -0.0129889789624728 0"
      rpy="0 0 2.59424846425085" />
    <parent
      link="R finger1-1" />
    <child
      link="R finger1-2" />
    <axis
      xyz="0 0 1" />
  </joint>
  <link
    name="R finger2-1">
    <inertial>
      <origin
        xyz="4.82947015711943E-15 -0.00650000000000353 0.000500000000001305"
        rpy="0 0 0" />
      <mass
        value="0.00079787614034051" />
      <inertia
        ixx="4.49656063445361E-08"
        ixy="4.74506988512216E-21"
        ixz="4.53129539556549E-21"
        iyy="1.38553394151495E-08"
        iyz="1.65460937928982E-20"
        izz="5.66932760521108E-08" />
    </inertial>
    <visual>
      <origin
        xyz="0 0 0"
        rpy="0 0 0" />
      <geometry>
        <mesh
          filename="package://Roly_with_arm9/meshes/R finger2-1.STL" />
      </geometry>
      <material
        name="">
        <color
          rgba="0.752941176470588 0.752941176470588 0.752941176470588 1" />
      </material>
    </visual>
    <collision>
      <origin
        xyz="0 0 0"
        rpy="0 0 0" />
      <geometry>
        <mesh
          filename="package://Roly_with_arm9/meshes/R finger2-1.STL" />
      </geometry>
    </collision>
  </link>
  <joint
    name="R finger2-1"
    type="continuous">
    <origin
      xyz="0.0303108891324581 0.0174999999999999 0.139999999999979"
      rpy="-1.57079632679453 -0.0411798962895708 -2.61799387799112" />
    <parent
      link="R_palm" />
    <child
      link="R finger2-1" />
    <axis
      xyz="0 0 1" />
    <mimic
      joint=""
      multiplier="1"
      offset="0" />
  </joint>
  <link
    name="R finger2-2">
    <inertial>
      <origin
        xyz="0.00567694416579953 0.0207722866943773 3.91353616180368E-15"
        rpy="0 0 0" />
      <mass
        value="0.00437887828203949" />
      <inertia
        ixx="5.7176732404831E-07"
        ixy="1.15303368140795E-07"
        ixz="2.11758236813575E-22"
        iyy="2.7709601634118E-07"
        iyz="-7.14684049245816E-22"
        izz="7.69938222163976E-07" />
    </inertial>
    <visual>
      <origin
        xyz="0 0 0"
        rpy="0 0 0" />
      <geometry>
        <mesh
          filename="package://Roly_with_arm9/meshes/R finger2-2.STL" />
      </geometry>
      <material
        name="">
        <color
          rgba="0.752941176470588 0.752941176470588 0.752941176470588 1" />
      </material>
    </visual>
    <collision>
      <origin
        xyz="0 0 0"
        rpy="0 0 0" />
      <geometry>
        <mesh
          filename="package://Roly_with_arm9/meshes/R finger2-2.STL" />
      </geometry>
    </collision>
  </link>
  <joint
    name="R finger2-2"
    type="continuous">
    <origin
      xyz="0 -0.0130000000000269 0"
      rpy="3.14159265358966 0 0.547344189339083" />
    <parent
      link="R finger2-1" />
    <child
      link="R finger2-2" />
    <axis
      xyz="0 0 1" />
    <mimic
      joint=""
      multiplier="1"
      offset="0" />
  </joint>
  <link
    name="R finger3-1">
    <inertial>
      <origin
        xyz="-0.006500000000036 2.4008572907519E-15 0.000500000000003803"
        rpy="0 0 0" />
      <mass
        value="0.000797876140340505" />
      <inertia
        ixx="1.38553394151494E-08"
        ixy="7.96130320309318E-21"
        ixz="2.16123165508441E-20"
        iyy="4.49656063445356E-08"
        iyz="4.96308367531817E-23"
        izz="5.66932760521103E-08" />
    </inertial>
    <visual>
      <origin
        xyz="0 0 0"
        rpy="0 0 0" />
      <geometry>
        <mesh
          filename="package://Roly_with_arm9/meshes/R finger3-1.STL" />
      </geometry>
      <material
        name="">
        <color
          rgba="0.752941176470588 0.752941176470588 0.752941176470588 1" />
      </material>
    </visual>
    <collision>
      <origin
        xyz="0 0 0"
        rpy="0 0 0" />
      <geometry>
        <mesh
          filename="package://Roly_with_arm9/meshes/R finger3-1.STL" />
      </geometry>
    </collision>
  </link>
  <joint
    name="R finger3-1"
    type="continuous">
    <origin
      xyz="0.0303108891324533 -0.0175000000000002 0.139999999999947"
      rpy="1.57079632678266 1.52961643050521 2.61799387797924" />
    <parent
      link="R_palm" />
    <child
      link="R finger3-1" />
    <axis
      xyz="0 0 1" />
    <mimic
      joint=""
      multiplier="1"
      offset="0" />
  </joint>
  <link
    name="R finger3-2">
    <inertial>
      <origin
        xyz="0.00567694416578834 0.0207722866943779 -6.32827124036339E-15"
        rpy="0 0 0" />
      <mass
        value="0.00437887828203949" />
      <inertia
        ixx="5.71767324048309E-07"
        ixy="1.15303368140795E-07"
        ixz="2.64697796016969E-23"
        iyy="2.7709601634118E-07"
        iyz="1.32348898008484E-22"
        izz="7.69938222163975E-07" />
    </inertial>
    <visual>
      <origin
        xyz="0 0 0"
        rpy="0 0 0" />
      <geometry>
        <mesh
          filename="package://Roly_with_arm9/meshes/R finger3-2.STL" />
      </geometry>
      <material
        name="">
        <color
          rgba="0.752941176470588 0.752941176470588 0.752941176470588 1" />
      </material>
    </visual>
    <collision>
      <origin
        xyz="0 0 0"
        rpy="0 0 0" />
      <geometry>
        <mesh
          filename="package://Roly_with_arm9/meshes/R finger3-2.STL" />
      </geometry>
    </collision>
  </link>
  <joint
    name="R finger3-2"
    type="continuous">
    <origin
      xyz="-0.0130000000000591 0 0"
      rpy="0 0 1.0234521374557" />
    <parent
      link="R finger3-1" />
    <child
      link="R finger3-2" />
    <axis
      xyz="0 0 1" />
    <mimic
      joint=""
      multiplier="1"
      offset="0" />
  </joint>
  <link
    name="R gripper">
    <inertial>
      <origin
        xyz="2.66453525910038E-15 0.00210478991921641 0.0049327210493951"
        rpy="0 0 0" />
      <mass
        value="0.00333908485238664" />
      <inertia
        ixx="4.77968396563339E-07"
        ixy="-2.01574058190995E-22"
        ixz="1.90694982634464E-24"
        iyy="1.44311250315152E-07"
        iyz="-4.72841318102333E-10"
        izz="5.61430850945776E-07" />
    </inertial>
    <visual>
      <origin
        xyz="0 0 0"
        rpy="0 0 0" />
      <geometry>
        <mesh
          filename="package://Roly_with_arm9/meshes/R gripper.STL" />
      </geometry>
      <material
        name="">
        <color
          rgba="0.792156862745098 0.819607843137255 0.933333333333333 1" />
      </material>
    </visual>
    <collision>
      <origin
        xyz="0 0 0"
        rpy="0 0 0" />
      <geometry>
        <mesh
          filename="package://Roly_with_arm9/meshes/R gripper.STL" />
      </geometry>
    </collision>
  </link>
  <joint
    name="R gripper"
    type="prismatic">
    <origin
      xyz="0 0 0.14031"
      rpy="0 0 -1.5708" />
    <parent
      link="R_palm" />
    <child
      link="R gripper" />
    <axis
      xyz="0 0 1" />
    <limit
      lower="0"
      upper="0.03"
      effort="0"
      velocity="0" />
  </joint>
  <link
    name="L_shoulder">
    <inertial>
      <origin
        xyz="-4.78827689021427E-05 0.0156539518070264 -0.248204682969383"
        rpy="0 0 0" />
      <mass
        value="0.159233792908747" />
      <inertia
        ixx="5.9063537908072E-05"
        ixy="6.76336036224655E-07"
        ixz="3.93669860266452E-09"
        iyy="4.06885503332511E-05"
        iyz="1.24343094959052E-08"
        izz="7.36582148169998E-05" />
    </inertial>
    <visual>
      <origin
        xyz="0 0 0"
        rpy="0 0 0" />
      <geometry>
        <mesh
          filename="package://Roly_with_arm9/meshes/L_shoulder.STL" />
      </geometry>
      <material
        name="">
        <color
          rgba="0.752941176470588 0.752941176470588 0.752941176470588 1" />
      </material>
    </visual>
    <collision>
      <origin
        xyz="0 0 0"
        rpy="0 0 0" />
      <geometry>
        <mesh
          filename="package://Roly_with_arm9/meshes/L_shoulder.STL" />
      </geometry>
    </collision>
  </link>
  <joint
    name="L_shoulder"
    type="continuous">
    <origin
      xyz="0 0 0.495000000000016"
      rpy="1.5707963267949 0 0" />
    <parent
      link="trunk" />
    <child
      link="L_shoulder" />
    <axis
      xyz="0 0 1" />
  </joint>
  <link
    name="L_arm1">
    <inertial>
      <origin
        xyz="-0.083348830513028 -1.3533276562061E-05 -7.82520297017194E-06"
        rpy="0 0 0" />
      <mass
        value="0.185807988101709" />
      <inertia
        ixx="5.49966092887569E-05"
        ixy="-6.05444467762914E-09"
        ixz="6.76337620782107E-07"
        iyy="8.80008229865708E-05"
        iyz="3.9387732585062E-09"
        izz="6.51364712551087E-05" />
    </inertial>
    <visual>
      <origin
        xyz="0 0 0"
        rpy="0 0 0" />
      <geometry>
        <mesh
          filename="package://Roly_with_arm9/meshes/L_arm1.STL" />
      </geometry>
      <material
        name="">
        <color
          rgba="0.752941176470588 0.752941176470588 0.752941176470588 1" />
      </material>
    </visual>
    <collision>
      <origin
        xyz="0 0 0"
        rpy="0 0 0" />
      <geometry>
        <mesh
          filename="package://Roly_with_arm9/meshes/L_arm1.STL" />
      </geometry>
    </collision>
  </link>
  <joint
    name="L_arm1"
    type="continuous">
    <origin
      xyz="0 0 -0.248800000000004"
      rpy="1.5707963267949 0 1.57079632679437" />
    <parent
      link="L_shoulder" />
    <child
      link="L_arm1" />
    <axis
      xyz="0 0 1" />
  </joint>
  <link
    name="L_arm2">
    <inertial>
      <origin
        xyz="-0.056300025896196 1.74828550247863E-07 -0.00680843479089758"
        rpy="0 0 0" />
      <mass
        value="0.072699641994854" />
      <inertia
        ixx="2.47802098012189E-05"
        ixy="2.31861399386526E-11"
        ixz="1.78932123459108E-07"
        iyy="2.69669041799343E-05"
        iyz="2.41603170588996E-11"
        izz="1.38415312388202E-05" />
    </inertial>
    <visual>
      <origin
        xyz="0 0 0"
        rpy="0 0 0" />
      <geometry>
        <mesh
          filename="package://Roly_with_arm9/meshes/L_arm2.STL" />
      </geometry>
      <material
        name="">
        <color
          rgba="0.752941176470588 0.752941176470588 0.752941176470588 1" />
      </material>
    </visual>
    <collision>
      <origin
        xyz="0 0 0"
        rpy="0 0 0" />
      <geometry>
        <mesh
          filename="package://Roly_with_arm9/meshes/L_arm2.STL" />
      </geometry>
    </collision>
  </link>
  <joint
    name="L_arm2"
    type="continuous">
    <origin
      xyz="-0.110499999999998 0 0"
      rpy="0 0 0" />
    <parent
      link="L_arm1" />
    <child
      link="L_arm2" />
    <axis
      xyz="0 0 1" />
  </joint>
  <link
    name="L_arm3">
    <inertial>
      <origin
        xyz="3.22976009903553E-05 -0.0109601967276191 -0.118522040871978"
        rpy="0 0 0" />
      <mass
        value="0.0455132201923672" />
      <inertia
        ixx="1.04441289103271E-05"
        ixy="1.81663053282859E-07"
        ixz="-4.34735321187876E-13"
        iyy="7.72819087118311E-06"
        iyz="-2.28574636652887E-09"
        izz="1.25281962251373E-05" />
    </inertial>
    <visual>
      <origin
        xyz="0 0 0"
        rpy="0 0 0" />
      <geometry>
        <mesh
          filename="package://Roly_with_arm9/meshes/L_arm3.STL" />
      </geometry>
      <material
        name="">
        <color
          rgba="0.752941176470588 0.752941176470588 0.752941176470588 1" />
      </material>
    </visual>
    <collision>
      <origin
        xyz="0 0 0"
        rpy="0 0 0" />
      <geometry>
        <mesh
          filename="package://Roly_with_arm9/meshes/L_arm3.STL" />
      </geometry>
    </collision>
  </link>
  <joint
    name="L_arm3"
    type="continuous">
    <origin
      xyz="0 0 0"
      rpy="1.5707963267949 0 1.5707963267949" />
    <parent
      link="L_arm2" />
    <child
      link="L_arm3" />
    <axis
      xyz="0 0 1" />
  </joint>
  <link
    name="L_arm4">
    <inertial>
      <origin
        xyz="-0.0101576589255851 -0.047494615245239 -9.22779220292325E-05"
        rpy="0 0 0" />
      <mass
        value="0.0493363035659337" />
      <inertia
        ixx="9.03991588344768E-06"
        ixy="1.78932600746644E-07"
        ixz="2.41655629372729E-11"
        iyy="1.18657637790304E-05"
        iyz="6.10889067927785E-11"
        izz="1.28686059616828E-05" />
    </inertial>
    <visual>
      <origin
        xyz="0 0 0"
        rpy="0 0 0" />
      <geometry>
        <mesh
          filename="package://Roly_with_arm9/meshes/L_arm4.STL" />
      </geometry>
      <material
        name="">
        <color
          rgba="0.752941176470588 0.752941176470588 0.752941176470588 1" />
      </material>
    </visual>
    <collision>
      <origin
        xyz="0 0 0"
        rpy="0 0 0" />
      <geometry>
        <mesh
          filename="package://Roly_with_arm9/meshes/L_arm4.STL" />
      </geometry>
    </collision>
  </link>
  <joint
    name="L_arm4"
    type="continuous">
    <origin
      xyz="0 0 -0.119500000000027"
      rpy="1.5707963267949 0 1.5707963267949" />
    <parent
      link="L_arm3" />
    <child
      link="L_arm4" />
    <axis
      xyz="0 0 1" />
  </joint>
  <link
    name="L_palm">
    <inertial>
      <origin
        xyz="-0.011443117131739 -0.0235777630739123 0.122371142598323"
        rpy="0 0 0" />
      <mass
        value="0.113421979638333" />
      <inertia
        ixx="1.37703635336256E-05"
        ixy="-2.42636872963092E-07"
        ixz="-5.57721636090102E-07"
        iyy="4.21508408298824E-05"
        iyz="2.41305446313844E-07"
        izz="4.19221710427468E-05" />
    </inertial>
    <visual>
      <origin
        xyz="0 0 0"
        rpy="0 0 0" />
      <geometry>
        <mesh
          filename="package://Roly_with_arm9/meshes/L_palm.STL" />
      </geometry>
      <material
        name="">
        <color
          rgba="0.752941176470588 0.752941176470588 0.752941176470588 1" />
      </material>
    </visual>
    <collision>
      <origin
        xyz="0 0 0"
        rpy="0 0 0" />
      <geometry>
        <mesh
          filename="package://Roly_with_arm9/meshes/L_palm.STL" />
      </geometry>
    </collision>
  </link>
  <joint
    name="L_palm"
    type="continuous">
    <origin
      xyz="0 0 0"
      rpy="1.5707963267949 0 0" />
    <parent
      link="L_arm4" />
    <child
      link="L_palm" />
    <axis
      xyz="0 0 1" />
  </joint>
  <link
    name="L finger1-1">
    <inertial>
      <origin
        xyz="-7.15399961492835E-15 -0.0065000000001188 8.88178419700125E-16"
        rpy="0 0 0" />
      <mass
        value="0.000797876140340506" />
      <inertia
        ixx="4.49656063445358E-08"
        ixy="-1.66700157884163E-20"
        ixz="2.02887708409072E-23"
        iyy="1.38553394151494E-08"
        iyz="1.52322101573017E-24"
        izz="5.66932760521105E-08" />
    </inertial>
    <visual>
      <origin
        xyz="0 0 0"
        rpy="0 0 0" />
      <geometry>
        <mesh
          filename="package://Roly_with_arm9/meshes/L finger1-1.STL" />
      </geometry>
      <material
        name="">
        <color
          rgba="0.752941176470588 0.752941176470588 0.752941176470588 1" />
      </material>
    </visual>
    <collision>
      <origin
        xyz="0 0 0"
        rpy="0 0 0" />
      <geometry>
        <mesh
          filename="package://Roly_with_arm9/meshes/L finger1-1.STL" />
      </geometry>
    </collision>
  </link>
  <joint
    name="L finger1-1"
    type="continuous">
    <origin
      xyz="-0.034999999999998 0 0.139999999999868"
      rpy="-1.5707963267949 0.0411798962899742 -3.14159265358979" />
    <parent
      link="L_palm" />
    <child
      link="L finger1-1" />
    <axis
      xyz="0 0 1" />
  </joint>
  <link
    name="L finger1-2">
    <inertial>
      <origin
        xyz="0.00521420691926289 0.0205031747923056 1.11022302462516E-15"
        rpy="0 0 0" />
      <mass
        value="0.0043788782820395" />
      <inertia
        ixx="5.71767324048312E-07"
        ixy="1.15303368140795E-07"
        ixz="2.41029179359833E-22"
        iyy="2.77096016341181E-07"
        iyz="-3.10713813960969E-22"
        izz="7.69938222163979E-07" />
    </inertial>
    <visual>
      <origin
        xyz="0 0 0"
        rpy="0 0 0" />
      <geometry>
        <mesh
          filename="package://Roly_with_arm9/meshes/L finger1-2.STL" />
      </geometry>
      <material
        name="">
        <color
          rgba="0.752941176470588 0.752941176470588 0.752941176470588 1" />
      </material>
    </visual>
    <collision>
      <origin
        xyz="0 0 0"
        rpy="0 0 0" />
      <geometry>
        <mesh
          filename="package://Roly_with_arm9/meshes/L finger1-2.STL" />
      </geometry>
    </collision>
  </link>
  <joint
    name="L finger1-2"
    type="continuous">
    <origin
      xyz="-0.000535187361494258 -0.0129889789624889 0"
      rpy="0 0 2.5942484642503" />
    <parent
      link="L finger1-1" />
    <child
      link="L finger1-2" />
    <axis
      xyz="0 0 1" />
  </joint>
  <link
    name="L finger2-1">
    <inertial>
      <origin
        xyz="5.91193760612896E-15 0.00650000000012796 0.000500000000000528"
        rpy="0 0 0" />
      <mass
        value="0.000797876140340504" />
      <inertia
        ixx="4.49656063445356E-08"
        ixy="-1.74916387812288E-20"
        ixz="-1.32348898008484E-23"
        iyy="1.38553394151493E-08"
        iyz="5.41027819397965E-23"
        izz="5.66932760521102E-08" />
    </inertial>
    <visual>
      <origin
        xyz="0 0 0"
        rpy="0 0 0" />
      <geometry>
        <mesh
          filename="package://Roly_with_arm9/meshes/L finger2-1.STL" />
      </geometry>
      <material
        name="">
        <color
          rgba="0.752941176470588 0.752941176470588 0.752941176470588 1" />
      </material>
    </visual>
    <collision>
      <origin
        xyz="0 0 0"
        rpy="0 0 0" />
      <geometry>
        <mesh
          filename="package://Roly_with_arm9/meshes/L finger2-1.STL" />
      </geometry>
    </collision>
  </link>
  <joint
    name="L finger2-1"
    type="continuous">
    <origin
      xyz="0.0303108891324555 -0.0174999999999983 0.139999999999857"
      rpy="1.5707963267949 -0.0411798962899958 2.6179938779915" />
    <parent
      link="L_palm" />
    <child
      link="L finger2-1" />
    <axis
      xyz="0 0 -1" />
  </joint>
  <link
    name="L finger2-2">
    <inertial>
      <origin
        xyz="0.00567694416578879 0.0207722866943877 0.00224999999999623"
        rpy="0 0 0" />
      <mass
        value="0.00437887828203949" />
      <inertia
        ixx="5.71767324048307E-07"
        ixy="1.15303368140794E-07"
        ixz="1.85288457211878E-22"
        iyy="2.77096016341179E-07"
        iyz="-2.91167575618666E-22"
        izz="7.69938222163973E-07" />
    </inertial>
    <visual>
      <origin
        xyz="0 0 0"
        rpy="0 0 0" />
      <geometry>
        <mesh
          filename="package://Roly_with_arm9/meshes/L finger2-2.STL" />
      </geometry>
      <material
        name="">
        <color
          rgba="0.752941176470588 0.752941176470588 0.752941176470588 1" />
      </material>
    </visual>
    <collision>
      <origin
        xyz="0 0 0"
        rpy="0 0 0" />
      <geometry>
        <mesh
          filename="package://Roly_with_arm9/meshes/L finger2-2.STL" />
      </geometry>
    </collision>
  </link>
  <joint
    name="L finger2-2"
    type="continuous">
    <origin
      xyz="0 0.0130000000001428 -0.00224999999999526"
      rpy="0 0 -0.547344189339513" />
    <parent
      link="L finger2-1" />
    <child
      link="L finger2-2" />
    <axis
      xyz="0 0 1" />
  </joint>
  <link
    name="L finger3-1">
    <inertial>
      <origin
        xyz="1.23928645123783E-14 -0.00650000000012901 0.000500000000000306"
        rpy="0 0 0" />
      <mass
        value="0.000797876140340505" />
      <inertia
        ixx="4.49656063445357E-08"
        ixy="1.76548001570548E-20"
        ixz="1.81979734761666E-23"
        iyy="1.38553394151494E-08"
        iyz="6.55799129389697E-23"
        izz="5.66932760521103E-08" />
    </inertial>
    <visual>
      <origin
        xyz="0 0 0"
        rpy="0 0 0" />
      <geometry>
        <mesh
          filename="package://Roly_with_arm9/meshes/L finger3-1.STL" />
      </geometry>
      <material
        name="">
        <color
          rgba="0.752941176470588 0.752941176470588 0.752941176470588 1" />
      </material>
    </visual>
    <collision>
      <origin
        xyz="0 0 0"
        rpy="0 0 0" />
      <geometry>
        <mesh
          filename="package://Roly_with_arm9/meshes/L finger3-1.STL" />
      </geometry>
    </collision>
  </link>
  <joint
    name="L finger3-1"
    type="continuous">
    <origin
      xyz="0.0303108891324596 0.017500000000001 0.139999999999857"
      rpy="-1.5707963267949 -0.0411798962899995 -2.6179938779915" />
    <parent
      link="L_palm" />
    <child
      link="L finger3-1" />
    <axis
      xyz="0 0 1" />
  </joint>
  <link
    name="L finger3-2">
    <inertial>
      <origin
        xyz="0.00567694416578804 0.0207722866943909 -4.16333634234434E-16"
        rpy="0 0 0" />
      <mass
        value="0.00437887828203949" />
      <inertia
        ixx="5.71767324048308E-07"
        ixy="1.15303368140795E-07"
        ixz="2.38228016415272E-22"
        iyy="2.77096016341179E-07"
        iyz="1.98523347012727E-22"
        izz="7.69938222163974E-07" />
    </inertial>
    <visual>
      <origin
        xyz="0 0 0"
        rpy="0 0 0" />
      <geometry>
        <mesh
          filename="package://Roly_with_arm9/meshes/L finger3-2.STL" />
      </geometry>
      <material
        name="">
        <color
          rgba="0.752941176470588 0.752941176470588 0.752941176470588 1" />
      </material>
    </visual>
    <collision>
      <origin
        xyz="0 0 0"
        rpy="0 0 0" />
      <geometry>
        <mesh
          filename="package://Roly_with_arm9/meshes/L finger3-2.STL" />
      </geometry>
    </collision>
  </link>
  <joint
    name="L finger3-2"
    type="continuous">
    <origin
      xyz="0 -0.0130000000001409 0"
      rpy="3.14159265358979 0 0.547344189339513" />
    <parent
      link="L finger3-1" />
    <child
      link="L finger3-2" />
    <axis
      xyz="0 0 1" />
  </joint>
  <link
    name="L gripper">
    <inertial>
      <origin
        xyz="3.63598040564739E-15 0.00210478991921784 0.00493272104945061"
        rpy="0 0 0" />
      <mass
        value="0.00333908485238664" />
      <inertia
        ixx="4.77968396563339E-07"
        ixy="-5.32986190889969E-23"
        ixz="3.7761018906207E-24"
        iyy="1.44311250315152E-07"
        iyz="-4.72841318102322E-10"
        izz="5.61430850945776E-07" />
    </inertial>
    <visual>
      <origin
        xyz="0 0 0"
        rpy="0 0 0" />
      <geometry>
        <mesh
          filename="package://Roly_with_arm9/meshes/L gripper.STL" />
      </geometry>
      <material
        name="">
        <color
          rgba="0.792156862745098 0.819607843137255 0.933333333333333 1" />
      </material>
    </visual>
    <collision>
      <origin
        xyz="0 0 0"
        rpy="0 0 0" />
      <geometry>
        <mesh
          filename="package://Roly_with_arm9/meshes/L gripper.STL" />
      </geometry>
    </collision>
  </link>
  <joint
    name="L gripper"
    type="prismatic">
    <origin
      xyz="0 0 0.140306953466177"
      rpy="0 0 -1.57079632679489" />
    <parent
      link="L_palm" />
    <child
      link="L gripper" />
    <axis
      xyz="0 0 1" />
    <limit
      lower="0"
      upper="0.03"
      effort="0"
      velocity="0" />
  </joint>
</robot>
