<?xml version="1.0" encoding="utf-8"?>
<!-- This URDF was automatically created by SolidWorks to URDF Exporter! Originally created by Stephen Brawner (brawner@gmail.com) 
     Commit Version: 1.6.0-4-g7f85cfe  Build Version: 1.6.7995.38578
     For more information, please see http://wiki.ros.org/sw_urdf_exporter -->
<robot
  name="Roly_update">
  <mujoco>
    <compiler meshdir="../meshes" balanceinertia="true" discardvisual="false"/>
  </mujoco>
  <link
    name="base_link">
    <inertial>
      <origin
        xyz="-2.09693302730856E-05 -4.03623321273321E-13 -0.0187178691238857"
        rpy="0 0 0" />
      <mass
        value="4.35454338307743" />
      <inertia
        ixx="0.0197722203546471"
        ixy="1.1899886219741E-07"
        ixz="6.77704110682819E-06"
        iyy="0.00413553225471283"
        iyz="-7.81217128670227E-15"
        izz="0.021630011357051" />
    </inertial>
    <visual>
      <origin
        xyz="0 0 0"
        rpy="0 0 0" />
      <geometry>
        <mesh
          filename="package://Roly_update/meshes/base_link.STL" />
      </geometry>
      <material
        name="">
        <color
          rgba="0.752941176470588 0.752941176470588 0.752941176470588 1" />
      </material>
    </visual>
    <collision>
      <origin
        xyz="0 0 0"
        rpy="0 0 0" />
      <geometry>
        <mesh
          filename="package://Roly_update/meshes/base_link.STL" />
      </geometry>
    </collision>
  </link>
  <!-- <joint
    name="trunk"
    type="continuous">
    <origin
      xyz="0 0 0.024"
      rpy="0 0 0" />
    <parent
      link="base_link" />
    <child
      link="trunk" />
    <axis
      xyz="0 0 1" />
  </joint> -->
  <link
    name="R_hip_yaw">
    <inertial>
      <origin
        xyz="-0.0551157453462435 -6.37588778601705E-05 -0.0843448458503075"
        rpy="0 0 0" />
      <mass
        value="1.43214345091561" />
      <inertia
        ixx="0.00166279676292496"
        ixy="-2.25901370225582E-06"
        ixz="8.23440880245644E-07"
        iyy="0.00137829761902421"
        iyz="-5.71796482477969E-13"
        izz="0.00159533562608115" />
    </inertial>
    <visual>
      <origin
        xyz="0 0 0"
        rpy="0 0 0" />
      <geometry>
        <mesh
          filename="package://Roly_update/meshes/R_hip_yaw.STL" />
      </geometry>
      <material
        name="">
        <color
          rgba="0.752941176470588 0.752941176470588 0.752941176470588 1" />
      </material>
    </visual>
    <collision>
      <origin
        xyz="0 0 0"
        rpy="0 0 0" />
      <geometry>
        <mesh
          filename="package://Roly_update/meshes/R_hip_yaw.STL" />
      </geometry>
    </collision>
  </link>
  <joint
    name="R_hip_yaw"
    type="continuous">
    <origin
      xyz="0 -0.13 -0.024"
      rpy="0 0 0" />
    <parent
      link="base_link" />
    <child
      link="R_hip_yaw" />
    <axis
      xyz="0 0 1" />
  </joint>
  <link
    name="R_hip_roll">
    <inertial>
      <origin
        xyz="0.00148012987693905 4.39768750581937E-09 9.44097992160296E-05"
        rpy="0 0 0" />
      <mass
        value="1.31563499532916" />
      <inertia
        ixx="0.000586960069643613"
        ixy="-1.61482924224722E-11"
        ixz="-4.2325434930938E-13"
        iyy="0.00199706384380774"
        iyz="9.90320585195441E-13"
        izz="0.00189601334783963" />
    </inertial>
    <visual>
      <origin
        xyz="0 0 0"
        rpy="0 0 0" />
      <geometry>
        <mesh
          filename="package://Roly_update/meshes/R_hip_roll.STL" />
      </geometry>
      <material
        name="">
        <color
          rgba="0.752941176470588 0.752941176470588 0.752941176470588 1" />
      </material>
    </visual>
    <collision>
      <origin
        xyz="0 0 0"
        rpy="0 0 0" />
      <geometry>
        <mesh
          filename="package://Roly_update/meshes/R_hip_roll.STL" />
      </geometry>
    </collision>
  </link>
  <joint
    name="R_hip_roll"
    type="continuous">
    <origin
      xyz="0 0 -0.100499999999984"
      rpy="1.5707963267949 0 1.5707963267949" />
    <parent
      link="R_hip_yaw" />
    <child
      link="R_hip_roll" />
    <axis
      xyz="0 0 1" />
  </joint>
  <link
    name="R_hip_pitch">
    <inertial>
      <origin
        xyz="-0.14991135697416 0.00102058562119425 0.00138204495712677"
        rpy="0 0 0" />
      <mass
        value="2.59034581862293" />
      <inertia
        ixx="0.00368152189538091"
        ixy="2.60027571776194E-05"
        ixz="-2.32790309814742E-08"
        iyy="0.00509733345831479"
        iyz="-2.00560044278427E-06"
        izz="0.0056508139334175" />
    </inertial>
    <visual>
      <origin
        xyz="0 0 0"
        rpy="0 0 0" />
      <geometry>
        <mesh
          filename="package://Roly_update/meshes/R_hip_pitch.STL" />
      </geometry>
      <material
        name="">
        <color
          rgba="0.752941176470588 0.752941176470588 0.752941176470588 1" />
      </material>
    </visual>
    <collision>
      <origin
        xyz="0 0 0"
        rpy="0 0 0" />
      <geometry>
        <mesh
          filename="package://Roly_update/meshes/R_hip_pitch.STL" />
      </geometry>
    </collision>
  </link>
  <joint
    name="R_hip_pitch"
    type="continuous">
    <origin
      xyz="0 0 0"
      rpy="1.5707963267949 0 1.5707963267949" />
    <parent
      link="R_hip_roll" />
    <child
      link="R_hip_pitch" />
    <axis
      xyz="0 0 1" />
  </joint>
  <link
    name="R_calf">
    <inertial>
      <origin
        xyz="-0.115445160832685 -0.000559768363222834 -0.010164295316872"
        rpy="0 0 0" />
      <mass
        value="1.86216970756978" />
      <inertia
        ixx="0.00121693708160006"
        ixy="1.75971149586229E-05"
        ixz="-1.72650949756646E-06"
        iyy="0.00442117021095285"
        iyz="4.63776535906187E-08"
        izz="0.00516207706040075" />
    </inertial>
    <visual>
      <origin
        xyz="0 0 0"
        rpy="0 0 0" />
      <geometry>
        <mesh
          filename="package://Roly_update/meshes/R_calf.STL" />
      </geometry>
      <material
        name="">
        <color
          rgba="0.752941176470588 0.752941176470588 0.752941176470588 1" />
      </material>
    </visual>
    <collision>
      <origin
        xyz="0 0 0"
        rpy="0 0 0" />
      <geometry>
        <mesh
          filename="package://Roly_update/meshes/R_calf.STL" />
      </geometry>
    </collision>
  </link>
  <joint
    name="R_calf"
    type="continuous">
    <origin
      xyz="-0.31 0 0"
      rpy="0 0 0" />
    <parent
      link="R_hip_pitch" />
    <child
      link="R_calf" />
    <axis
      xyz="0 0 1" />
  </joint>
  <link
    name="R_ankle_pitch">
    <inertial>
      <origin
        xyz="-0.0459602409816355 0.0196316983322056 -4.06788864645014E-05"
        rpy="0 0 0" />
      <mass
        value="0.990577841443613" />
      <inertia
        ixx="0.00101039561412582"
        ixy="1.54677494342955E-05"
        ixz="-8.03493866092893E-13"
        iyy="0.000487571749316864"
        iyz="-4.5006050473777E-13"
        izz="0.00115084495203271" />
    </inertial>
    <visual>
      <origin
        xyz="0 0 0"
        rpy="0 0 0" />
      <geometry>
        <mesh
          filename="package://Roly_update/meshes/R_ankle_pitch.STL" />
      </geometry>
      <material
        name="">
        <color
          rgba="0.752941176470588 0.752941176470588 0.752941176470588 1" />
      </material>
    </visual>
    <collision>
      <origin
        xyz="0 0 0"
        rpy="0 0 0" />
      <geometry>
        <mesh
          filename="package://Roly_update/meshes/R_ankle_pitch.STL" />
      </geometry>
    </collision>
  </link>
  <joint
    name="R_ankle_pitch"
    type="continuous">
    <origin
      xyz="-0.26 0 0"
      rpy="0 0 0" />
    <parent
      link="R_calf" />
    <child
      link="R_ankle_pitch" />
    <axis
      xyz="0 0 1" />
  </joint>
  <link
    name="R_ankle_roll">
    <inertial>
      <origin
        xyz="-0.0685998049350527 2.19566587134068E-11 0.019999999988339"
        rpy="0 0 0" />
      <mass
        value="1.80750858879406" />
      <inertia
        ixx="0.00356060489977588"
        ixy="5.08107146048658E-14"
        ixz="7.01373919018601E-14"
        iyy="0.00313608673879828"
        iyz="-3.22423664026232E-13"
        izz="0.000582664567478919" />
    </inertial>
    <visual>
      <origin
        xyz="0 0 0"
        rpy="0 0 0" />
      <geometry>
        <mesh
          filename="package://Roly_update/meshes/R_ankle_roll.STL" />
      </geometry>
      <material
        name="">
        <color
          rgba="0.752941176470588 0.752941176470588 0.752941176470588 1" />
      </material>
    </visual>
    <collision>
      <origin
        xyz="0 0 0"
        rpy="0 0 0" />
      <geometry>
        <mesh
          filename="package://Roly_update/meshes/R_ankle_roll.STL" />
      </geometry>
    </collision>
  </link>
  <joint
    name="R_ankle_roll"
    type="continuous">
    <origin
      xyz="-0.05 0 0"
      rpy="-1.57079632679489 0 0" />
    <parent
      link="R_ankle_pitch" />
    <child
      link="R_ankle_roll" />
    <axis
      xyz="0 0 1" />
  </joint>
  <link
    name="R_knee_rocker">
    <inertial>
      <origin
        xyz="-0.00719496594494917 -0.00261875342603682 -0.0168740723753152"
        rpy="0 0 0" />
      <mass
        value="0.147234181769685" />
      <inertia
        ixx="3.23048235524151E-05"
        ixy="-1.42989160924717E-05"
        ixz="-6.07779307992846E-06"
        iyy="6.63863926537154E-05"
        iyz="-2.21213576180986E-06"
        izz="8.94281354141203E-05" />
    </inertial>
    <visual>
      <origin
        xyz="0 0 0"
        rpy="0 0 0" />
      <geometry>
        <mesh
          filename="package://Roly_update/meshes/R_knee_rocker.STL" />
      </geometry>
      <material
        name="">
        <color
          rgba="0.752941176470588 0.752941176470588 0.752941176470588 1" />
      </material>
    </visual>
    <collision>
      <origin
        xyz="0 0 0"
        rpy="0 0 0" />
      <geometry>
        <mesh
          filename="package://Roly_update/meshes/R_knee_rocker.STL" />
      </geometry>
    </collision>
  </link>
  <joint
    name="R_knee_rocker"
    type="continuous">
    <origin
      xyz="-0.16 0 -0.0345000000000003"
      rpy="0 0 0" />
    <parent
      link="R_hip_pitch" />
    <child
      link="R_knee_rocker" />
    <axis
      xyz="0 0 1" />
  </joint>
  <link
    name="R_knee_linkage">
    <inertial>
      <origin
        xyz="-0.0731902184314708 0.0266387984841575 -5.56249490912819E-13"
        rpy="0 0 0" />
      <mass
        value="0.110281845782562" />
      <inertia
        ixx="1.16107281437619E-05"
        ixy="2.38947586603858E-05"
        ixz="2.06937518272874E-13"
        iyy="6.85640571092493E-05"
        iyz="5.72483218242183E-13"
        izz="7.74131693353276E-05" />
    </inertial>
    <visual>
      <origin
        xyz="0 0 0"
        rpy="0 0 0" />
      <geometry>
        <mesh
          filename="package://Roly_update/meshes/R_knee_linkage.STL" />
      </geometry>
      <material
        name="">
        <color
          rgba="0.752941176470588 0.752941176470588 0.752941176470588 1" />
      </material>
    </visual>
    <collision>
      <origin
        xyz="0 0 0"
        rpy="0 0 0" />
      <geometry>
        <mesh
          filename="package://Roly_update/meshes/R_knee_linkage.STL" />
      </geometry>
    </collision>
  </link>
  <joint
    name="R_knee_linkage"
    type="continuous">
    <origin
      xyz="-0.0563815572471495 -0.0205212085995536 -0.0215000000000002"
      rpy="0 0 0.349065850399105" />
    <parent
      link="R_knee_rocker" />
    <child
      link="R_knee_linkage" />
    <axis
      xyz="0 0 1" />
  </joint>
  <link
    name="L_hip_yaw">
    <inertial>
      <origin
        xyz="-0.0551157453462433 -6.37588778602816E-05 -0.0843448458503074"
        rpy="0 0 0" />
      <mass
        value="1.43214345091561" />
      <inertia
        ixx="0.00166279676292496"
        ixy="-2.25901370225579E-06"
        ixz="8.2344088024564E-07"
        iyy="0.00137829761902421"
        iyz="-5.71796475956582E-13"
        izz="0.00159533562608115" />
    </inertial>
    <visual>
      <origin
        xyz="0 0 0"
        rpy="0 0 0" />
      <geometry>
        <mesh
          filename="package://Roly_update/meshes/L_hip_yaw.STL" />
      </geometry>
      <material
        name="">
        <color
          rgba="0.752941176470588 0.752941176470588 0.752941176470588 1" />
      </material>
    </visual>
    <collision>
      <origin
        xyz="0 0 0"
        rpy="0 0 0" />
      <geometry>
        <mesh
          filename="package://Roly_update/meshes/L_hip_yaw.STL" />
      </geometry>
    </collision>
  </link>
  <joint
    name="L_hip_yaw"
    type="continuous">
    <origin
      xyz="0 0.13 -0.024"
      rpy="0 0 0" />
    <parent
      link="base_link" />
    <child
      link="L_hip_yaw" />
    <axis
      xyz="0 0 1" />
  </joint>
  <link
    name="L_hip_roll">
    <inertial>
      <origin
        xyz="-0.00145606804278145 -4.43152028961613E-09 -0.000573641853623313"
        rpy="0 0 0" />
      <mass
        value="1.33737606179077" />
      <inertia
        ixx="0.000590105330412749"
        ixy="-1.60440311053523E-11"
        ixz="3.46676955400324E-13"
        iyy="0.00200020910826934"
        iyz="-2.1650150233675E-16"
        izz="0.00190217341882605" />
    </inertial>
    <visual>
      <origin
        xyz="0 0 0"
        rpy="0 0 0" />
      <geometry>
        <mesh
          filename="package://Roly_update/meshes/L_hip_roll.STL" />
      </geometry>
      <material
        name="">
        <color
          rgba="0.752941176470588 0.752941176470588 0.752941176470588 1" />
      </material>
    </visual>
    <collision>
      <origin
        xyz="0 0 0"
        rpy="0 0 0" />
      <geometry>
        <mesh
          filename="package://Roly_update/meshes/L_hip_roll.STL" />
      </geometry>
    </collision>
  </link>
  <joint
    name="L_hip_roll"
    type="continuous">
    <origin
      xyz="0 0 -0.100499999999984"
      rpy="1.5707963267949 0 1.5707963267949" />
    <parent
      link="L_hip_yaw" />
    <child
      link="L_hip_roll" />
    <axis
      xyz="0 0 1" />
  </joint>
  <link
    name="L_hip_pitch">
    <inertial>
      <origin
        xyz="-0.149911356974161 0.00102058562119372 -0.0013709185674789"
        rpy="0 0 0" />
      <mass
        value="2.59034581862293" />
      <inertia
        ixx="0.0036815218953809"
        ixy="2.60027571776145E-05"
        ixz="2.32820573929458E-08"
        iyy="0.00509733345831478"
        iyz="2.00559932947277E-06"
        izz="0.0056508139334175" />
    </inertial>
    <visual>
      <origin
        xyz="0 0 0"
        rpy="0 0 0" />
      <geometry>
        <mesh
          filename="package://Roly_update/meshes/L_hip_pitch.STL" />
      </geometry>
      <material
        name="">
        <color
          rgba="0.752941176470588 0.752941176470588 0.752941176470588 1" />
      </material>
    </visual>
    <collision>
      <origin
        xyz="0 0 0"
        rpy="0 0 0" />
      <geometry>
        <mesh
          filename="package://Roly_update/meshes/L_hip_pitch.STL" />
      </geometry>
    </collision>
  </link>
  <joint
    name="L_hip_pitch"
    type="continuous">
    <origin
      xyz="0 0 0"
      rpy="1.5707963267949 0 1.5707963267949" />
    <parent
      link="L_hip_roll" />
    <child
      link="L_hip_pitch" />
    <axis
      xyz="0 0 1" />
  </joint>
  <link
    name="L_calf">
    <inertial>
      <origin
        xyz="-0.115426382792599 -0.000677771088297709 0.0105015841300466"
        rpy="0 0 0" />
      <mass
        value="1.87198703722554" />
      <inertia
        ixx="0.00121957366335642"
        ixy="1.75898619777057E-05"
        ixz="1.72520219163734E-06"
        iyy="0.00442397879163606"
        iyz="-4.63709721302385E-08"
        izz="0.0051612766976138" />
    </inertial>
    <visual>
      <origin
        xyz="0 0 0"
        rpy="0 0 0" />
      <geometry>
        <mesh
          filename="package://Roly_update/meshes/L_calf.STL" />
      </geometry>
      <material
        name="">
        <color
          rgba="0.752941176470588 0.752941176470588 0.752941176470588 1" />
      </material>
    </visual>
    <collision>
      <origin
        xyz="0 0 0"
        rpy="0 0 0" />
      <geometry>
        <mesh
          filename="package://Roly_update/meshes/L_calf.STL" />
      </geometry>
    </collision>
  </link>
  <joint
    name="L_calf"
    type="continuous">
    <origin
      xyz="-0.31 0 0"
      rpy="0 0 0" />
    <parent
      link="L_hip_pitch" />
    <child
      link="L_calf" />
    <axis
      xyz="0 0 1" />
  </joint>
  <link
    name="L_ankle_pitch">
    <inertial>
      <origin
        xyz="-0.045960203600186 0.0196317255822612 5.49194716691348E-05"
        rpy="0 0 0" />
      <mass
        value="0.990577841443614" />
      <inertia
        ixx="0.00101039570726068"
        ixy="1.54676260903529E-05"
        ixz="-9.68287418918988E-13"
        iyy="0.000487571656182"
        iyz="5.95500775831433E-14"
        izz="0.00115084495203272" />
    </inertial>
    <visual>
      <origin
        xyz="0 0 0"
        rpy="0 0 0" />
      <geometry>
        <mesh
          filename="package://Roly_update/meshes/L_ankle_pitch.STL" />
      </geometry>
      <material
        name="">
        <color
          rgba="0.752941176470588 0.752941176470588 0.752941176470588 1" />
      </material>
    </visual>
    <collision>
      <origin
        xyz="0 0 0"
        rpy="0 0 0" />
      <geometry>
        <mesh
          filename="package://Roly_update/meshes/L_ankle_pitch.STL" />
      </geometry>
    </collision>
  </link>
  <joint
    name="L_ankle_pitch"
    type="continuous">
    <origin
      xyz="-0.26 0 0"
      rpy="0 0 0" />
    <parent
      link="L_calf" />
    <child
      link="L_ankle_pitch" />
    <axis
      xyz="0 0 1" />
  </joint>
  <link
    name="L_ankle_roll">
    <inertial>
      <origin
        xyz="-0.0685998049350521 2.19568807580117E-11 0.019999999988339"
        rpy="0 0 0" />
      <mass
        value="1.80750858879406" />
      <inertia
        ixx="0.00356060489977588"
        ixy="5.08107016845893E-14"
        ixz="7.01373933899488E-14"
        iyy="0.00313608673879828"
        iyz="-3.22423614316346E-13"
        izz="0.000582664567478919" />
    </inertial>
    <visual>
      <origin
        xyz="0 0 0"
        rpy="0 0 0" />
      <geometry>
        <mesh
          filename="package://Roly_update/meshes/L_ankle_roll.STL" />
      </geometry>
      <material
        name="">
        <color
          rgba="0.752941176470588 0.752941176470588 0.752941176470588 1" />
      </material>
    </visual>
    <collision>
      <origin
        xyz="0 0 0"
        rpy="0 0 0" />
      <geometry>
        <mesh
          filename="package://Roly_update/meshes/L_ankle_roll.STL" />
      </geometry>
    </collision>
  </link>
  <joint
    name="L_ankle_roll"
    type="continuous">
    <origin
      xyz="-0.05 0 0"
      rpy="-1.5707963267949 0 0" />
    <parent
      link="L_ankle_pitch" />
    <child
      link="L_ankle_roll" />
    <axis
      xyz="0 0 1" />
  </joint>
  <link
    name="L_knee_rocker">
    <inertial>
      <origin
        xyz="-0.00719496593564223 -0.00261875345160752 0.0168740723753152"
        rpy="0 0 0" />
      <mass
        value="0.147234181769685" />
      <inertia
        ixx="3.23048234923004E-05"
        ixy="-1.42989160208298E-05"
        ixz="6.0777930739413E-06"
        iyy="6.63863927138299E-05"
        iyz="2.21213577825894E-06"
        izz="8.94281354141202E-05" />
    </inertial>
    <visual>
      <origin
        xyz="0 0 0"
        rpy="0 0 0" />
      <geometry>
        <mesh
          filename="package://Roly_update/meshes/L_knee_rocker.STL" />
      </geometry>
      <material
        name="">
        <color
          rgba="0.752941176470588 0.752941176470588 0.752941176470588 1" />
      </material>
    </visual>
    <collision>
      <origin
        xyz="0 0 0"
        rpy="0 0 0" />
      <geometry>
        <mesh
          filename="package://Roly_update/meshes/L_knee_rocker.STL" />
      </geometry>
    </collision>
  </link>
  <joint
    name="L_knee_rocker"
    type="continuous">
    <origin
      xyz="-0.16 0 0.0344999999999996"
      rpy="0 0 0" />
    <parent
      link="L_hip_pitch" />
    <child
      link="L_knee_rocker" />
    <axis
      xyz="0 0 1" />
  </joint>
  <link
    name="L_knee_linkage">
    <inertial>
      <origin
        xyz="-0.0731902184314766 0.0266387984841421 -5.56277246488435E-13"
        rpy="0 0 0" />
      <mass
        value="0.110281845782561" />
      <inertia
        ixx="1.16107281437516E-05"
        ixy="2.38947586603736E-05"
        ixz="2.0693749572872E-13"
        iyy="6.85640571092591E-05"
        iyz="5.72483231874431E-13"
        izz="7.74131693353272E-05" />
    </inertial>
    <visual>
      <origin
        xyz="0 0 0"
        rpy="0 0 0" />
      <geometry>
        <mesh
          filename="package://Roly_update/meshes/L_knee_linkage.STL" />
      </geometry>
      <material
        name="">
        <color
          rgba="0.752941176470588 0.752941176470588 0.752941176470588 1" />
      </material>
    </visual>
    <collision>
      <origin
        xyz="0 0 0"
        rpy="0 0 0" />
      <geometry>
        <mesh
          filename="package://Roly_update/meshes/L_knee_linkage.STL" />
      </geometry>
    </collision>
  </link>
  <joint
    name="L_knee_linkage"
    type="continuous">
    <origin
      xyz="-0.056381557247154 -0.0205212085995416 0.0215"
      rpy="0 0 0.349065850398892" />
    <parent
      link="L_knee_rocker" />
    <child
      link="L_knee_linkage" />
    <axis
      xyz="0 0 1" />
  </joint>
  <link
    name="trunk_link">
    <inertial>
      <origin
        xyz="-0.000201091103492413 -0.00171850259382555 0.342933302682392"
        rpy="0 0 0" />
      <mass
        value="3.71736761608175" />
      <inertia
        ixx="0.0423654714360495"
        ixy="6.10031795665251E-05"
        ixz="-3.51532548621897E-05"
        iyy="0.0296803741935265"
        iyz="6.70641597379969E-05"
        izz="0.0132646084404209" />
    </inertial>
    <visual>
      <origin
        xyz="0 0 0"
        rpy="0 0 0" />
      <geometry>
        <mesh
          filename="package://Roly_update/meshes/trunk_link.STL" />
      </geometry>
      <material
        name="">
        <color
          rgba="0.752941176470588 0.752941176470588 0.752941176470588 1" />
      </material>
    </visual>
    <collision>
      <origin
        xyz="0 0 0"
        rpy="0 0 0" />
      <geometry>
        <mesh
          filename="package://Roly_update/meshes/trunk_link.STL" />
      </geometry>
    </collision>
  </link>
  <joint
    name="trunk"
    type="continuous">
    <origin
      xyz="0 0 0.024"
      rpy="0 0 0" />
    <parent
      link="base_link" />
    <child
      link="trunk_link" />
    <axis
      xyz="0 0 1" />
  </joint>
  <link
    name="neck">
    <inertial>
      <origin
        xyz="-0.0115401971148497 -2.74217546407196E-05 0.0768418068454789"
        rpy="0 0 0" />
      <mass
        value="0.0915993237937378" />
      <inertia
        ixx="1.52019609168068E-05"
        ixy="-3.28341386543851E-07"
        ixz="1.4320638760515E-09"
        iyy="2.11960891861308E-05"
        iyz="-1.37470597830053E-09"
        izz="2.61388223158171E-05" />
    </inertial>
    <visual>
      <origin
        xyz="0 0 0"
        rpy="0 0 0" />
      <geometry>
        <mesh
          filename="package://Roly_update/meshes/neck.STL" />
      </geometry>
      <material
        name="">
        <color
          rgba="0.752941176470588 0.752941176470588 0.752941176470588 1" />
      </material>
    </visual>
    <collision>
      <origin
        xyz="0 0 0"
        rpy="0 0 0" />
      <geometry>
        <mesh
          filename="package://Roly_update/meshes/neck.STL" />
      </geometry>
    </collision>
  </link>
  <joint
    name="neck"
    type="continuous">
    <origin
      xyz="0.0236 0 0.525"
      rpy="0 0 0" />
    <parent
      link="trunk_link" />
    <child
      link="neck" />
    <axis
      xyz="0 0 1" />
  </joint>
  <link
    name="camera">
    <inertial>
      <origin
        xyz="0.00773068278361725 0.0510544535429484 -0.00119353011540578"
        rpy="0 0 0" />
      <mass
        value="0.074287263423426" />
      <inertia
        ixx="4.43870779407165E-05"
        ixy="9.06935673607431E-08"
        ixz="4.47251575648331E-07"
        iyy="3.98543909637004E-05"
        iyz="2.19915553005924E-08"
        izz="1.5340417371391E-05" />
    </inertial>
    <visual>
      <origin
        xyz="0 0 0"
        rpy="0 0 0" />
      <geometry>
        <mesh
          filename="package://Roly_update/meshes/camera.STL" />
      </geometry>
      <material
        name="">
        <color
          rgba="0.752941176470588 0.752941176470588 0.752941176470588 1" />
      </material>
    </visual>
    <collision>
      <origin
        xyz="0 0 0"
        rpy="0 0 0" />
      <geometry>
        <mesh
          filename="package://Roly_update/meshes/camera.STL" />
      </geometry>
    </collision>
  </link>
  <joint
    name="camera"
    type="continuous">
    <origin
      xyz="0 0 0.0799"
      rpy="1.5708 0 0" />
    <parent
      link="neck" />
    <child
      link="camera" />
    <axis
      xyz="0 0 1" />
  </joint>
  <link
    name="R_shoulder">
    <inertial>
      <origin
        xyz="-4.78828931240873E-05 0.0156539518070029 0.248211898616547"
        rpy="0 0 0" />
      <mass
        value="0.159233792908747" />
      <inertia
        ixx="5.90635379080722E-05"
        ixy="6.76340148769994E-07"
        ixz="3.93669860266589E-09"
        iyy="4.06885503332512E-05"
        iyz="-6.05489800766554E-09"
        izz="7.3658214817E-05" />
    </inertial>
    <visual>
      <origin
        xyz="0 0 0"
        rpy="0 0 0" />
      <geometry>
        <mesh
          filename="package://Roly_update/meshes/R_shoulder.STL" />
      </geometry>
      <material
        name="">
        <color
          rgba="0.752941176470588 0.752941176470588 0.752941176470588 1" />
      </material>
    </visual>
    <collision>
      <origin
        xyz="0 0 0"
        rpy="0 0 0" />
      <geometry>
        <mesh
          filename="package://Roly_update/meshes/R_shoulder.STL" />
      </geometry>
    </collision>
  </link>
  <joint
    name="R_shoulder"
    type="continuous">
    <origin
      xyz="0 0 0.495"
      rpy="1.5708 0 0" />
    <parent
      link="trunk_link" />
    <child
      link="R_shoulder" />
    <axis
      xyz="0 0 1" />
  </joint>
  <link
    name="R_arm1">
    <inertial>
      <origin
        xyz="-0.0833488305221005 1.97180429876431E-05 -7.82530764731025E-06"
        rpy="0 0 0" />
      <mass
        value="0.185807988030178" />
      <inertia
        ixx="5.49966092882244E-05"
        ixy="1.2433857230614E-08"
        ixz="6.76337657036284E-07"
        iyy="8.80008229873593E-05"
        iyz="3.93877607820814E-09"
        izz="6.51364712534083E-05" />
    </inertial>
    <visual>
      <origin
        xyz="0 0 0"
        rpy="0 0 0" />
      <geometry>
        <mesh
          filename="package://Roly_update/meshes/R_arm1.STL" />
      </geometry>
      <material
        name="">
        <color
          rgba="0.752941176470588 0.752941176470588 0.752941176470588 1" />
      </material>
    </visual>
    <collision>
      <origin
        xyz="0 0 0"
        rpy="0 0 0" />
      <geometry>
        <mesh
          filename="package://Roly_update/meshes/R_arm1.STL" />
      </geometry>
    </collision>
  </link>
  <joint
    name="R_arm1"
    type="continuous">
    <origin
      xyz="0 0 0.2488"
      rpy="1.5708 0 1.5708" />
    <parent
      link="R_shoulder" />
    <child
      link="R_arm1" />
    <axis
      xyz="0 0 1" />
  </joint>
  <link
    name="R_arm2">
    <inertial>
      <origin
        xyz="-0.0563000259056253 1.75933948937113E-07 -0.00680843482052775"
        rpy="0 0 0" />
      <mass
        value="0.0726996420803591" />
      <inertia
        ixx="2.47802098371494E-05"
        ixy="2.31836798352999E-11"
        ixz="1.78932145416602E-07"
        iyy="2.6966904229404E-05"
        iyz="2.41655414443905E-11"
        izz="1.38415312507139E-05" />
    </inertial>
    <visual>
      <origin
        xyz="0 0 0"
        rpy="0 0 0" />
      <geometry>
        <mesh
          filename="package://Roly_update/meshes/R_arm2.STL" />
      </geometry>
      <material
        name="">
        <color
          rgba="0.752941176470588 0.752941176470588 0.752941176470588 1" />
      </material>
    </visual>
    <collision>
      <origin
        xyz="0 0 0"
        rpy="0 0 0" />
      <geometry>
        <mesh
          filename="package://Roly_update/meshes/R_arm2.STL" />
      </geometry>
    </collision>
  </link>
  <joint
    name="R_arm2"
    type="continuous">
    <origin
      xyz="-0.1105 0 0"
      rpy="0 0 0" />
    <parent
      link="R_arm1" />
    <child
      link="R_arm2" />
    <axis
      xyz="0 0 1" />
  </joint>
  <link
    name="R_arm3">
    <inertial>
      <origin
        xyz="-3.22966608941877E-05 -1.4973746871969E-05 -0.127350702193879"
        rpy="0 0 0" />
      <mass
        value="0.0455132201726528" />
      <inertia
        ixx="1.04441289107308E-05"
        ixy="-1.21609224311861E-12"
        ixz="1.81663840661959E-07"
        iyy="1.24358375510277E-05"
        iyz="-2.28574770322915E-09"
        izz="7.82054953991462E-06" />
    </inertial>
    <visual>
      <origin
        xyz="0 0 0"
        rpy="0 0 0" />
      <geometry>
        <mesh
          filename="package://Roly_update/meshes/R_arm3.STL" />
      </geometry>
      <material
        name="">
        <color
          rgba="0.752941176470588 0.752941176470588 0.752941176470588 1" />
      </material>
    </visual>
    <collision>
      <origin
        xyz="0 0 0"
        rpy="0 0 0" />
      <geometry>
        <mesh
          filename="package://Roly_update/meshes/R_arm3.STL" />
      </geometry>
    </collision>
  </link>
  <joint
    name="R_arm3"
    type="continuous">
    <origin
      xyz="0 0 0"
      rpy="1.5708 0 1.5708" />
    <parent
      link="R_arm2" />
    <child
      link="R_arm3" />
    <axis
      xyz="0 0 1" />
  </joint>
  <link
    name="R_arm4">
    <inertial>
      <origin
        xyz="-0.0101576588872515 -0.047494615258097 9.27942669561033E-05"
        rpy="0 0 0" />
      <mass
        value="0.0493363034804285" />
      <inertia
        ixx="9.03991587155395E-06"
        ixy="1.7893257478444E-07"
        ixz="2.41603387549999E-11"
        iyy="1.18657637430999E-05"
        iyz="-1.47190672566463E-11"
        izz="1.28686059122131E-05" />
    </inertial>
    <visual>
      <origin
        xyz="0 0 0"
        rpy="0 0 0" />
      <geometry>
        <mesh
          filename="package://Roly_update/meshes/R_arm4.STL" />
      </geometry>
      <material
        name="">
        <color
          rgba="0.752941176470588 0.752941176470588 0.752941176470588 1" />
      </material>
    </visual>
    <collision>
      <origin
        xyz="0 0 0"
        rpy="0 0 0" />
      <geometry>
        <mesh
          filename="package://Roly_update/meshes/R_arm4.STL" />
      </geometry>
    </collision>
  </link>
  <joint
    name="R_arm4"
    type="continuous">
    <origin
      xyz="0 0 -0.1403"
      rpy="1.5708 0 1.5708" />
    <parent
      link="R_arm3" />
    <child
      link="R_arm4" />
    <axis
      xyz="0 0 1" />
  </joint>
  <link
    name="R_palm">
    <inertial>
      <origin
        xyz="-0.0113946842972341 0.0235192814508995 0.122399644416361"
        rpy="0 0 0" />
      <mass
        value="0.113705119247748" />
      <inertia
        ixx="1.3780982342221E-05"
        ixy="-2.42636957056662E-07"
        ixz="1.94870345629198E-07"
        iyy="4.21616665868208E-05"
        iyz="-2.41359412605047E-07"
        izz="4.19257646065179E-05" />
    </inertial>
    <visual>
      <origin
        xyz="0 0 0"
        rpy="0 0 0" />
      <geometry>
        <mesh
          filename="package://Roly_update/meshes/R_palm.STL" />
      </geometry>
      <material
        name="">
        <color
          rgba="0.752941176470588 0.752941176470588 0.752941176470588 1" />
      </material>
    </visual>
    <collision>
      <origin
        xyz="0 0 0"
        rpy="0 0 0" />
      <geometry>
        <mesh
          filename="package://Roly_update/meshes/R_palm.STL" />
      </geometry>
    </collision>
  </link>
  <joint
    name="R_palm"
    type="continuous">
    <origin
      xyz="0 0 0"
      rpy="1.5708 0 0" />
    <parent
      link="R_arm4" />
    <child
      link="R_palm" />
    <axis
      xyz="0 0 1" />
  </joint>
  <link
    name="R finger1-1">
    <inertial>
      <origin
        xyz="-0.000480686558137322 -0.0114899518322553 5.752972154216E-09"
        rpy="0 0 0" />
      <mass
        value="0.0012778761403405" />
      <inertia
        ixx="1.1824809639494E-07"
        ixy="-4.03761413416375E-09"
        ixz="1.01172163297441E-14"
        iyy="2.04217019954223E-08"
        iyz="5.71316280881948E-14"
        izz="1.35262128682723E-07" />
    </inertial>
    <visual>
      <origin
        xyz="0 0 0"
        rpy="0 0 0" />
      <geometry>
        <mesh
          filename="package://Roly_update/meshes/R finger1-1.STL" />
      </geometry>
      <material
        name="">
        <color
          rgba="0.752941176470588 0.752941176470588 0.752941176470588 1" />
      </material>
    </visual>
    <collision>
      <origin
        xyz="0 0 0"
        rpy="0 0 0" />
      <geometry>
        <mesh
          filename="package://Roly_update/meshes/R finger1-1.STL" />
      </geometry>
    </collision>
  </link>
  <joint
    name="R finger1-1"
    type="continuous">
    <origin
      xyz="-0.035007 0 0.14"
      rpy="-1.5708 0.04118 -3.1416" />
    <parent
      link="R_palm" />
    <child
      link="R finger1-1" />
    <axis
      xyz="0 0 1" />
  </joint>
  <link
    name="R finger1-2">
    <inertial>
      <origin
        xyz="-0.00382802648270555 -0.0297910428258497 1.94733618119614E-10"
        rpy="0 0 0" />
      <mass
        value="0.00707739712532309" />
      <inertia
        ixx="1.51715953464134E-06"
        ixy="2.43506955637569E-07"
        ixz="1.5995473913918E-13"
        iyy="3.21509193857958E-07"
        iyz="-4.41039109602696E-13"
        izz="1.7239148033551E-06" />
    </inertial>
    <visual>
      <origin
        xyz="0 0 0"
        rpy="0 0 0" />
      <geometry>
        <mesh
          filename="package://Roly_update/meshes/R finger1-2.STL" />
      </geometry>
      <material
        name="">
        <color
          rgba="0.752941176470588 0.752941176470588 0.752941176470588 1" />
      </material>
    </visual>
    <collision>
      <origin
        xyz="0 0 0"
        rpy="0 0 0" />
      <geometry>
        <mesh
          filename="package://Roly_update/meshes/R finger1-2.STL" />
      </geometry>
    </collision>
  </link>
  <joint
    name="R finger1-2"
    type="continuous">
    <origin
      xyz="-0.00094687 -0.022981 0"
      rpy="0 0 -0.04118" />
    <parent
      link="R finger1-1" />
    <child
      link="R finger1-2" />
    <axis
      xyz="0 0 1" />
  </joint>
  <link
    name="R finger2-1">
    <inertial>
      <origin
        xyz="0.000527380885400608 -0.0114881135900972 -6.84427847730262E-10"
        rpy="0 0 0" />
      <mass
        value="0.0012778761403405" />
      <inertia
        ixx="1.18248088639666E-07"
        ixy="4.03770808337544E-09"
        ixz="-8.10269804901887E-16"
        iyy="2.04217097506651E-08"
        iyz="-6.91892129797207E-15"
        izz="1.35262128682755E-07" />
    </inertial>
    <visual>
      <origin
        xyz="0 0 0"
        rpy="0 0 0" />
      <geometry>
        <mesh
          filename="package://Roly_update/meshes/R finger2-1.STL" />
      </geometry>
      <material
        name="">
        <color
          rgba="0.752941176470588 0.752941176470588 0.752941176470588 1" />
      </material>
    </visual>
    <collision>
      <origin
        xyz="0 0 0"
        rpy="0 0 0" />
      <geometry>
        <mesh
          filename="package://Roly_update/meshes/R finger2-1.STL" />
      </geometry>
    </collision>
  </link>
  <joint
    name="R finger2-1"
    type="continuous">
    <origin
      xyz="0.0303576346822608 0.0175269885557571 0.139999914307583"
      rpy="-1.57079638666558 -0.0411808566521372 -2.61799394048697" />
    <parent
      link="R_palm" />
    <child
      link="R finger2-1" />
    <axis
      xyz="0 0 0.999999999999996" />
    <mimic
      joint=""
      multiplier="1"
      offset="0" />
  </joint>
  <link
    name="R finger2-2">
    <inertial>
      <origin
        xyz="0.0038747458567531 -0.0297911285180824 -1.94733729141916E-10"
        rpy="0 0 0" />
      <mass
        value="0.00707739712532309" />
      <inertia
        ixx="1.51715953464136E-06"
        ixy="-2.43506955637547E-07"
        ixz="1.59954739110165E-13"
        iyy="3.21509193857949E-07"
        iyz="4.41039109201381E-13"
        izz="1.72391480335511E-06" />
    </inertial>
    <visual>
      <origin
        xyz="0 0 0"
        rpy="0 0 0" />
      <geometry>
        <mesh
          filename="package://Roly_update/meshes/R finger2-2.STL" />
      </geometry>
      <material
        name="">
        <color
          rgba="0.752941176470588 0.752941176470588 0.752941176470588 1" />
      </material>
    </visual>
    <collision>
      <origin
        xyz="0 0 0"
        rpy="0 0 0" />
      <geometry>
        <mesh
          filename="package://Roly_update/meshes/R finger2-2.STL" />
      </geometry>
    </collision>
  </link>
  <joint
    name="R finger2-2"
    type="continuous">
    <origin
      xyz="0.000946892016852635 -0.0229805003319862 0"
      rpy="0 0 0.0411808566521328" />
    <parent
      link="R finger2-1" />
    <child
      link="R finger2-2" />
    <axis
      xyz="0 0 1" />
    <mimic
      joint=""
      multiplier="1"
      offset="0" />
  </joint>
  <link
    name="R finger3-1">
    <inertial>
      <origin
        xyz="-5.24197635071166E-05 -0.0115 5.55111512312578E-17"
        rpy="0 0 0" />
      <mass
        value="0.00127787614034051" />
      <inertia
        ixx="1.18414458975182E-07"
        ixy="-1.77883710625383E-23"
        ixz="1.32348898008484E-23"
        iyy="2.02553394151494E-08"
        iyz="1.63382837847785E-24"
        izz="1.35262128682756E-07" />
    </inertial>
    <visual>
      <origin
        xyz="0 0 0"
        rpy="0 0 0" />
      <geometry>
        <mesh
          filename="package://Roly_update/meshes/R finger3-1.STL" />
      </geometry>
      <material
        name="">
        <color
          rgba="0.752941176470588 0.752941176470588 0.752941176470588 1" />
      </material>
    </visual>
    <collision>
      <origin
        xyz="0 0 0"
        rpy="0 0 0" />
      <geometry>
        <mesh
          filename="package://Roly_update/meshes/R finger3-1.STL" />
      </geometry>
    </collision>
  </link>
  <joint
    name="R finger3-1"
    type="continuous">
    <origin
      xyz="0.0302654922856084 -0.0174737901182462 0.139999999999815"
      rpy="-1.5707963267949 0 2.61799387799149" />
    <parent
      link="R_palm" />
    <child
      link="R finger3-1" />
    <axis
      xyz="0 0 1" />
    <mimic
      joint=""
      multiplier="1"
      offset="0" />
  </joint>
  <link
    name="R finger3-2">
    <inertial>
      <origin
        xyz="0.0037683489817274 -0.0297910428258497 -1.9473370138634E-10"
        rpy="0 0 0" />
      <mass
        value="0.00707739712532307" />
      <inertia
        ixx="1.51715953464134E-06"
        ixy="-2.43506955637571E-07"
        ixz="1.59954739268983E-13"
        iyy="3.21509193857958E-07"
        iyz="4.41039109044725E-13"
        izz="1.7239148033551E-06" />
    </inertial>
    <visual>
      <origin
        xyz="0 0 0"
        rpy="0 0 0" />
      <geometry>
        <mesh
          filename="package://Roly_update/meshes/R finger3-2.STL" />
      </geometry>
      <material
        name="">
        <color
          rgba="0.752941176470588 0.752941176470588 0.752941176470588 1" />
      </material>
    </visual>
    <collision>
      <origin
        xyz="0 0 0"
        rpy="0 0 0" />
      <geometry>
        <mesh
          filename="package://Roly_update/meshes/R finger3-2.STL" />
      </geometry>
    </collision>
  </link>
  <joint
    name="R finger3-2"
    type="continuous">
    <origin
      xyz="0 -0.023 0"
      rpy="0 0 0" />
    <parent
      link="R finger3-1" />
    <child
      link="R finger3-2" />
    <axis
      xyz="0 0 1" />
    <mimic
      joint=""
      multiplier="1"
      offset="0" />
  </joint>
  <link
    name="R gripper">
    <inertial>
      <origin
        xyz="-3.99957844621213E-14 0.00156504693317696 0"
        rpy="0 0 0" />
      <mass
        value="0.00609127056774437" />
      <inertia
        ixx="8.38284437689384E-07"
        ixy="-3.54738643211013E-21"
        ixz="-6.04735374827273E-23"
        iyy="3.77175708246467E-07"
        iyz="2.10240750990425E-22"
        izz="9.34655494343131E-07" />
    </inertial>
    <visual>
      <origin
        xyz="0 0 0"
        rpy="0 0 0" />
      <geometry>
        <mesh
          filename="package://Roly_update/meshes/R gripper.STL" />
      </geometry>
      <material
        name="">
        <color
          rgba="0.792156862745098 0.819607843137255 0.933333333333333 1" />
      </material>
    </visual>
    <collision>
      <origin
        xyz="0 0 0"
        rpy="0 0 0" />
      <geometry>
        <mesh
          filename="package://Roly_update/meshes/R gripper.STL" />
      </geometry>
    </collision>
  </link>
  <joint
    name="R gripper"
    type="prismatic">
    <origin
      xyz="0 0 0.163"
      rpy="0 0 -1.5708" />
    <parent
      link="R_palm" />
    <child
      link="R gripper" />
    <axis
      xyz="0 0 1" />
    <limit
      lower="0"
      upper="0.03"
      effort="0"
      velocity="0" />
  </joint>
  <link
    name="L_shoulder">
    <inertial>
      <origin
        xyz="-4.78827689011739E-05 0.0156539518070223 -0.248204682969382"
        rpy="0 0 0" />
      <mass
        value="0.159233792908747" />
      <inertia
        ixx="5.90635379080722E-05"
        ixy="6.76336036224675E-07"
        ixz="3.9366986026362E-09"
        iyy="4.06885503332512E-05"
        iyz="1.24343094959127E-08"
        izz="7.3658214817E-05" />
    </inertial>
    <visual>
      <origin
        xyz="0 0 0"
        rpy="0 0 0" />
      <geometry>
        <mesh
          filename="package://Roly_update/meshes/L_shoulder.STL" />
      </geometry>
      <material
        name="">
        <color
          rgba="0.752941176470588 0.752941176470588 0.752941176470588 1" />
      </material>
    </visual>
    <collision>
      <origin
        xyz="0 0 0"
        rpy="0 0 0" />
      <geometry>
        <mesh
          filename="package://Roly_update/meshes/L_shoulder.STL" />
      </geometry>
    </collision>
  </link>
  <joint
    name="L_shoulder"
    type="continuous">
    <origin
      xyz="0 0 0.495"
      rpy="1.5707963267949 0 0" />
    <parent
      link="trunk_link" />
    <child
      link="L_shoulder" />
    <axis
      xyz="0 0 1" />
  </joint>
  <link
    name="L_arm1">
    <inertial>
      <origin
        xyz="-0.0833488305130483 -1.35332765609231E-05 -7.82520296900079E-06"
        rpy="0 0 0" />
      <mass
        value="0.185807988101709" />
      <inertia
        ixx="5.49966092887569E-05"
        ixy="-6.05444467762574E-09"
        ixz="6.76337620782089E-07"
        iyy="8.80008229865707E-05"
        iyz="3.938773258511E-09"
        izz="6.51364712551086E-05" />
    </inertial>
    <visual>
      <origin
        xyz="0 0 0"
        rpy="0 0 0" />
      <geometry>
        <mesh
          filename="package://Roly_update/meshes/L_arm1.STL" />
      </geometry>
      <material
        name="">
        <color
          rgba="0.752941176470588 0.752941176470588 0.752941176470588 1" />
      </material>
    </visual>
    <collision>
      <origin
        xyz="0 0 0"
        rpy="0 0 0" />
      <geometry>
        <mesh
          filename="package://Roly_update/meshes/L_arm1.STL" />
      </geometry>
    </collision>
  </link>
  <joint
    name="L_arm1"
    type="continuous">
    <origin
      xyz="0 0 -0.248800000000004"
      rpy="1.5707963267949 0 1.57079632679437" />
    <parent
      link="L_shoulder" />
    <child
      link="L_arm1" />
    <axis
      xyz="0 0 1" />
  </joint>
  <link
    name="L_arm2">
    <inertial>
      <origin
        xyz="-0.0563000258962163 1.74828551496864E-07 -0.00680843479089642"
        rpy="0 0 0" />
      <mass
        value="0.0726996419948538" />
      <inertia
        ixx="2.47802098012189E-05"
        ixy="2.31861399300713E-11"
        ixz="1.78932123459111E-07"
        iyy="2.69669041799343E-05"
        iyz="2.41603170614869E-11"
        izz="1.38415312388201E-05" />
    </inertial>
    <visual>
      <origin
        xyz="0 0 0"
        rpy="0 0 0" />
      <geometry>
        <mesh
          filename="package://Roly_update/meshes/L_arm2.STL" />
      </geometry>
      <material
        name="">
        <color
          rgba="0.752941176470588 0.752941176470588 0.752941176470588 1" />
      </material>
    </visual>
    <collision>
      <origin
        xyz="0 0 0"
        rpy="0 0 0" />
      <geometry>
        <mesh
          filename="package://Roly_update/meshes/L_arm2.STL" />
      </geometry>
    </collision>
  </link>
  <joint
    name="L_arm2"
    type="continuous">
    <origin
      xyz="-0.110499999999998 0 0"
      rpy="0 0 0" />
    <parent
      link="L_arm1" />
    <child
      link="L_arm2" />
    <axis
      xyz="0 0 1" />
  </joint>
  <link
    name="L_arm3">
    <inertial>
      <origin
        xyz="3.2297618124677E-05 -1.49723623576823E-05 -0.127350702159071"
        rpy="0 0 0" />
      <mass
        value="0.045513220258158" />
      <inertia
        ixx="1.04441289466614E-05"
        ixy="-1.21363217593623E-12"
        ixz="-1.81663846805576E-07"
        iyy="1.24358376004975E-05"
        iyz="-2.28507494410195E-09"
        izz="7.82054955180837E-06" />
    </inertial>
    <visual>
      <origin
        xyz="0 0 0"
        rpy="0 0 0" />
      <geometry>
        <mesh
          filename="package://Roly_update/meshes/L_arm3.STL" />
      </geometry>
      <material
        name="">
        <color
          rgba="0.752941176470588 0.752941176470588 0.752941176470588 1" />
      </material>
    </visual>
    <collision>
      <origin
        xyz="0 0 0"
        rpy="0 0 0" />
      <geometry>
        <mesh
          filename="package://Roly_update/meshes/L_arm3.STL" />
      </geometry>
    </collision>
  </link>
  <joint
    name="L_arm3"
    type="continuous">
    <origin
      xyz="0 0 0"
      rpy="1.5707963267949 0 1.5707963267949" />
    <parent
      link="L_arm2" />
    <child
      link="L_arm3" />
    <axis
      xyz="0 0 1" />
  </joint>
  <link
    name="L_arm4">
    <inertial>
      <origin
        xyz="-0.0101576588877177 -0.047494615258856 -9.2277926150186E-05"
        rpy="0 0 0" />
      <mass
        value="0.0493363034804284" />
      <inertia
        ixx="9.0399158715539E-06"
        ixy="1.78932578789159E-07"
        ixz="2.41603387315885E-11"
        iyy="1.18657637430999E-05"
        iyz="6.10913669040075E-11"
        izz="1.28686059122131E-05" />
    </inertial>
    <visual>
      <origin
        xyz="0 0 0"
        rpy="0 0 0" />
      <geometry>
        <mesh
          filename="package://Roly_update/meshes/L_arm4.STL" />
      </geometry>
      <material
        name="">
        <color
          rgba="0.752941176470588 0.752941176470588 0.752941176470588 1" />
      </material>
    </visual>
    <collision>
      <origin
        xyz="0 0 0"
        rpy="0 0 0" />
      <geometry>
        <mesh
          filename="package://Roly_update/meshes/L_arm4.STL" />
      </geometry>
    </collision>
  </link>
  <joint
    name="L_arm4"
    type="continuous">
    <origin
      xyz="0 0 -0.140300000000043"
      rpy="1.5707963267949 0 1.5707963267949" />
    <parent
      link="L_arm3" />
    <child
      link="L_arm4" />
    <axis
      xyz="0 0 1" />
  </joint>
  <link
    name="L_palm">
    <inertial>
      <origin
        xyz="-0.0113949831973588 -0.0235190546411198 0.122399647257947"
        rpy="0 0 0" />
      <mass
        value="0.113705108200624" />
      <inertia
        ixx="1.37809800988937E-05"
        ixy="-2.42636881988956E-07"
        ixz="-5.57783550016223E-07"
        iyy="4.21616633808545E-05"
        iyz="2.41304269026031E-07"
        izz="4.19257631414222E-05" />
    </inertial>
    <visual>
      <origin
        xyz="0 0 0"
        rpy="0 0 0" />
      <geometry>
        <mesh
          filename="package://Roly_update/meshes/L_palm.STL" />
      </geometry>
      <material
        name="">
        <color
          rgba="0.752941176470588 0.752941176470588 0.752941176470588 1" />
      </material>
    </visual>
    <collision>
      <origin
        xyz="0 0 0"
        rpy="0 0 0" />
      <geometry>
        <mesh
          filename="package://Roly_update/meshes/L_palm.STL" />
      </geometry>
    </collision>
  </link>
  <joint
    name="L_palm"
    type="continuous">
    <origin
      xyz="0 0 0"
      rpy="1.5707963267949 0 0" />
    <parent
      link="L_arm4" />
    <child
      link="L_palm" />
    <axis
      xyz="0 0 1" />
  </joint>
  <link
    name="L finger1-1">
    <inertial>
      <origin
        xyz="2.34998495634853E-05 -0.0115000000000026 -5.55111512312578E-17"
        rpy="0 0 0" />
      <mass
        value="0.0012778761403405" />
      <inertia
        ixx="1.1841445897518E-07"
        ixy="9.88187823376305E-22"
        ixz="-1.63253569256281E-23"
        iyy="2.02553394151493E-08"
        iyz="-3.6455066369243E-23"
        izz="1.35262128682755E-07" />
    </inertial>
    <visual>
      <origin
        xyz="0 0 0"
        rpy="0 0 0" />
      <geometry>
        <mesh
          filename="package://Roly_update/meshes/L finger1-1.STL" />
      </geometry>
      <material
        name="">
        <color
          rgba="0.752941176470588 0.752941176470588 0.752941176470588 1" />
      </material>
    </visual>
    <collision>
      <origin
        xyz="0 0 0"
        rpy="0 0 0" />
      <geometry>
        <mesh
          filename="package://Roly_update/meshes/L finger1-1.STL" />
      </geometry>
    </collision>
  </link>
  <joint
    name="L finger1-1"
    type="continuous">
    <origin
      xyz="-0.0349765001504338 0 0.139999999999761"
      rpy="-1.5707963267949 0 3.14159265358978" />
    <parent
      link="L_palm" />
    <child
      link="L finger1-1" />
    <axis
      xyz="0 0 1" />
  </joint>
  <link
    name="L finger1-2">
    <inertial>
      <origin
        xyz="-0.00379726889567304 -0.0297910428258427 1.94733784653067E-10"
        rpy="0 0 0" />
      <mass
        value="0.0070773971253231" />
      <inertia
        ixx="1.51715953464136E-06"
        ixy="2.43506955637539E-07"
        ixz="1.59954737239008E-13"
        iyy="3.21509193857945E-07"
        iyz="-4.41039105985216E-13"
        izz="1.7239148033551E-06" />
    </inertial>
    <visual>
      <origin
        xyz="0 0 0"
        rpy="0 0 0" />
      <geometry>
        <mesh
          filename="package://Roly_update/meshes/L finger1-2.STL" />
      </geometry>
      <material
        name="">
        <color
          rgba="0.752941176470588 0.752941176470588 0.752941176470588 1" />
      </material>
    </visual>
    <collision>
      <origin
        xyz="0 0 0"
        rpy="0 0 0" />
      <geometry>
        <mesh
          filename="package://Roly_update/meshes/L finger1-2.STL" />
      </geometry>
    </collision>
  </link>
  <joint
    name="L finger1-2"
    type="continuous">
    <origin
      xyz="0 -0.023 0"
      rpy="0 0 0" />
    <parent
      link="L finger1-1" />
    <child
      link="L finger1-2" />
    <axis
      xyz="0 0 1" />
  </joint>
  <link
    name="L finger2-1">
    <inertial>
      <origin
        xyz="-1.33226762955019E-15 -0.0114999999999917 3.33066907387547E-16"
        rpy="0 0 0" />
      <mass
        value="0.00127787614034051" />
      <inertia
        ixx="1.18414458975181E-07"
        ixy="-4.87201684179787E-22"
        ixz="1.65436122510606E-23"
        iyy="2.02553394151493E-08"
        iyz="4.06969927122691E-22"
        izz="1.35262128682756E-07" />
    </inertial>
    <visual>
      <origin
        xyz="0 0 0"
        rpy="0 0 0" />
      <geometry>
        <mesh
          filename="package://Roly_update/meshes/L finger2-1.STL" />
      </geometry>
      <material
        name="">
        <color
          rgba="0.752941176470588 0.752941176470588 0.752941176470588 1" />
      </material>
    </visual>
    <collision>
      <origin
        xyz="0 0 0"
        rpy="0 0 0" />
      <geometry>
        <mesh
          filename="package://Roly_update/meshes/L finger2-1.STL" />
      </geometry>
    </collision>
  </link>
  <joint
    name="L finger2-1"
    type="continuous">
    <origin
      xyz="0.030310889132458 -0.0175000000000002 0.139999999999761"
      rpy="-1.57079632679489 0 2.61799387799149" />
    <parent
      link="L_palm" />
    <child
      link="L finger2-1" />
    <axis
      xyz="0 0 1" />
  </joint>
  <link
    name="L finger2-2">
    <inertial>
      <origin
        xyz="0.00382076874523407 -0.0297910428258413 -1.94733090763677E-10"
        rpy="0 0 0" />
      <mass
        value="0.00707739712532307" />
      <inertia
        ixx="1.51715953464135E-06"
        ixy="-2.43506955637541E-07"
        ixz="1.59954739057225E-13"
        iyy="3.21509193857946E-07"
        iyz="4.41039110007776E-13"
        izz="1.7239148033551E-06" />
    </inertial>
    <visual>
      <origin
        xyz="0 0 0"
        rpy="0 0 0" />
      <geometry>
        <mesh
          filename="package://Roly_update/meshes/L finger2-2.STL" />
      </geometry>
      <material
        name="">
        <color
          rgba="0.752941176470588 0.752941176470588 0.752941176470588 1" />
      </material>
    </visual>
    <collision>
      <origin
        xyz="0 0 0"
        rpy="0 0 0" />
      <geometry>
        <mesh
          filename="package://Roly_update/meshes/L finger2-2.STL" />
      </geometry>
    </collision>
  </link>
  <joint
    name="L finger2-2"
    type="continuous">
    <origin
      xyz="0 -0.023 0"
      rpy="0 0 0" />
    <parent
      link="L finger2-1" />
    <child
      link="L finger2-2" />
    <axis
      xyz="0 0 1" />
  </joint>
  <link
    name="L finger3-1">
    <inertial>
      <origin
        xyz="-3.01147995429574E-15 -0.0114999999999993 -1.11022302462516E-16"
        rpy="0 0 0" />
      <mass
        value="0.00127787614034051" />
      <inertia
        ixx="1.18414458975181E-07"
        ixy="1.07457964364719E-21"
        ixz="3.30872245021211E-24"
        iyy="2.02553394151494E-08"
        iyz="-2.99439245301074E-22"
        izz="1.35262128682756E-07" />
    </inertial>
    <visual>
      <origin
        xyz="0 0 0"
        rpy="0 0 0" />
      <geometry>
        <mesh
          filename="package://Roly_update/meshes/L finger3-1.STL" />
      </geometry>
      <material
        name="">
        <color
          rgba="0.752941176470588 0.752941176470588 0.752941176470588 1" />
      </material>
    </visual>
    <collision>
      <origin
        xyz="0 0 0"
        rpy="0 0 0" />
      <geometry>
        <mesh
          filename="package://Roly_update/meshes/L finger3-1.STL" />
      </geometry>
    </collision>
  </link>
  <joint
    name="L finger3-1"
    type="continuous">
    <origin
      xyz="0.0303108891324579 0.0174999999999974 0.139999999999761"
      rpy="-1.5707963267949 0 -2.61799387799151" />
    <parent
      link="L_palm" />
    <child
      link="L finger3-1" />
    <axis
      xyz="0 0 1" />
  </joint>
  <link
    name="L finger3-2">
    <inertial>
      <origin
        xyz="0.0038207687452321 -0.0297910428258411 -1.9473370138634E-10"
        rpy="0 0 0" />
      <mass
        value="0.00707739712532307" />
      <inertia
        ixx="1.51715953464135E-06"
        ixy="-2.43506955637547E-07"
        ixz="1.59954739480742E-13"
        iyy="3.21509193857947E-07"
        iyz="4.4103910965334E-13"
        izz="1.7239148033551E-06" />
    </inertial>
    <visual>
      <origin
        xyz="0 0 0"
        rpy="0 0 0" />
      <geometry>
        <mesh
          filename="package://Roly_update/meshes/L finger3-2.STL" />
      </geometry>
      <material
        name="">
        <color
          rgba="0.752941176470588 0.752941176470588 0.752941176470588 1" />
      </material>
    </visual>
    <collision>
      <origin
        xyz="0 0 0"
        rpy="0 0 0" />
      <geometry>
        <mesh
          filename="package://Roly_update/meshes/L finger3-2.STL" />
      </geometry>
    </collision>
  </link>
  <joint
    name="L finger3-2"
    type="continuous">
    <origin
      xyz="0 -0.023 0"
      rpy="0 0 0" />
    <parent
      link="L finger3-1" />
    <child
      link="L finger3-2" />
    <axis
      xyz="0 0 1" />
  </joint>
  <link
    name="L gripper">
    <inertial>
      <origin
        xyz="9.85878045867139E-14 0.00156504693281307 1.22138410496575E-13"
        rpy="0 0 0" />
      <mass
        value="0.00609127056774437" />
      <inertia
        ixx="8.38284437689385E-07"
        ixy="1.86732222530706E-22"
        ixz="7.286215363113E-23"
        iyy="3.77175708246468E-07"
        iyz="-9.67951962022181E-23"
        izz="9.34655494343132E-07" />
    </inertial>
    <visual>
      <origin
        xyz="0 0 0"
        rpy="0 0 0" />
      <geometry>
        <mesh
          filename="package://Roly_update/meshes/L gripper.STL" />
      </geometry>
      <material
        name="">
        <color
          rgba="0.792156862745098 0.819607843137255 0.933333333333333 1" />
      </material>
    </visual>
    <collision>
      <origin
        xyz="0 0 0"
        rpy="0 0 0" />
      <geometry>
        <mesh
          filename="package://Roly_update/meshes/L gripper.STL" />
      </geometry>
    </collision>
  </link>
  <joint
    name="L gripper"
    type="prismatic">
    <origin
      xyz="0 0 0.163000000000415"
      rpy="0 0 -1.5707963267949" />
    <parent
      link="L_palm" />
    <child
      link="L gripper" />
    <axis
      xyz="0 0 1" />
    <limit
      lower="0"
      upper="0.03"
      effort="0"
      velocity="0" />
  </joint>
</robot>