<mujoco model="Roly">
    <compiler angle="radian" meshdir="meshes/" />
  <option timestep="0.005" iterations="1000"/>
    <size njmax="500" nconmax="100" />
    <asset>
        <mesh name="base_link" file="base_link.STL" />

        <mesh name="R_hip_yaw" file="R_hip_yaw.STL" />
        <mesh name="R_hip_roll" file="R_hip_roll.STL" />
        <mesh name="R_hip_pitch" file="R_hip_pitch.STL" />
        <mesh name="R_calf" file="R_calf.STL" />
        <mesh name="R_ankle_pitch" file="R_ankle_pitch.STL" />
        <mesh name="R_ankle_roll" file="R_ankle_roll.STL" />
        <mesh name="R_knee_rocker" file="R_knee_rocker.STL" />
        <mesh name="R_knee_linkage" file="R_knee_linkage.STL" />

        <mesh name="L_hip_yaw" file="L_hip_yaw.STL" />
        <mesh name="L_hip_roll" file="L_hip_roll.STL" />
        <mesh name="L_hip_pitch" file="L_hip_pitch.STL" />
        <mesh name="L_calf" file="L_calf.STL" />
        <mesh name="L_ankle_pitch" file="L_ankle_pitch.STL" />
        <mesh name="L_ankle_roll" file="L_ankle_roll.STL" />
        <mesh name="L_knee_rocker" file="L_knee_rocker.STL" />
        <mesh name="L_knee_linkage" file="L_knee_linkage.STL" />

        <mesh name="trunk_link" file="trunk_link.STL" />
        <mesh name="neck" file="neck.STL" />
        <mesh name="camera" file="camera.STL" />

        <mesh name="R_shoulder" file="R_shoulder.STL" />
        <mesh name="R_arm1" file="R_arm1.STL" />
        <mesh name="R_arm2" file="R_arm2.STL" />
        <mesh name="R_arm3" file="R_arm3.STL" />
        <mesh name="R_arm4" file="R_arm4.STL" />
        <mesh name="R_palm" file="R_palm.STL" />
        <mesh name="R_finger2" file="R_finger2.STL" />
        <mesh name="R_finger3" file="R_finger3.STL" />
        <mesh name="R_finger1" file="R_finger1.STL" />

        <mesh name="L_shoulder" file="L_shoulder.STL" />
        <mesh name="L_arm1" file="L_arm1.STL" />
        <mesh name="L_arm2" file="L_arm2.STL" />
        <mesh name="L_arm3" file="L_arm3.STL" />
        <mesh name="L_arm4" file="L_arm4.STL" />
        <mesh name="L_palm" file="L_palm.STL" />
        <mesh name="L_finger1" file="L_finger1.STL" />
        <mesh name="L_finger2" file="L_finger2.STL" />
        <mesh name="L_finger3" file="L_finger3.STL" />

        <texture type="skybox" builtin="gradient" rgb1="0.3 0.5 0.7" rgb2="0 0 0" width="512" height="512" />
        <texture name="texplane" type="2d" builtin="checker" rgb1=".2 .3 .4" rgb2=".1 0.15 0.2" width="512" height= "512" mark="cross" markrgb=".8 .8 .8" />
        <texture name="wood_texture" type="2d" file="wood_texture.png" mark="cross" markrgb="1 1 1" />
        <material name="matplane" reflectance="0.1" texture="texplane" texrepeat="2 2" />
        <material name="glowing_material" rgba="1 1 0 1" specular="1.0" emission="1.0" shininess="1.0"/>
        <material name="wood_table" texture="wood_texture"/>
    </asset>
    <worldbody>
        <light directional="false" diffuse="1.0 1.0 1.0" specular="1.0 1.0 1.0" pos="0.5 0 3" dir="0 0 -1" attenuation="1 0.1 0.01" castshadow="true" />
        <geom name="floor" pos="0 0 0" size="1.0 1.0 0.5" type="plane" material="matplane" margin="0.001" condim="3" friction="1 0.5 0.01" />   
        <site name="pos_target" type="sphere" size="0.01" pos="0.0 0.0 0.0" rgba="0 1 0 0.5"/>
        <site name="end_effector" type="sphere" size="0.015" pos="0.0 0.0 0.0" rgba="0 1 0 0.2"/>
        <site name="predicted_grasp_point" type="sphere" size="0.015" pos="0.0 0.0 0.0" rgba="0 1 0 0.5"/>

        <body name="base" pos="0 0 0.83" euler="0 0 0">
            <freejoint name="base" />
            <geom type="mesh" contype="0" conaffinity="0" group="1" rgba="0.752941 0.752941 0.752941 1" mesh="base_link" />
            <geom type="mesh" rgba="0.752941 0.752941 0.752941 1" mesh="base_link" />
            <site name="R_hip_yaw_X8-1" type="cylinder" size="0.05 0.025" pos="0 -0.13 -0.024" rgba="0 0 0 1"/>
            <site name="R_hip_yaw_X8-2" type="cylinder" size="0.036 0.028" pos="0 -0.13 -0.014" rgba="0 0 0 1"/>
            <site name="L_hip_yaw_X8-1" type="cylinder" size="0.05 0.025" pos="0 0.13 -0.024" rgba="0 0 0 1"/>
            <site name="L_hip_yaw_X8-2" type="cylinder" size="0.036 0.028" pos="0 0.13 -0.014" rgba="0 0 0 1"/>
            <site name="trunk_X8-1" type="cylinder" size="0.05 0.025" pos="0 0 -0.024" rgba="0 0 0 1"/>
            <site name="trunk_X8-2" type="cylinder" size="0.036 0.028" pos="0 0 -0.034" rgba="0 0 0 1"/>
            <body name="R_hip_yaw" pos="0 -0.13 -0.024">
                <inertial pos="-0.0376961 2.56626e-06 -0.0690573" quat="0.504536 0.504647 -0.495312 0.495421" mass="0.733344" diaginertia="0.00124909 0.00119898 0.000924833" />
                <!-- <joint name="R_hip_yaw" pos="0 0 0" axis="0 0 1" frictionloss="0.10" damping="0.4" stiffness="0.0" armature="0.01" /> -->
                <geom type="mesh" contype="0" conaffinity="0" group="1" rgba="0.752941 0.752941 0.752941 1" mesh="R_hip_yaw" />
                <site name="R_hip_roll_X12-1" type="cylinder" size="0.063 0.021" pos="-0.068 0 -0.1165" euler="0 1.5708 0" rgba="0 0 0 1"/>
                <site name="R_hip_roll_X12-2" type="cylinder" size="0.041 0.031" pos="-0.072 0 -0.1165" euler="0 1.5708 0" rgba="0 0 0 1"/>
                <!-- <geom type="mesh" rgba="0.752941 0.752941 0.752941 1" mesh="R_hip_yaw" /> -->
                <body name="R_hip_roll" pos="0 0 -0.1165" quat="0.5 0.5 0.5 0.5">
                    <inertial pos="0.00146094 4.44633e-09 -0.000423487" quat="0.5 0.5 0.5 0.5" mass="1.33292" diaginertia="0.00200428 0.00190741 0.000591897" />
                    <!-- <joint name="R_hip_roll" pos="0 0 0" axis="0 0 1" frictionloss="0.10" damping="0.4" stiffness="0.0" armature="0.01" /> -->
                    <geom type="mesh" contype="0" conaffinity="0" group="1" rgba="0.752941 0.752941 0.752941 1" mesh="R_hip_roll" />
                    <geom type="mesh" rgba="0.752941 0.752941 0.752941 1" mesh="R_hip_roll" />
                    <site name="R_hip_pitch_pro200-1" type="box" size="0.0658 0.0275 0.0275" pos="0 0 0" rgba="0 0 0 1"/>
                    <site name="R_hip_pitch_pro200-2" type="box" size="0.0658 0.0275 0.0275" pos="0 0 0" rgba="0 0 0 1"/>
                    <body name="R_hip_pitch" pos="0 0 0" quat="0.5 0.5 0.5 0.5">
                        <inertial pos="-0.127211 0.000292504 0.0010722" quat="0.0441692 0.705695 -0.0464379 0.705611" mass="2.89882" diaginertia="0.00547577 0.0048392 0.00467068" />
                        <!-- <joint name="R_hip_pitch" pos="0 0 0" axis="0 0 1" frictionloss="0.10" damping="0.4" stiffness="0.0" armature="0.01" /> -->
                        <geom type="mesh" contype="0" conaffinity="0" group="1" rgba="0.752941 0.752941 0.752941 1" mesh="R_hip_pitch" />
                        <geom type="mesh" rgba="0.752941 0.752941 0.752941 1" mesh="R_hip_pitch" />
                        <site name="R_knee_X10-1" type="cylinder" size="0.062 0.029" pos="-0.15 0 0" euler="0 0 0" rgba="0 0 0 1"/>
                        <site name="R_knee_X10-2" type="cylinder" size="0.036 0.038" pos="-0.15 0 0.005" euler="0 0 0" rgba="0 0 0 1"/>
                        <body name="R_calf" pos="-0.27 0 0">
                            <inertial pos="-0.115064 -0.000572913 -0.01046" quat="0.00197966 0.706949 -0.001944 0.707259" mass="1.80953" diaginertia="0.00514147 0.00439278 0.00120576" />
                            <!-- <joint name="R_calf" pos="0 0 0" axis="0 0 -1" frictionloss="0.10" damping="0.4" stiffness="0.0" armature="0.01" /> -->
                            <geom type="mesh" contype="0" conaffinity="0" group="1" rgba="0.752941 0.752941 0.752941 1" mesh="R_calf" />
                            <geom type="mesh" rgba="0.752941 0.752941 0.752941 1" mesh="R_calf" />
                            <site name="R_ankle_X8-1" type="cylinder" size="0.05 0.021" pos="-0.11 0 0" euler="0 0 0" rgba="0 0 0 1"/>
                            <site name="R_ankle_X8-2" type="cylinder" size="0.036 0.029" pos="-0.11 0 0.0054" euler="0 0 0" rgba="0 0 0 1"/>
                            <body name="R_ankle_pitch" pos="-0.26 0 0" quat="1 0 0 -1.36435e-05">
                                <inertial pos="-0.0459608 0.0196304 -4.06787e-05" quat="0.492551 0.507339 -0.492551 0.507339" mass="0.990578" diaginertia="0.00115084 0.00101085 0.000487115" />
                                <!-- <joint name="R_ankle_pitch" pos="0 0 0" axis="0 0 -1" frictionloss="0.10" damping="0.4" stiffness="0.0" armature="0.01" /> -->
                                <geom type="mesh" contype="0" conaffinity="0" group="1" rgba="0.752941 0.752941 0.752941 1" mesh="R_ankle_pitch" />
                                <geom type="mesh" rgba="0.752941 0.752941 0.752941 1" mesh="R_ankle_pitch" />
                                <site name="R_ankle_pro100-1" type="box" size="0.0275 0.0558 0.0275" pos="-0.05 0.02 0" rgba="0 0 0 1"/>
                                <site name="R_ankle_pro100-2" type="box" size="0.0275 0.0558 0.0275" pos="-0.05 0.02 0" rgba="0 0 0 1"/>
                                <body name="R_ankle_roll" pos="-0.05 0 0" quat="0.707107 -0.707107 -9.60377e-06 9.60377e-06">
                                    <inertial pos="-0.0685998 3.41171e-11 0.02" mass="1.80751" diaginertia="0.0035606 0.00313609 0.000582665" />
                                    <!-- <joint name="R_ankle_roll" pos="0 0 0" axis="0 0 -1" frictionloss="0.10" damping="0.4" stiffness="0.0" armature="0.01" /> -->
                                    <geom type="mesh" contype="0" conaffinity="0" group="1" rgba="0.752941 0.752941 0.752941 1" mesh="R_ankle_roll" />
                                    <geom type="mesh" rgba="0.752941 0.752941 0.752941 1" mesh="R_ankle_roll" />
                                </body>
                            </body>
                        </body>
                        <body name="R_knee_rocker" pos="-0.15 0 -0.0295">
                            <inertial pos="-0.00719497 -0.00261875 -0.0218741" quat="-0.128906 0.659843 0.116348 0.731063" mass="0.147234" diaginertia="9.00922e-05 7.15908e-05 2.64363e-05" />
                            <!-- <joint name="R_knee_rocker" pos="0 0 0" axis="0 0 1" frictionloss="0.10" damping="0.4" stiffness="0.0" armature="0.01" /> -->
                            <geom type="mesh" contype="0" conaffinity="0" group="1" rgba="0.752941 0.752941 0.752941 1" mesh="R_knee_rocker" />
                            <geom type="mesh" rgba="0.752941 0.752941 0.752941 1" mesh="R_knee_rocker" />
                            <body name="R_knee_linkage" pos="-0.0563816 -0.0205212 -0.0265" quat="0.984808 0 0 0.173648">
                                <inertial pos="-0.0590948 0.0215085 0" quat="0.122788 0.696364 -0.122788 0.696364" mass="0.110282" diaginertia="7.74132e-05 7.7261e-05 2.91375e-06" />
                                <!-- <joint name="R_knee_linkage" pos="0 0 0" axis="0 0 1"/> -->
                                <geom type="mesh" contype="0" conaffinity="0" group="1" rgba="0.752941 0.752941 0.752941 1" mesh="R_knee_linkage" />
                                <geom type="mesh" rgba="0.752941 0.752941 0.752941 1" mesh="R_knee_linkage" />
                            </body>
                        </body>
                    </body>
                </body>
            </body>
            <body name="L_hip_yaw" pos="0 0.13 -0.024">
                <inertial pos="-0.0376961 2.56626e-06 -0.0690573" quat="0.504536 0.504647 -0.495312 0.495421" mass="0.733344" diaginertia="0.00124909 0.00119898 0.000924833" />
                <!-- <joint name="L_hip_yaw" pos="0 0 0" axis="0 0 1" frictionloss="0.10" damping="0.4" stiffness="0.0" armature="0.01" /> -->
                <geom type="mesh" contype="0" conaffinity="0" group="1" rgba="0.752941 0.752941 0.752941 1" mesh="L_hip_yaw" />
                <!-- <geom type="mesh" rgba="0.752941 0.752941 0.752941 1" mesh="L_hip_yaw" /> -->
                <site name="L_hip_roll_X12-1" type="cylinder" size="0.063 0.021" pos="-0.068 0 -0.1165" euler="0 1.5708 0" rgba="0 0 0 1"/>
                <site name="L_hip_roll_X12-2" type="cylinder" size="0.041 0.031" pos="-0.072 0 -0.1165" euler="0 1.5708 0" rgba="0 0 0 1"/>
                <body name="L_hip_roll" pos="0 0 -0.1165" quat="0.5 0.5 0.5 0.5">
                    <inertial pos="-0.00146135 -4.44757e-09 -0.000413806" quat="0.5 0.5 0.5 0.5" mass="1.33254" diaginertia="0.00200428 0.0019074 0.000591888" />
                    <!-- <joint name="L_hip_roll" pos="0 0 0" axis="0 0 1" frictionloss="0.10" damping="0.4" stiffness="0.0" armature="0.01" /> -->
                    <geom type="mesh" contype="0" conaffinity="0" group="1" rgba="0.752941 0.752941 0.752941 1" mesh="L_hip_roll" />
                    <geom type="mesh" rgba="0.752941 0.752941 0.752941 1" mesh="L_hip_roll" />
                    <site name="L_hip_pitch_pro200-1" type="box" size="0.0658 0.0275 0.0275" pos="0 0 0" rgba="0 0 0 1"/>
                    <site name="L_hip_pitch_pro200-2" type="box" size="0.0658 0.0275 0.0275" pos="0 0 0" rgba="0 0 0 1"/>
                    <body name="L_hip_pitch" pos="0 0 0" quat="0.5 0.5 0.5 0.5">
                        <inertial pos="-0.127211 0.000292504 -0.00112657" quat="0.0464378 0.70561 -0.0441693 0.705696" mass="2.89882" diaginertia="0.00547577 0.0048392 0.00467068" />
                        <!-- <joint name="L_hip_pitch" pos="0 0 0" axis="0 0 1" frictionloss="0.10" damping="0.4" stiffness="0.0" armature="0.01" /> -->
                        <geom type="mesh" contype="0" conaffinity="0" group="1" rgba="0.752941 0.752941 0.752941 1" mesh="L_hip_pitch" />
                        <geom type="mesh" rgba="0.752941 0.752941 0.752941 1" mesh="L_hip_pitch" />
                        <site name="L_knee_X10-1" type="cylinder" size="0.062 0.029" pos="-0.15 0 0" euler="0 0 0" rgba="0 0 0 1"/>
                        <site name="L_knee_X10-2" type="cylinder" size="0.036 0.038" pos="-0.15 0 -0.005" euler="0 0 0" rgba="0 0 0 1"/>
                        <body name="L_calf" pos="-0.27 0 0">
                            <inertial pos="-0.115047 -0.000697383 0.0108054" quat="0.00193336 0.707259 -0.00196919 0.706949" mass="1.81934" diaginertia="0.00514067 0.00439559 0.0012084" />
                            <!-- <joint name="L_calf" pos="0 0 0" axis="0 0 -1" frictionloss="0.10" damping="0.4" stiffness="0.0" armature="0.01" /> -->
                            <geom type="mesh" contype="0" conaffinity="0" group="1" rgba="0.752941 0.752941 0.752941 1" mesh="L_calf" />
                            <geom type="mesh" rgba="0.752941 0.752941 0.752941 1" mesh="L_calf" />
                            <site name="L_ankle_X8-1" type="cylinder" size="0.05 0.021" pos="-0.11 0 0" euler="0 0 0" rgba="0 0 0 1"/>
                            <site name="L_ankle_X8-2" type="cylinder" size="0.036 0.029" pos="-0.11 0 -0.0054" euler="0 0 0" rgba="0 0 0 1"/>
                            <body name="L_ankle_pitch" pos="-0.26 0 0">
                                <inertial pos="-0.0459602 0.0196317 5.49196e-05" quat="0.492558 0.507333 -0.492558 0.507333" mass="0.990578" diaginertia="0.00115084 0.00101085 0.000487114" />
                                <!-- <joint name="L_ankle_pitch" pos="0 0 0" axis="0 0 -1" frictionloss="0.10" damping="0.4" stiffness="0.0" armature="0.01" /> -->
                                <geom type="mesh" contype="0" conaffinity="0" group="1" rgba="0.752941 0.752941 0.752941 1" mesh="L_ankle_pitch" />
                                <geom type="mesh" rgba="0.752941 0.752941 0.752941 1" mesh="L_ankle_pitch" />
                                <site name="L_ankle_pro100-1" type="box" size="0.0275 0.0558 0.0275" pos="-0.05 0.02 0" rgba="0 0 0 1"/>
                                <site name="L_ankle_pro100-2" type="box" size="0.0275 0.0558 0.0275" pos="-0.05 0.02 0" rgba="0 0 0 1"/>
                                <body name="L_ankle_roll" pos="-0.05 0 0" quat="0.707107 -0.707107 0 0">
                                    <inertial pos="-0.0685998 2.17384e-11 0.02" mass="1.80751" diaginertia="0.0035606 0.00313609 0.000582665" />
                                    <!-- <joint name="L_ankle_roll" pos="0 0 0" axis="0 0 -1" frictionloss="0.10" damping="0.4" stiffness="0.0" armature="0.01" /> -->
                                    <geom type="mesh" contype="0" conaffinity="0" group="1" rgba="0.752941 0.752941 0.752941 1" mesh="L_ankle_roll" />
                                    <geom type="mesh" rgba="0.752941 0.752941 0.752941 1" mesh="L_ankle_roll" />
                                </body>
                            </body>
                        </body>
                        <body name="L_knee_rocker" pos="-0.15 0 0.0345">
                            <inertial pos="-0.00719497 -0.00261875 0.0168741" quat="-0.116348 0.731063 0.128906 0.659843" mass="0.147234" diaginertia="9.00922e-05 7.15908e-05 2.64363e-05" />
                            <!-- <joint name="L_knee_rocker" pos="0 0 0" axis="0 0 1" frictionloss="0.10" damping="0.4" stiffness="0.0" armature="0.01" /> -->
                            <geom type="mesh" contype="0" conaffinity="0" group="1" rgba="0.752941 0.752941 0.752941 1" mesh="L_knee_rocker" />
                            <geom type="mesh" rgba="0.752941 0.752941 0.752941 1" mesh="L_knee_rocker" />
                            <body name="L_knee_linkage" pos="-0.0563816 -0.0205212 0.0215" quat="0.984808 0 0 0.173648">
                                <inertial pos="-0.0590948 0.0215085 0" quat="0.122788 0.696364 -0.122788 0.696364" mass="0.110282" diaginertia="7.74132e-05 7.7261e-05 2.91375e-06" />
                                <!-- <joint name="L_knee_linkage" pos="0 0 0" axis="0 0 1"/> -->
                                <geom type="mesh" contype="0" conaffinity="0" group="1" rgba="0.752941 0.752941 0.752941 1" mesh="L_knee_linkage" />
                                <!-- <geom type="mesh" rgba="0.752941 0.752941 0.752941 1" mesh="L_knee_linkage" /> -->
                            </body>
                        </body>
                    </body>
                </body>
            </body>
            <body name="trunk_link" pos="0 0 0">
                <inertial pos="-0.000201063 -0.00171826 0.342962" quat="0.999995 0.00204635 0.000603463 0.00240004" mass="7.20265" diaginertia="0.082079 0.057503 0.025698" />
                <!-- <joint name="trunk" pos="0 0 0" axis="0 0 1" frictionloss="0.10" damping="0.4" stiffness="0.0" armature="0.01" /> -->
                <geom type="mesh" contype="0" conaffinity="0" group="1" rgba="0.752941 0.752941 0.752941 1" mesh="trunk_link" />
                <geom type="mesh" rgba="0.752941 0.752941 0.752941 1" mesh="trunk_link" />
		        <body name="hitbox1" > 
                    <geom name="hitbox1-3" type="box" contype="1" conaffinity="1" group="1" mass="0.00000001" pos="0.00 0.0 0.30" size="0.08 0.18 0.20" rgba="0.99 0.752941 0.752941 0.00002"/>
                </body>
                <body name="neck" pos="0.0236 0 0.6049" quat="0.707107 0.707107 0 0">
                    <inertial pos="-0.0115402 -0.00305819 2.74218e-05" quat="0.486136 0.513558 0.513346 0.486216" mass="0.0915993" diaginertia="2.61388e-05 2.1214e-05 1.5184e-05" />
                    <joint name="neck" pos="0 0 0" axis="0 1 0" frictionloss="0.10" damping="0.4" stiffness="0.0" armature="0.01"/>
                    <geom type="mesh" contype="0" conaffinity="0" group="1" rgba="0.752941 0.752941 0.752941 1" mesh="neck" />
                    <geom type="mesh" rgba="0.752941 0.752941 0.752941 1" mesh="neck" />
                    <body name="camera" pos="0 0 0">
                        <inertial pos="0.00115688 0.0531957 -0.00111035" quat="0.99992 0.000785471 -0.00299477 0.0122238" mass="0.13263" diaginertia="9.89677e-05 9.22981e-05 2.20764e-05" />
                        <joint name="camera" pos="0 0 0" axis="0 0 1" frictionloss="0.10" damping="0.4" stiffness="0.0" armature="0.01" />
                        <geom type="mesh" contype="0" conaffinity="0" group="1" rgba="0.752941 0.752941 0.752941 1" mesh="camera" />
                        <geom type="mesh" rgba="0.1 0.1 0.1 1" mesh="camera" />
                        <camera name="head_camera" mode="fixed" pos="0.01 0.06 0" zaxis="-1 0 0" fovy="85"/>
                        <!-- <site name="neck_marker" type="sphere" size="0.015" pos="0.0 0.0 0.0" rgba="0 1 1 0.5"/> -->
                    </body>
                </body>
                <body name="R_shoulder" pos="0 0 0.495" quat="0.707107 0.707107 0 0">
                    <inertial pos="-4.78829e-05 0.015654 0.248212" quat="0.49075 0.509211 -0.490712 0.50899" mass="0.159234" diaginertia="7.36582e-05 5.90884e-05 4.06637e-05" />
                    <joint name="R_shoulder" pos="0 0 0" axis="0 0 1" frictionloss="0.10" damping="0.4" stiffness="0.0" armature="0.01" />
                    <geom name="R_shoulder" type="mesh" contype="0" conaffinity="0" group="1" rgba="0.752941 0.752941 0.752941 1" mesh="R_shoulder" />
                    <!-- <geom type="mesh" rgba="0.752941 0.752941 0.752941 1" mesh="R_shoulder" /> -->
                    <site name="origin_marker" type="sphere" size="0.025" pos="0.0 0.0 0.0" rgba="1 0 1 0.5"/>
                    <body name="R_arm1" pos="0 0 0.2488" quat="0.5 0.5 0.5 0.5">
                        <inertial pos="-0.133479 1.93811e-05 -7.69201e-06" quat="0.486261 0.513545 0.513273 0.486182" mass="0.189028" diaginertia="9.02608e-05 6.74332e-05 5.49718e-05" />
                        <joint name="R_arm1" pos="0 0 0" axis="0 0 1" frictionloss="0.10" damping="0.4" stiffness="0.0" armature="0.01" />
                        <geom name="R_arm1" type="mesh" contype="0" conaffinity="0" group="1" rgba="0.752941 0.752941 0.752941 1" mesh="R_arm1" />
                        <!-- <geom type="mesh" rgba="0.752941 0.752941 0.752941 1" mesh="R_arm1" /> -->
			            <site name="R_shoulder_marker" type="sphere" size="0.025" pos="0 0 0"     rgba="1 0.0 1 0.5"/>
                        <site name="R_arm_marker1" type="sphere" size="0.015" pos="-0.10 0.0 0.0" rgba="0 0.9 1 0.00005"/>
                        <site name="R_arm_marker2" type="sphere" size="0.015" pos="-0.14 0.0 0.0" rgba="0 0.9 1 0.00005"/>
                        <site name="R_arm_marker3" type="sphere" size="0.015" pos="-0.18 0.0 0.0" rgba="0 0.9 1 0.00005"/>
                        <site name="R_arm_marker4" type="sphere" size="0.015" pos="-0.22 0.0 0.0" rgba="0 0.9 1 0.00005"/>
                        <site name="R_arm_marker5" type="sphere" size="0.015" pos="-0.26 0.0 0.0" rgba="0 0.9 1 0.00005"/>
                        <site name="R_arm_marker6" type="sphere" size="0.015" pos="-0.30 0.0 0.0" rgba="0 0.9 1 0.00005"/>
                        <site name="R_arm_marker7" type="sphere" size="0.015" pos="-0.34 0.0 0.0" rgba="0 0.9 1 0.00005"/>
                        <body name="R_arm2" pos="-0.1705 0 0">
                            <inertial pos="-0.0928721 1.67411e-07 -0.00651967" quat="0.707071 -0.00727436 -0.00727567 0.707067" mass="0.0759196" diaginertia="2.92269e-05 2.47959e-05 1.60978e-05" />
                            <joint name="R_arm2" pos="0 0 0" axis="0 0 1" frictionloss="0.10" damping="0.4" stiffness="0.0" armature="0.01" limited="true" range="-0.00001 0.00001"  />
                            <geom name="R_arm2" type="mesh" contype="0" conaffinity="0" group="1" rgba="0.752941 0.752941 0.752941 1" mesh="R_arm2" />
                            <!-- <geom type="mesh" rgba="0.752941 0.752941 0.752941 1" mesh="R_arm2" /> -->
                            <body name="R_arm3" pos="0 0 0" quat="0.5 0.5 0.5 0.5">
                                <inertial pos="-3.22978e-05 -1.49737e-05 -0.187351" quat="0.706666 -0.0244966 -0.0241464 0.706711" mass="0.0455132" diaginertia="1.24358e-05 1.04566e-05 7.80803e-06" />
                                <joint name="R_arm3" pos="0 0 0" axis="0 0 1" frictionloss="0.10" damping="0.4" stiffness="0.0" armature="0.01" />
                                <geom name="R_arm3" type="mesh" contype="0" conaffinity="0" group="1" rgba="0.752941 0.752941 0.752941 1" mesh="R_arm3" />
                                <!-- <geom type="mesh" rgba="0.752941 0.752941 0.752941 1" mesh="R_arm3" /> -->
                                <body name="R_arm4" pos="0 0 -0.2003" quat="0.5 0.5 0.5 0.5">
                                    <inertial pos="-0.0101577 -0.0474946 9.27932e-05" quat="0.02226 0.706758 -0.0222695 0.706754" mass="0.0493363" diaginertia="1.28686e-05 1.1877e-05 9.02863e-06" />
                                    <joint name="R_arm4" pos="0 0 0" axis="0 0 1" frictionloss="0.10" damping="0.4" stiffness="0.0" armature="0.01" />
                                    <geom name="R_arm4" type="mesh" contype="0" conaffinity="0" group="1" rgba="0.752941 0.752941 0.752941 1" mesh="R_arm4" />
                                    <!-- <geom type="mesh" rgba="0.752941 0.752941 0.752941 1" mesh="R_arm4" /> -->
                                    <site name="R_elbow_marker" type="sphere" size="0.020" pos="0.0 0.0 0.0"   rgba="1 0 1.0 0.5"/>
                                    <site name="R_arm_marker8"  type="sphere" size="0.010" pos="0.0 -0.04 0.0" rgba="0 1 0.5 0.00001"/>
                                    <site name="R_arm_marker9"  type="sphere" size="0.010" pos="0.0 -0.08 0.0" rgba="0 1 0.5 0.00001"/>
                                    <site name="R_arm_marker10" type="sphere" size="0.010" pos="0.0 -0.12 0.0" rgba="0 1 0.5 0.00001"/>
                                    <site name="R_arm_marker11" type="sphere" size="0.010" pos="0.0 -0.16 0.0" rgba="0 1 0.5 0.00001"/>
                                    <site name="R_arm_marker12" type="sphere" size="0.010" pos="0.0 -0.20 0.0" rgba="0 1 0.5 0.00001"/>
                                    <body name="R_palm" pos="0 0 0" quat="0.707107 0.707107 0 0">
                                        <inertial pos="-0.00739621 -4.38124e-05 0.113166" quat="0.00210295 0.697675 -0.00221488 0.716408" mass="0.114731" diaginertia="3.2167e-05 3.0104e-05 1.92109e-05" />
                                        <joint name="R_palm" pos="0 0 0" axis="0 0 1" frictionloss="0.10" damping="0.4" stiffness="0.0" armature="0.01" />
                                        <geom name="R_palm" type="mesh" contype="0" conaffinity="0" group="1" rgba="0.752941 0.752941 0.752941 1" mesh="R_palm" />
                                        <!-- <geom type="mesh" rgba="0.752941 0.752941 0.752941 1" mesh="R_palm" /> -->
                                        <body name="R_finger2" pos="0.028343 -0.019846 0.12875" quat="0.62721 -0.326505 0.627213 0.326506">
                                            <inertial pos="-0.0445566 0.0133763 -2.00831e-10" quat="0.580505 0.580505 0.403749 0.403749" mass="0.0078541" diaginertia="4.08422e-06 4.0541e-06 1.6249e-07" />
                                            <!-- <joint name="R_finger2" pos="0 0 0" axis="0 0 -1" frictionloss="0.10" damping="0.4" stiffness="0.0" armature="0.01" /> -->
                                            <geom type="mesh" contype="0" conaffinity="0" group="1" rgba="0.792157 0.819608 0.933333 1" mesh="R_finger2" />
                                            <!-- <geom type="mesh" rgba="0.792157 0.819608 0.933333 1" mesh="R_finger2" /> -->
                                        </body>
                                        <body name="R_finger3" pos="0.0283427 0.0198457 0.12875" quat="0.326506 -0.627211 0.326506 0.627211">
                                            <inertial pos="-0.0445566 0.0133763 8.22281e-10" quat="0.580505 0.580505 0.403749 0.403749" mass="0.0078541" diaginertia="4.08422e-06 4.0541e-06 1.6249e-07" />
                                            <!-- <joint name="R_finger3" pos="0 0 0" axis="0 0 -1" frictionloss="0.10" damping="0.4" stiffness="0.0" armature="0.01" /> -->
                                            <geom type="mesh" contype="0" conaffinity="0" group="1" rgba="0.792157 0.819608 0.933333 1" mesh="R_finger3" />
                                            <!-- <geom type="mesh" rgba="0.792157 0.819608 0.933333 1" mesh="R_finger3" /> -->
                                        </body>
                                        <body name="R_finger1" pos="-0.0346 0 0.12875" quat="0.499998 0.5 0.5 -0.500002">
                                            <inertial pos="-0.044557 0.013376 1.1889e-09" quat="0.580506 0.580506 0.403748 0.403748" mass="0.0078541" diaginertia="4.0842e-06 4.0541e-06 1.62477e-07" />
                                            <!-- <joint name="R_finger1" pos="0 0 0" axis="0 0 -1" frictionloss="0.10" damping="0.4" stiffness="0.0" armature="0.01" /> -->
                                            <geom type="mesh" contype="0" conaffinity="0" group="1" rgba="0.79216 0.81961 0.93333 1" mesh="R_finger1" />
                                            <!-- <geom type="mesh" rgba="0.79216 0.81961 0.93333 1" mesh="R_finger1" /> -->
                                        </body>
                                        <site name="R_hand_marker" type="sphere" size="0.01" pos="0 0 0.17" rgba="1 1 0 0.0005"/>
                                        <site name="temp_target" type="sphere" size="0.01" pos="0 0 0.25" rgba="1 1 0 0.0005"/>
                                    </body>
                                </body>
                            </body>
                        </body>
                    </body>
                </body>
                <body name="L_shoulder" pos="0 0 0.495" quat="0.707107 0.707107 0 0">
                    <inertial pos="-4.78828e-05 0.015654 -0.248205" quat="0.490899 0.50908 -0.490563 0.509121" mass="0.159234" diaginertia="7.36582e-05 5.90884e-05 4.06637e-05" />
                    <!-- <joint name="L_shoulder" pos="0 0 0" axis="0 0 1" frictionloss="0.10" damping="0.4" stiffness="0.0" armature="0.01" /> -->
                    <geom type="mesh" contype="0" conaffinity="0" group="1" rgba="0.752941 0.752941 0.752941 1" mesh="L_shoulder" />
                    <geom type="mesh" rgba="0.752941 0.752941 0.752941 1" mesh="L_shoulder" />
                    <body name="L_arm1" pos="0 0 -0.2488" quat="0.5 0.5 0.5 0.5">
                        <inertial pos="-0.133479 -1.33027e-05 -7.69191e-06" quat="0.486138 0.513406 0.513411 0.486305" mass="0.189028" diaginertia="9.02608e-05 6.74332e-05 5.49718e-05" />
                        <!-- <joint name="L_arm1" pos="0 0 0" axis="0 0 1" frictionloss="0.10" damping="0.4" stiffness="0.0" armature="0.01" /> -->
                        <geom type="mesh" contype="0" conaffinity="0" group="1" rgba="0.752941 0.752941 0.752941 1" mesh="L_arm1" />
                        <geom type="mesh" rgba="0.752941 0.752941 0.752941 1" mesh="L_arm1" />
                        <body name="L_arm2" pos="-0.1705 0 0">
                            <inertial pos="-0.0928721 1.67409e-07 -0.00651967" quat="0.707071 -0.00727436 -0.00727567 0.707067" mass="0.0759196" diaginertia="2.92269e-05 2.47959e-05 1.60978e-05" />
                            <!-- <joint name="L_arm2" pos="0 0 0" axis="0 0 1" frictionloss="0.10" damping="0.4" stiffness="0.0" armature="0.01" /> -->
                            <geom type="mesh" contype="0" conaffinity="0" group="1" rgba="0.752941 0.752941 0.752941 1" mesh="L_arm2" />
                            <geom type="mesh" rgba="0.752941 0.752941 0.752941 1" mesh="L_arm2" />
                            <body name="L_arm3" pos="0 0 0" quat="0.5 0.5 0.5 0.5">
                                <inertial pos="3.22976e-05 -1.49724e-05 -0.187351" quat="0.70671 0.0241465 0.0244965 0.706667" mass="0.0455132" diaginertia="1.24358e-05 1.04566e-05 7.80803e-06" />
                                <!-- <joint name="L_arm3" pos="0 0 0" axis="0 0 1" frictionloss="0.10" damping="0.4" stiffness="0.0" armature="0.01" /> -->
                                <geom type="mesh" contype="0" conaffinity="0" group="1" rgba="0.752941 0.752941 0.752941 1" mesh="L_arm3" />
                                <geom type="mesh" rgba="0.752941 0.752941 0.752941 1" mesh="L_arm3" />
                                <body name="L_arm4" pos="0 0 -0.2003" quat="0.5 0.5 0.5 0.5">
                                    <inertial pos="-0.00934619 -0.0476609 -9.22779e-05" quat="0.0162594 0.706923 -0.0162149 0.706918" mass="0.0493363" diaginertia="1.28686e-05 1.1877e-05 9.02863e-06" />
                                    <!-- <joint name="L_arm4" pos="0 0 0" axis="0 0 1" frictionloss="0.10" damping="0.4" stiffness="0.0" armature="0.01" /> -->
                                    <geom type="mesh" contype="0" conaffinity="0" group="1" rgba="0.752941 0.752941 0.752941 1" mesh="L_arm4" />
                                    <geom type="mesh" rgba="0.752941 0.752941 0.752941 1" mesh="L_arm4" />
                                    <body name="L_palm" pos="0 0 0" quat="0.707081 0.707081 0.00602983 0.00602983">
                                        <inertial pos="-0.00739621 -4.38134e-05 0.113166" quat="0.00210266 0.697675 -0.00221505 0.716408" mass="0.114731" diaginertia="3.2167e-05 3.0104e-05 1.92109e-05" />
                                        <!-- <joint name="L_palm" pos="0 0 0" axis="0 0 1" frictionloss="0.10" damping="0.4" stiffness="0.0" armature="0.01" /> -->
                                        <geom type="mesh" contype="0" conaffinity="0" group="1" rgba="0.752941 0.752941 0.752941 1" mesh="L_palm" />
                                        <geom type="mesh" rgba="0.752941 0.752941 0.752941 1" mesh="L_palm" />
                                        <body name="L_finger1" pos="-0.0346 0 0.12875" quat="0.499998 0.5 0.5 -0.500002">
                                            <inertial pos="-0.0445566 0.0133763 5.82671e-10" quat="0.580505 0.580505 0.40375 0.40375" mass="0.00785409" diaginertia="4.08422e-06 4.0541e-06 1.6249e-07" />
                                            <!-- <joint name="L_finger1" pos="0 0 0" axis="0 0 -1" frictionloss="0.10" damping="0.4" stiffness="0.0" armature="0.01" /> -->
                                            <geom type="mesh" contype="0" conaffinity="0" group="1" rgba="0.792157 0.819608 0.933333 1" mesh="L_finger1" />
                                            <geom type="mesh" rgba="0.792157 0.819608 0.933333 1" mesh="L_finger1" />
                                        </body>
                                        <body name="L_finger2" pos="0.028343 0.019846 0.12875" quat="0.326493 -0.627216 0.326494 0.627219">
                                            <inertial pos="-0.0445566 0.0133763 1.16507e-09" quat="0.580505 0.580505 0.403749 0.403749" mass="0.0078541" diaginertia="4.08422e-06 4.0541e-06 1.6249e-07" />
                                            <!-- <joint name="L_finger2" pos="0 0 0" axis="0 0 -1" frictionloss="0.10" damping="0.4" stiffness="0.0" armature="0.01" /> -->
                                            <geom type="mesh" contype="0" conaffinity="0" group="1" rgba="0.792157 0.819608 0.933333 1" mesh="L_finger2" />
                                            <geom type="mesh" rgba="0.792157 0.819608 0.933333 1" mesh="L_finger2" />
                                        </body>
                                        <body name="L_finger3" pos="0.028343 -0.019846 0.12875" quat="0.62721 -0.326505 0.627213 0.326506">
                                            <inertial pos="-0.0445566 0.0133763 2.89035e-10" quat="0.580505 0.580505 0.403749 0.403749" mass="0.0078541" diaginertia="4.08422e-06 4.0541e-06 1.6249e-07" />
                                            <!-- <joint name="L_finger3" pos="0 0 0" axis="0 0 -1" frictionloss="0.10" damping="0.4" stiffness="0.0" armature="0.01" /> -->
                                            <geom type="mesh" contype="0" conaffinity="0" group="1" rgba="0.792157 0.819608 0.933333 1" mesh="L_finger3" />
                                            <geom type="mesh" rgba="0.792157 0.819608 0.933333 1" mesh="L_finger3" />
                                        </body>
                                        <site name="L_hand_marker" type="sphere" size="0.01" pos="0 0 0.17" rgba="0 1 0 0.1"/>
                                    </body>
                                </body>
                            </body>
                        </body>
                    </body>
                </body>
            </body>
        </body>

        <body name="red_ball" > 
            <joint type="free" damping="0.1"/>
            <!-- <geom name="red_ball" type="sphere" material="glowing_material" contype="1" conaffinity="1" group="1" mass="0.0000001" pos="0.0 0.0 0.0" size="0.02" rgba="1 0 0 1.0"/> -->
            <geom name="red_ball" type="sphere" material="glowing_material" contype="0" conaffinity="0" group="1" mass="0.0000001" pos="0.0 0.0 0.0" size="0.015" rgba="1 0 0 1.0"/>  
            <!-- <light name="R_hand_light" directional="false" pos="0 0 0" dir="0 0 -1" diffuse="1 1 1" specular="1 1 1" attenuation="1 0.1 0.0"/> -->
        </body>
        <!-- <body name="obstacle_hand" > 
            <joint type="free" damping="0.1"/>
            <geom name="obstacle_hand" type="box" contype="2" conaffinity="4" group="1" mass="1.0" pos="10.0 0.0 0.2" size="0.02 0.02 0.125" rgba="0 0 0 0.5" condim="6" priority="1" class="plastic_collision"/> 
        </body>
        <body name="obstacle_table" > 
            <joint type="free" damping="0.1"/>
            <geom name="obstacle_table" type="box" contype="2" conaffinity="4" group="1" mass="1.0" pos="10.5 0.0 0.0" size="0.3 0.5 0.01" material="wood_table" condim="6" priority="1" class="plastic_collision"/> 
        </body>
        <body name="obstacle_human" > 
            <joint type="free" damping="0.1"/>
            <geom name="obstacle_human" type="box" contype="2" conaffinity="4" group="1" mass="1.0" pos="10.5 0.0 0.0" size="0.10 0.20 0.75" rgba="0 0 0 0.5" condim="6" priority="1" class="plastic_collision"/> 
        </body> -->

        <body name="fix_box" > 
            <geom type="box" mass="20000" pos="0.020  0.43 0" size="0.145 0.20 0.02"  rgba="0.2 0.2 0.2 0"/> 
            <geom type="box" mass="20000" pos="0.020 -0.43 0" size="0.145 0.20 0.02"  rgba="0.2 0.2 0.2 0"/> 
            <geom type="box" mass="20000" pos="0.365  0.00 0" size="0.200 0.63 0.02"  rgba="0.2 0.2 0.2 0"/> 
            <geom type="box" mass="20000" pos="-0.325  0.00 0" size="0.200 0.63 0.02"  rgba="0.2 0.2 0.2 0"/> 
        </body>
    </worldbody>
    <equality>
        <connect name="linkageR_knee" active="true" body1="R_calf" body2="R_knee_linkage" anchor="-0.05638 -0.02052 -0.056" />
        <connect name="linkageL_knee" active="true" body1="L_calf" body2="L_knee_linkage" anchor="-0.05638 -0.02052  0.056" />
    </equality>
    <actuator>
        <!-- <motor joint="R_hip_yaw"     name="R_hip_yaw"       gear="1" />
        <motor joint="R_hip_roll"    name="R_hip_roll"      gear="1" />
        <motor joint="R_hip_pitch"   name="R_hip_pitch"     gear="1" />
        <motor joint="R_calf"        name="R_knee"          gear="1" />
        <motor joint="R_ankle_pitch" name="R_ankle_pitch"   gear="1" />
        <motor joint="R_ankle_roll"  name="R_ankle_roll"    gear="1" />

        <motor joint="L_hip_yaw"     name="L_hip_yaw"       gear="1"/>
        <motor joint="L_hip_roll"    name="L_hip_roll"      gear="1" />
        <motor joint="L_hip_pitch"   name="L_hip_pitch"     gear="1" />
        <motor joint="L_calf"        name="L_knee"          gear="1" />
        <motor joint="L_ankle_pitch" name="L_ankle_pitch"   gear="1" />
        <motor joint="L_ankle_roll"  name="L_ankle_roll"    gear="1"/>

        <motor joint="trunk"  name="trunk"  gear="1" /> -->
        <motor joint="neck"   name="neck"   gear="1" />
        <motor joint="camera" name="camera" gear="1" />

        <motor joint="R_shoulder"   name="R_shoulder"   ctrlrange="-10 10" gear="1" />
        <motor joint="R_arm1"       name="R_arm1"       ctrlrange="-10 10" gear="1" />
        <motor joint="R_arm2"       name="R_arm2"       ctrlrange="-10 10" gear="1" />
        <motor joint="R_arm3"       name="R_arm3"       ctrlrange="-5 5"   gear="1" />
        <motor joint="R_arm4"       name="R_arm4"       ctrlrange="-5 5"   gear="1" />
        <motor joint="R_palm"       name="R_palm"       ctrlrange="-5 5"   gear="1" />
        <!-- <motor joint="R_finger1"    name="R_finger1"    ctrlrange="-5 5"   gear="1" />
        <motor joint="R_finger2"    name="R_finger2"    ctrlrange="-5 5"   gear="1" />
        <motor joint="R_finger3"    name="R_finger3"    ctrlrange="-5 5"   gear="1" /> -->

        <!-- <motor joint="L_shoulder"   name="L_shoulder"   ctrlrange="-10 10" gear="1" />
        <motor joint="L_arm1"       name="L_arm1"       ctrlrange="-10 10" gear="1" />
        <motor joint="L_arm2"       name="L_arm2"       ctrlrange="-10 10" gear="1" />
        <motor joint="L_arm3"       name="L_arm3"       ctrlrange="-5 5"   gear="1" />
        <motor joint="L_arm4"       name="L_arm4"       ctrlrange="-5 5"   gear="1" />
        <motor joint="L_palm"       name="L_palm"       ctrlrange="-5 5"   gear="1" />
        <motor joint="L_finger1"    name="L_finger1"    ctrlrange="-5 5"   gear="1" />
        <motor joint="L_finger2"    name="L_finger2"    ctrlrange="-5 5"   gear="1" />
        <motor joint="L_finger3"    name="L_finger3"    ctrlrange="-5 5"   gear="1" /> -->
    </actuator>
    <default>
        <default class="plastic_collision">
            <geom solimp="0.2 0.99 0.0001" solref="0.05 1" friction="1 0.2 0.001"/>
        </default>
    </default>
</mujoco>
